2024-01-21 22:11:09 [DEBUG] common_utils - <module> line 38: Config(env='local', common_config={'logger_path': {'LOGGER_DEF_FILE': 'tests/def/mfaUtilsLoggingHelper/logging_TimedRotate.json', 'LOGGER_MSG_FILE': 'tests/def/mfaUtilsLoggingHelper/config_MessageList.toml'}, 'input_file_path': {'UPDATE_EXCEL_PATH': 'tests/share/receive'}, 'output_file_path': {'SEND_REFFERENCE_MASTER_PATH': 'tests/share/receive'}}, package_config={'test': {'local_test': 'test'}}, log_message=<bound method LoggerPackage.log_message of <src.lib.common_utils.ibr_logger_package.LoggerPackage object at 0x7f7643ab8b10>>):
2024-01-21 22:11:09 [DEBUG] common_utils - test_processmanager_exit_UT_C0_unlink_error line 217: 
        - テスト関数: test_processmanager_UT_C0_normal, test_processmanager_enter_UT_C0_exception, test_processmanager_enter_UT_C0_oserror, test_processmanager_exit_UT_C0_exception, test_processmanager_exit_UT_C0_unlink_error
        - テスト定義:
                - テストカテゴリ: C0
                - テスト区分: 正常系/UT
                - テストシナリオ: ロック開放時にロックファイル削除失敗する場合
        :
2024-01-21 22:21:46 [DEBUG] common_utils - <module> line 38: Config(env='local', common_config={'logger_path': {'LOGGER_DEF_FILE': 'tests/def/mfaUtilsLoggingHelper/logging_TimedRotate.json', 'LOGGER_MSG_FILE': 'tests/def/mfaUtilsLoggingHelper/config_MessageList.toml'}, 'input_file_path': {'UPDATE_EXCEL_PATH': 'tests/share/receive'}, 'output_file_path': {'SEND_REFFERENCE_MASTER_PATH': 'tests/share/receive'}}, package_config={'test': {'local_test': 'test'}}, log_message=<bound method LoggerPackage.log_message of <src.lib.common_utils.ibr_logger_package.LoggerPackage object at 0x7fc3556c9010>>):
2024-01-21 22:23:09 [DEBUG] common_utils - <module> line 38: Config(env='local', common_config={'logger_path': {'LOGGER_DEF_FILE': 'tests/def/mfaUtilsLoggingHelper/logging_TimedRotate.json', 'LOGGER_MSG_FILE': 'tests/def/mfaUtilsLoggingHelper/config_MessageList.toml'}, 'input_file_path': {'UPDATE_EXCEL_PATH': 'tests/share/receive'}, 'output_file_path': {'SEND_REFFERENCE_MASTER_PATH': 'tests/share/receive'}}, package_config={'test': {'local_test': 'test'}}, log_message=<bound method LoggerPackage.log_message of <src.lib.common_utils.ibr_logger_package.LoggerPackage object at 0x7fb90f889b10>>):
2024-01-21 22:23:09 [DEBUG] common_utils - test_processmanager_UT_C0_normal line 78: 
        - テスト関数: test_processmanager_UT_C0_normal, test_processmanager_enter_UT_C0_exception, test_processmanager_enter_UT_C0_oserror, test_processmanager_exit_UT_C0_exception
        - テスト定義:
                - テストカテゴリ: C0
                - テスト区分: 正常系/UT
                - テストシナリオ:
                    with ProcessManager('test_package'): ステートメントを使用すると
                    ProcessManager クラスのインスタンスがコンテキストマネージャとして機能します。
                    Pythonのコンテキストマネージャは、with ステートメントのブロックに入る際に
                    __enter__ メソッドを呼び出し、ブロックを抜ける際に __exit__ メソッドを呼び出します。

                    このテストケースでは、ProcessManager の __enter__ メソッドが呼び出されると
                    fcntl.flock を使用してファイルロックを試みます。
                    これは、プロセスが排他的にリソースを使用することを保証するためです。
                    with ブロックを抜けると、ProcessManager の __exit__ メソッドが呼び出され
                    fcntl.flock を使用してファイルロックを解放します。

                    呼び出しの引数は、最初が (5, 6) で、2回目が (5, 8) です。
                    5 はファイル記述子
                    6 は fcntl.LOCK_EX | fcntl.LOCK_NB(排他的ロックを試みる)
                    8 は fcntl.LOCK_UN(ロックの解放)
                    を表しています。
        :
2024-01-21 22:23:09 [DEBUG] common_utils - test_processmanager_enter_UT_C0_oserror line 116: 
        - テスト関数: test_processmanager_UT_C0_normal, test_processmanager_enter_UT_C0_exception, test_processmanager_enter_UT_C0_oserror, test_processmanager_exit_UT_C0_exception
        - テスト定義:
                - テストカテゴリ: C0
                - テスト区分: 正常系/UT
                - テストシナリオ: ロック作成時にエラー OSErrorが発生する場合
        :
2024-01-21 22:23:09 [ERROR] common_utils - __enter__ line 80: already runnning: test_package:
2024-01-21 22:23:09 [DEBUG] common_utils - test_processmanager_enter_UT_C0_exception line 150: 
        - テスト関数: test_processmanager_UT_C0_normal, test_processmanager_enter_UT_C0_exception, test_processmanager_enter_UT_C0_oserror, test_processmanager_exit_UT_C0_exception
        - テスト定義:
                - テストカテゴリ: C0
                - テスト区分: 正常系/UT
                - テストシナリオ: ロック作成時にエラー Exceptionが発生する場合
        :
2024-01-21 22:23:09 [ERROR] common_utils - __enter__ line 83: Failed to multiprocess check: :
2024-01-21 22:23:09 [ERROR] common_utils - __enter__ line 85: Traceback (most recent call last):
  File "/developer/library_dev/project_1/src/lib/common_utils/ibr_multiprocess_lock.py", line 78, in __enter__
    fcntl.flock(self.lock_file.fileno(), fcntl.LOCK_EX | fcntl.LOCK_NB)
  File "/home/satoshi/.pyenv/versions/3.11.6/lib/python3.11/unittest/mock.py", line 1124, in __call__
    return self._mock_call(*args, **kwargs)
           ^^^^^^^^^^^^^^^^^^^^^^^^^^^^^^^^
  File "/home/satoshi/.pyenv/versions/3.11.6/lib/python3.11/unittest/mock.py", line 1128, in _mock_call
    return self._execute_mock_call(*args, **kwargs)
           ^^^^^^^^^^^^^^^^^^^^^^^^^^^^^^^^^^^^^^^^
  File "/home/satoshi/.pyenv/versions/3.11.6/lib/python3.11/unittest/mock.py", line 1187, in _execute_mock_call
    raise result
Exception
:
2024-01-21 22:23:09 [DEBUG] common_utils - test_processmanager_exit_UT_C0_exception line 183: 
        - テスト関数: test_processmanager_UT_C0_normal, test_processmanager_enter_UT_C0_exception, test_processmanager_enter_UT_C0_oserror, test_processmanager_exit_UT_C0_exception
        - テスト定義:
                - テストカテゴリ: C0
                - テスト区分: 正常系/UT
                - テストシナリオ: ロック開放時にエラー Exceptionが発生する場合
        :
2024-01-21 22:23:09 [ERROR] common_utils - __enter__ line 83: Failed to multiprocess check: :
2024-01-21 22:23:09 [ERROR] common_utils - __enter__ line 85: Traceback (most recent call last):
  File "/developer/library_dev/project_1/src/lib/common_utils/ibr_multiprocess_lock.py", line 78, in __enter__
    fcntl.flock(self.lock_file.fileno(), fcntl.LOCK_EX | fcntl.LOCK_NB)
  File "/home/satoshi/.pyenv/versions/3.11.6/lib/python3.11/unittest/mock.py", line 1124, in __call__
    return self._mock_call(*args, **kwargs)
           ^^^^^^^^^^^^^^^^^^^^^^^^^^^^^^^^
  File "/home/satoshi/.pyenv/versions/3.11.6/lib/python3.11/unittest/mock.py", line 1128, in _mock_call
    return self._execute_mock_call(*args, **kwargs)
           ^^^^^^^^^^^^^^^^^^^^^^^^^^^^^^^^^^^^^^^^
  File "/home/satoshi/.pyenv/versions/3.11.6/lib/python3.11/unittest/mock.py", line 1183, in _execute_mock_call
    raise effect
Exception
:
2024-01-21 22:23:15 [DEBUG] common_utils - <module> line 38: Config(env='local', common_config={'logger_path': {'LOGGER_DEF_FILE': 'tests/def/mfaUtilsLoggingHelper/logging_TimedRotate.json', 'LOGGER_MSG_FILE': 'tests/def/mfaUtilsLoggingHelper/config_MessageList.toml'}, 'input_file_path': {'UPDATE_EXCEL_PATH': 'tests/share/receive'}, 'output_file_path': {'SEND_REFFERENCE_MASTER_PATH': 'tests/share/receive'}}, package_config={'test': {'local_test': 'test'}}, log_message=<bound method LoggerPackage.log_message of <src.lib.common_utils.ibr_logger_package.LoggerPackage object at 0x7f2e3f810890>>):
2024-01-21 22:23:15 [DEBUG] common_utils - test_processmanager_UT_C0_normal line 78: 
        - テスト関数: test_processmanager_UT_C0_normal, test_processmanager_enter_UT_C0_exception, test_processmanager_enter_UT_C0_oserror, test_processmanager_exit_UT_C0_exception
        - テスト定義:
                - テストカテゴリ: C0
                - テスト区分: 正常系/UT
                - テストシナリオ:
                    with ProcessManager('test_package'): ステートメントを使用すると
                    ProcessManager クラスのインスタンスがコンテキストマネージャとして機能します。
                    Pythonのコンテキストマネージャは、with ステートメントのブロックに入る際に
                    __enter__ メソッドを呼び出し、ブロックを抜ける際に __exit__ メソッドを呼び出します。

                    このテストケースでは、ProcessManager の __enter__ メソッドが呼び出されると
                    fcntl.flock を使用してファイルロックを試みます。
                    これは、プロセスが排他的にリソースを使用することを保証するためです。
                    with ブロックを抜けると、ProcessManager の __exit__ メソッドが呼び出され
                    fcntl.flock を使用してファイルロックを解放します。

                    呼び出しの引数は、最初が (5, 6) で、2回目が (5, 8) です。
                    5 はファイル記述子
                    6 は fcntl.LOCK_EX | fcntl.LOCK_NB(排他的ロックを試みる)
                    8 は fcntl.LOCK_UN(ロックの解放)
                    を表しています。
        :
2024-01-21 22:23:15 [DEBUG] common_utils - test_processmanager_enter_UT_C0_oserror line 116: 
        - テスト関数: test_processmanager_UT_C0_normal, test_processmanager_enter_UT_C0_exception, test_processmanager_enter_UT_C0_oserror, test_processmanager_exit_UT_C0_exception
        - テスト定義:
                - テストカテゴリ: C0
                - テスト区分: 正常系/UT
                - テストシナリオ: ロック作成時にエラー OSErrorが発生する場合
        :
2024-01-21 22:23:15 [ERROR] common_utils - __enter__ line 80: already runnning: test_package:
2024-01-21 22:23:15 [DEBUG] common_utils - test_processmanager_enter_UT_C0_exception line 150: 
        - テスト関数: test_processmanager_UT_C0_normal, test_processmanager_enter_UT_C0_exception, test_processmanager_enter_UT_C0_oserror, test_processmanager_exit_UT_C0_exception
        - テスト定義:
                - テストカテゴリ: C0
                - テスト区分: 正常系/UT
                - テストシナリオ: ロック作成時にエラー Exceptionが発生する場合
        :
2024-01-21 22:23:15 [ERROR] common_utils - __enter__ line 83: Failed to multiprocess check: :
2024-01-21 22:23:15 [ERROR] common_utils - __enter__ line 85: Traceback (most recent call last):
  File "/developer/library_dev/project_1/src/lib/common_utils/ibr_multiprocess_lock.py", line 78, in __enter__
    fcntl.flock(self.lock_file.fileno(), fcntl.LOCK_EX | fcntl.LOCK_NB)
  File "/home/satoshi/.pyenv/versions/3.11.6/lib/python3.11/unittest/mock.py", line 1124, in __call__
    return self._mock_call(*args, **kwargs)
           ^^^^^^^^^^^^^^^^^^^^^^^^^^^^^^^^
  File "/home/satoshi/.pyenv/versions/3.11.6/lib/python3.11/unittest/mock.py", line 1128, in _mock_call
    return self._execute_mock_call(*args, **kwargs)
           ^^^^^^^^^^^^^^^^^^^^^^^^^^^^^^^^^^^^^^^^
  File "/home/satoshi/.pyenv/versions/3.11.6/lib/python3.11/unittest/mock.py", line 1187, in _execute_mock_call
    raise result
Exception
:
2024-01-21 22:23:15 [DEBUG] common_utils - test_processmanager_exit_UT_C0_exception line 183: 
        - テスト関数: test_processmanager_UT_C0_normal, test_processmanager_enter_UT_C0_exception, test_processmanager_enter_UT_C0_oserror, test_processmanager_exit_UT_C0_exception
        - テスト定義:
                - テストカテゴリ: C0
                - テスト区分: 正常系/UT
                - テストシナリオ: ロック開放時にエラー Exceptionが発生する場合
        :
2024-01-21 22:23:15 [ERROR] common_utils - __enter__ line 83: Failed to multiprocess check: :
2024-01-21 22:23:15 [ERROR] common_utils - __enter__ line 85: Traceback (most recent call last):
  File "/developer/library_dev/project_1/src/lib/common_utils/ibr_multiprocess_lock.py", line 78, in __enter__
    fcntl.flock(self.lock_file.fileno(), fcntl.LOCK_EX | fcntl.LOCK_NB)
  File "/home/satoshi/.pyenv/versions/3.11.6/lib/python3.11/unittest/mock.py", line 1124, in __call__
    return self._mock_call(*args, **kwargs)
           ^^^^^^^^^^^^^^^^^^^^^^^^^^^^^^^^
  File "/home/satoshi/.pyenv/versions/3.11.6/lib/python3.11/unittest/mock.py", line 1128, in _mock_call
    return self._execute_mock_call(*args, **kwargs)
           ^^^^^^^^^^^^^^^^^^^^^^^^^^^^^^^^^^^^^^^^
  File "/home/satoshi/.pyenv/versions/3.11.6/lib/python3.11/unittest/mock.py", line 1183, in _execute_mock_call
    raise effect
Exception
:
2024-01-21 22:25:16 [DEBUG] common_utils - <module> line 38: Config(env='local', common_config={'logger_path': {'LOGGER_DEF_FILE': 'tests/def/mfaUtilsLoggingHelper/logging_TimedRotate.json', 'LOGGER_MSG_FILE': 'tests/def/mfaUtilsLoggingHelper/config_MessageList.toml'}, 'input_file_path': {'UPDATE_EXCEL_PATH': 'tests/share/receive'}, 'output_file_path': {'SEND_REFFERENCE_MASTER_PATH': 'tests/share/receive'}}, package_config={'test': {'local_test': 'test'}}, log_message=<bound method LoggerPackage.log_message of <src.lib.common_utils.ibr_logger_package.LoggerPackage object at 0x7f66c6b30a50>>):
2024-01-21 22:25:16 [DEBUG] common_utils - test_processmanager_UT_C0_normal line 78: 
        - テスト関数: test_processmanager_UT_C0_normal, test_processmanager_enter_UT_C0_exception, test_processmanager_enter_UT_C0_oserror, test_processmanager_exit_UT_C0_delete_file_error_exception, test_processmanager_exit_UT_C0_exception
        - テスト定義:
                - テストカテゴリ: C0
                - テスト区分: 正常系/UT
                - テストシナリオ:
                    with ProcessManager('test_package'): ステートメントを使用すると
                    ProcessManager クラスのインスタンスがコンテキストマネージャとして機能します。
                    Pythonのコンテキストマネージャは、with ステートメントのブロックに入る際に
                    __enter__ メソッドを呼び出し、ブロックを抜ける際に __exit__ メソッドを呼び出します。

                    このテストケースでは、ProcessManager の __enter__ メソッドが呼び出されると
                    fcntl.flock を使用してファイルロックを試みます。
                    これは、プロセスが排他的にリソースを使用することを保証するためです。
                    with ブロックを抜けると、ProcessManager の __exit__ メソッドが呼び出され
                    fcntl.flock を使用してファイルロックを解放します。

                    呼び出しの引数は、最初が (5, 6) で、2回目が (5, 8) です。
                    5 はファイル記述子
                    6 は fcntl.LOCK_EX | fcntl.LOCK_NB(排他的ロックを試みる)
                    8 は fcntl.LOCK_UN(ロックの解放)
                    を表しています。
        :
2024-01-21 22:25:16 [DEBUG] common_utils - test_processmanager_enter_UT_C0_oserror line 116: 
        - テスト関数: test_processmanager_UT_C0_normal, test_processmanager_enter_UT_C0_exception, test_processmanager_enter_UT_C0_oserror, test_processmanager_exit_UT_C0_delete_file_error_exception, test_processmanager_exit_UT_C0_exception
        - テスト定義:
                - テストカテゴリ: C0
                - テスト区分: 正常系/UT
                - テストシナリオ: ロック作成時にエラー OSErrorが発生する場合
        :
2024-01-21 22:25:16 [ERROR] common_utils - __enter__ line 80: already runnning: test_package:
2024-01-21 22:25:16 [DEBUG] common_utils - test_processmanager_enter_UT_C0_exception line 150: 
        - テスト関数: test_processmanager_UT_C0_normal, test_processmanager_enter_UT_C0_exception, test_processmanager_enter_UT_C0_oserror, test_processmanager_exit_UT_C0_delete_file_error_exception, test_processmanager_exit_UT_C0_exception
        - テスト定義:
                - テストカテゴリ: C0
                - テスト区分: 正常系/UT
                - テストシナリオ: ロック作成時にエラー Exceptionが発生する場合
        :
2024-01-21 22:25:16 [ERROR] common_utils - __enter__ line 83: Failed to multiprocess check: :
2024-01-21 22:25:16 [ERROR] common_utils - __enter__ line 85: Traceback (most recent call last):
  File "/developer/library_dev/project_1/src/lib/common_utils/ibr_multiprocess_lock.py", line 78, in __enter__
    fcntl.flock(self.lock_file.fileno(), fcntl.LOCK_EX | fcntl.LOCK_NB)
  File "/home/satoshi/.pyenv/versions/3.11.6/lib/python3.11/unittest/mock.py", line 1124, in __call__
    return self._mock_call(*args, **kwargs)
           ^^^^^^^^^^^^^^^^^^^^^^^^^^^^^^^^
  File "/home/satoshi/.pyenv/versions/3.11.6/lib/python3.11/unittest/mock.py", line 1128, in _mock_call
    return self._execute_mock_call(*args, **kwargs)
           ^^^^^^^^^^^^^^^^^^^^^^^^^^^^^^^^^^^^^^^^
  File "/home/satoshi/.pyenv/versions/3.11.6/lib/python3.11/unittest/mock.py", line 1187, in _execute_mock_call
    raise result
Exception
:
2024-01-21 22:25:16 [DEBUG] common_utils - test_processmanager_exit_UT_C0_exception line 183: 
        - テスト関数: test_processmanager_UT_C0_normal, test_processmanager_enter_UT_C0_exception, test_processmanager_enter_UT_C0_oserror, test_processmanager_exit_UT_C0_delete_file_error_exception, test_processmanager_exit_UT_C0_exception
        - テスト定義:
                - テストカテゴリ: C0
                - テスト区分: 正常系/UT
                - テストシナリオ: ロック開放時にエラー Exceptionが発生する場合
        :
2024-01-21 22:25:16 [ERROR] common_utils - __exit__ line 95: Failed to release lockfile: :
2024-01-21 22:25:16 [DEBUG] common_utils - test_processmanager_exit_UT_C0_delete_file_error_exception line 217: 
        - テスト関数: test_processmanager_UT_C0_normal, test_processmanager_enter_UT_C0_exception, test_processmanager_enter_UT_C0_oserror, test_processmanager_exit_UT_C0_delete_file_error_exception, test_processmanager_exit_UT_C0_exception
        - テスト定義:
                - テストカテゴリ: C0
                - テスト区分: 正常系/UT
                - テストシナリオ: ロック開放時にエラー Exceptionが発生する場合
        :
2024-01-21 22:25:16 [ERROR] common_utils - __enter__ line 83: Failed to multiprocess check: :
2024-01-21 22:25:16 [ERROR] common_utils - __enter__ line 85: Traceback (most recent call last):
  File "/developer/library_dev/project_1/src/lib/common_utils/ibr_multiprocess_lock.py", line 78, in __enter__
    fcntl.flock(self.lock_file.fileno(), fcntl.LOCK_EX | fcntl.LOCK_NB)
  File "/home/satoshi/.pyenv/versions/3.11.6/lib/python3.11/unittest/mock.py", line 1124, in __call__
    return self._mock_call(*args, **kwargs)
           ^^^^^^^^^^^^^^^^^^^^^^^^^^^^^^^^
  File "/home/satoshi/.pyenv/versions/3.11.6/lib/python3.11/unittest/mock.py", line 1128, in _mock_call
    return self._execute_mock_call(*args, **kwargs)
           ^^^^^^^^^^^^^^^^^^^^^^^^^^^^^^^^^^^^^^^^
  File "/home/satoshi/.pyenv/versions/3.11.6/lib/python3.11/unittest/mock.py", line 1183, in _execute_mock_call
    raise effect
Exception
:
2024-01-21 22:26:03 [DEBUG] common_utils - <module> line 38: Config(env='local', common_config={'logger_path': {'LOGGER_DEF_FILE': 'tests/def/mfaUtilsLoggingHelper/logging_TimedRotate.json', 'LOGGER_MSG_FILE': 'tests/def/mfaUtilsLoggingHelper/config_MessageList.toml'}, 'input_file_path': {'UPDATE_EXCEL_PATH': 'tests/share/receive'}, 'output_file_path': {'SEND_REFFERENCE_MASTER_PATH': 'tests/share/receive'}}, package_config={'test': {'local_test': 'test'}}, log_message=<bound method LoggerPackage.log_message of <src.lib.common_utils.ibr_logger_package.LoggerPackage object at 0x7fb723f90a50>>):
2024-01-21 22:26:03 [DEBUG] common_utils - test_processmanager_UT_C0_normal line 78: 
        - テスト関数: test_processmanager_UT_C0_normal, test_processmanager_enter_UT_C0_exception, test_processmanager_enter_UT_C0_oserror, test_processmanager_exit_UT_C0_exception
        - テスト定義:
                - テストカテゴリ: C0
                - テスト区分: 正常系/UT
                - テストシナリオ:
                    with ProcessManager('test_package'): ステートメントを使用すると
                    ProcessManager クラスのインスタンスがコンテキストマネージャとして機能します。
                    Pythonのコンテキストマネージャは、with ステートメントのブロックに入る際に
                    __enter__ メソッドを呼び出し、ブロックを抜ける際に __exit__ メソッドを呼び出します。

                    このテストケースでは、ProcessManager の __enter__ メソッドが呼び出されると
                    fcntl.flock を使用してファイルロックを試みます。
                    これは、プロセスが排他的にリソースを使用することを保証するためです。
                    with ブロックを抜けると、ProcessManager の __exit__ メソッドが呼び出され
                    fcntl.flock を使用してファイルロックを解放します。

                    呼び出しの引数は、最初が (5, 6) で、2回目が (5, 8) です。
                    5 はファイル記述子
                    6 は fcntl.LOCK_EX | fcntl.LOCK_NB(排他的ロックを試みる)
                    8 は fcntl.LOCK_UN(ロックの解放)
                    を表しています。
        :
2024-01-21 22:26:03 [DEBUG] common_utils - test_processmanager_enter_UT_C0_oserror line 116: 
        - テスト関数: test_processmanager_UT_C0_normal, test_processmanager_enter_UT_C0_exception, test_processmanager_enter_UT_C0_oserror, test_processmanager_exit_UT_C0_exception
        - テスト定義:
                - テストカテゴリ: C0
                - テスト区分: 正常系/UT
                - テストシナリオ: ロック作成時にエラー OSErrorが発生する場合
        :
2024-01-21 22:26:03 [ERROR] common_utils - __enter__ line 80: already runnning: test_package:
2024-01-21 22:26:03 [DEBUG] common_utils - test_processmanager_enter_UT_C0_exception line 150: 
        - テスト関数: test_processmanager_UT_C0_normal, test_processmanager_enter_UT_C0_exception, test_processmanager_enter_UT_C0_oserror, test_processmanager_exit_UT_C0_exception
        - テスト定義:
                - テストカテゴリ: C0
                - テスト区分: 正常系/UT
                - テストシナリオ: ロック作成時にエラー Exceptionが発生する場合
        :
2024-01-21 22:26:03 [ERROR] common_utils - __enter__ line 83: Failed to multiprocess check: :
2024-01-21 22:26:03 [ERROR] common_utils - __enter__ line 85: Traceback (most recent call last):
  File "/developer/library_dev/project_1/src/lib/common_utils/ibr_multiprocess_lock.py", line 78, in __enter__
    fcntl.flock(self.lock_file.fileno(), fcntl.LOCK_EX | fcntl.LOCK_NB)
  File "/home/satoshi/.pyenv/versions/3.11.6/lib/python3.11/unittest/mock.py", line 1124, in __call__
    return self._mock_call(*args, **kwargs)
           ^^^^^^^^^^^^^^^^^^^^^^^^^^^^^^^^
  File "/home/satoshi/.pyenv/versions/3.11.6/lib/python3.11/unittest/mock.py", line 1128, in _mock_call
    return self._execute_mock_call(*args, **kwargs)
           ^^^^^^^^^^^^^^^^^^^^^^^^^^^^^^^^^^^^^^^^
  File "/home/satoshi/.pyenv/versions/3.11.6/lib/python3.11/unittest/mock.py", line 1187, in _execute_mock_call
    raise result
Exception
:
2024-01-21 22:26:03 [DEBUG] common_utils - test_processmanager_exit_UT_C0_exception line 183: 
        - テスト関数: test_processmanager_UT_C0_normal, test_processmanager_enter_UT_C0_exception, test_processmanager_enter_UT_C0_oserror, test_processmanager_exit_UT_C0_exception
        - テスト定義:
                - テストカテゴリ: C0
                - テスト区分: 正常系/UT
                - テストシナリオ: ロック開放時にエラー Exceptionが発生する場合
        :
2024-01-21 22:26:03 [ERROR] common_utils - __exit__ line 95: Failed to release lockfile: :
2024-01-21 22:29:51 [DEBUG] common_utils - <module> line 38: Config(env='local', common_config={'logger_path': {'LOGGER_DEF_FILE': 'tests/def/mfaUtilsLoggingHelper/logging_TimedRotate.json', 'LOGGER_MSG_FILE': 'tests/def/mfaUtilsLoggingHelper/config_MessageList.toml'}, 'input_file_path': {'UPDATE_EXCEL_PATH': 'tests/share/receive'}, 'output_file_path': {'SEND_REFFERENCE_MASTER_PATH': 'tests/share/receive'}}, package_config={'test': {'local_test': 'test'}}, log_message=<bound method LoggerPackage.log_message of <src.lib.common_utils.ibr_logger_package.LoggerPackage object at 0x7f75092afa50>>):
2024-01-21 22:29:51 [DEBUG] common_utils - test_processmanager_UT_C0_normal line 78: 
        - テスト関数: test_processmanager_UT_C0_normal, test_processmanager_enter_UT_C0_exception, test_processmanager_enter_UT_C0_oserror, test_processmanager_exit_UT_C0_delete_file_error_exception, test_processmanager_exit_UT_C0_exception
        - テスト定義:
                - テストカテゴリ: C0
                - テスト区分: 正常系/UT
                - テストシナリオ:
                    with ProcessManager('test_package'): ステートメントを使用すると
                    ProcessManager クラスのインスタンスがコンテキストマネージャとして機能します。
                    Pythonのコンテキストマネージャは、with ステートメントのブロックに入る際に
                    __enter__ メソッドを呼び出し、ブロックを抜ける際に __exit__ メソッドを呼び出します。

                    このテストケースでは、ProcessManager の __enter__ メソッドが呼び出されると
                    fcntl.flock を使用してファイルロックを試みます。
                    これは、プロセスが排他的にリソースを使用することを保証するためです。
                    with ブロックを抜けると、ProcessManager の __exit__ メソッドが呼び出され
                    fcntl.flock を使用してファイルロックを解放します。

                    呼び出しの引数は、最初が (5, 6) で、2回目が (5, 8) です。
                    5 はファイル記述子
                    6 は fcntl.LOCK_EX | fcntl.LOCK_NB(排他的ロックを試みる)
                    8 は fcntl.LOCK_UN(ロックの解放)
                    を表しています。
        :
2024-01-21 22:29:51 [DEBUG] common_utils - test_processmanager_enter_UT_C0_oserror line 116: 
        - テスト関数: test_processmanager_UT_C0_normal, test_processmanager_enter_UT_C0_exception, test_processmanager_enter_UT_C0_oserror, test_processmanager_exit_UT_C0_delete_file_error_exception, test_processmanager_exit_UT_C0_exception
        - テスト定義:
                - テストカテゴリ: C0
                - テスト区分: 正常系/UT
                - テストシナリオ: ロック作成時にエラー OSErrorが発生する場合
        :
2024-01-21 22:29:51 [ERROR] common_utils - __enter__ line 80: already runnning: test_package:
2024-01-21 22:29:52 [DEBUG] common_utils - test_processmanager_enter_UT_C0_exception line 150: 
        - テスト関数: test_processmanager_UT_C0_normal, test_processmanager_enter_UT_C0_exception, test_processmanager_enter_UT_C0_oserror, test_processmanager_exit_UT_C0_delete_file_error_exception, test_processmanager_exit_UT_C0_exception
        - テスト定義:
                - テストカテゴリ: C0
                - テスト区分: 正常系/UT
                - テストシナリオ: ロック作成時にエラー Exceptionが発生する場合
        :
2024-01-21 22:29:52 [ERROR] common_utils - __enter__ line 83: Failed to multiprocess check: :
2024-01-21 22:29:52 [ERROR] common_utils - __enter__ line 85: Traceback (most recent call last):
  File "/developer/library_dev/project_1/src/lib/common_utils/ibr_multiprocess_lock.py", line 78, in __enter__
    fcntl.flock(self.lock_file.fileno(), fcntl.LOCK_EX | fcntl.LOCK_NB)
  File "/home/satoshi/.pyenv/versions/3.11.6/lib/python3.11/unittest/mock.py", line 1124, in __call__
    return self._mock_call(*args, **kwargs)
           ^^^^^^^^^^^^^^^^^^^^^^^^^^^^^^^^
  File "/home/satoshi/.pyenv/versions/3.11.6/lib/python3.11/unittest/mock.py", line 1128, in _mock_call
    return self._execute_mock_call(*args, **kwargs)
           ^^^^^^^^^^^^^^^^^^^^^^^^^^^^^^^^^^^^^^^^
  File "/home/satoshi/.pyenv/versions/3.11.6/lib/python3.11/unittest/mock.py", line 1187, in _execute_mock_call
    raise result
Exception
:
2024-01-21 22:29:52 [DEBUG] common_utils - test_processmanager_exit_UT_C0_exception line 183: 
        - テスト関数: test_processmanager_UT_C0_normal, test_processmanager_enter_UT_C0_exception, test_processmanager_enter_UT_C0_oserror, test_processmanager_exit_UT_C0_delete_file_error_exception, test_processmanager_exit_UT_C0_exception
        - テスト定義:
                - テストカテゴリ: C0
                - テスト区分: 正常系/UT
                - テストシナリオ: ロック開放時にエラー Exceptionが発生する場合
        :
2024-01-21 22:29:52 [ERROR] common_utils - __exit__ line 95: Failed to release lockfile: :
2024-01-21 22:29:52 [DEBUG] common_utils - test_processmanager_exit_UT_C0_delete_file_error_exception line 217: 
        - テスト関数: test_processmanager_UT_C0_normal, test_processmanager_enter_UT_C0_exception, test_processmanager_enter_UT_C0_oserror, test_processmanager_exit_UT_C0_delete_file_error_exception, test_processmanager_exit_UT_C0_exception
        - テスト定義:
                - テストカテゴリ: C0
                - テスト区分: 正常系/UT
                - テストシナリオ: ロック開放時にエラー Exceptionが発生する場合
        :
2024-01-21 22:31:42 [DEBUG] common_utils - <module> line 38: Config(env='local', common_config={'logger_path': {'LOGGER_DEF_FILE': 'tests/def/mfaUtilsLoggingHelper/logging_TimedRotate.json', 'LOGGER_MSG_FILE': 'tests/def/mfaUtilsLoggingHelper/config_MessageList.toml'}, 'input_file_path': {'UPDATE_EXCEL_PATH': 'tests/share/receive'}, 'output_file_path': {'SEND_REFFERENCE_MASTER_PATH': 'tests/share/receive'}}, package_config={'test': {'local_test': 'test'}}, log_message=<bound method LoggerPackage.log_message of <src.lib.common_utils.ibr_logger_package.LoggerPackage object at 0x7f981d7fc390>>):
2024-01-21 22:31:42 [DEBUG] common_utils - test_processmanager_UT_C0_normal line 78: 
        - テスト関数: test_processmanager_UT_C0_normal, test_processmanager_enter_UT_C0_exception, test_processmanager_enter_UT_C0_oserror, test_processmanager_exit_UT_C0_delete_file_error_exception, test_processmanager_exit_UT_C0_exception
        - テスト定義:
                - テストカテゴリ: C0
                - テスト区分: 正常系/UT
                - テストシナリオ:
                    with ProcessManager('test_package'): ステートメントを使用すると
                    ProcessManager クラスのインスタンスがコンテキストマネージャとして機能します。
                    Pythonのコンテキストマネージャは、with ステートメントのブロックに入る際に
                    __enter__ メソッドを呼び出し、ブロックを抜ける際に __exit__ メソッドを呼び出します。

                    このテストケースでは、ProcessManager の __enter__ メソッドが呼び出されると
                    fcntl.flock を使用してファイルロックを試みます。
                    これは、プロセスが排他的にリソースを使用することを保証するためです。
                    with ブロックを抜けると、ProcessManager の __exit__ メソッドが呼び出され
                    fcntl.flock を使用してファイルロックを解放します。

                    呼び出しの引数は、最初が (5, 6) で、2回目が (5, 8) です。
                    5 はファイル記述子
                    6 は fcntl.LOCK_EX | fcntl.LOCK_NB(排他的ロックを試みる)
                    8 は fcntl.LOCK_UN(ロックの解放)
                    を表しています。
        :
2024-01-21 22:31:42 [DEBUG] common_utils - test_processmanager_enter_UT_C0_oserror line 116: 
        - テスト関数: test_processmanager_UT_C0_normal, test_processmanager_enter_UT_C0_exception, test_processmanager_enter_UT_C0_oserror, test_processmanager_exit_UT_C0_delete_file_error_exception, test_processmanager_exit_UT_C0_exception
        - テスト定義:
                - テストカテゴリ: C0
                - テスト区分: 正常系/UT
                - テストシナリオ: ロック作成時にエラー OSErrorが発生する場合
        :
2024-01-21 22:31:42 [ERROR] common_utils - __enter__ line 80: already runnning: test_package:
2024-01-21 22:31:42 [DEBUG] common_utils - test_processmanager_enter_UT_C0_exception line 150: 
        - テスト関数: test_processmanager_UT_C0_normal, test_processmanager_enter_UT_C0_exception, test_processmanager_enter_UT_C0_oserror, test_processmanager_exit_UT_C0_delete_file_error_exception, test_processmanager_exit_UT_C0_exception
        - テスト定義:
                - テストカテゴリ: C0
                - テスト区分: 正常系/UT
                - テストシナリオ: ロック作成時にエラー Exceptionが発生する場合
        :
2024-01-21 22:31:42 [ERROR] common_utils - __enter__ line 83: Failed to multiprocess check: :
2024-01-21 22:31:42 [ERROR] common_utils - __enter__ line 85: Traceback (most recent call last):
  File "/developer/library_dev/project_1/src/lib/common_utils/ibr_multiprocess_lock.py", line 78, in __enter__
    fcntl.flock(self.lock_file.fileno(), fcntl.LOCK_EX | fcntl.LOCK_NB)
  File "/home/satoshi/.pyenv/versions/3.11.6/lib/python3.11/unittest/mock.py", line 1124, in __call__
    return self._mock_call(*args, **kwargs)
           ^^^^^^^^^^^^^^^^^^^^^^^^^^^^^^^^
  File "/home/satoshi/.pyenv/versions/3.11.6/lib/python3.11/unittest/mock.py", line 1128, in _mock_call
    return self._execute_mock_call(*args, **kwargs)
           ^^^^^^^^^^^^^^^^^^^^^^^^^^^^^^^^^^^^^^^^
  File "/home/satoshi/.pyenv/versions/3.11.6/lib/python3.11/unittest/mock.py", line 1187, in _execute_mock_call
    raise result
Exception
:
2024-01-21 22:31:42 [DEBUG] common_utils - test_processmanager_exit_UT_C0_exception line 183: 
        - テスト関数: test_processmanager_UT_C0_normal, test_processmanager_enter_UT_C0_exception, test_processmanager_enter_UT_C0_oserror, test_processmanager_exit_UT_C0_delete_file_error_exception, test_processmanager_exit_UT_C0_exception
        - テスト定義:
                - テストカテゴリ: C0
                - テスト区分: 正常系/UT
                - テストシナリオ: ロック開放時にエラー Exceptionが発生する場合
        :
2024-01-21 22:31:42 [ERROR] common_utils - __exit__ line 94: Failed to release lockfile: :
2024-01-21 22:31:42 [DEBUG] common_utils - test_processmanager_exit_UT_C0_delete_file_error_exception line 217: 
        - テスト関数: test_processmanager_UT_C0_normal, test_processmanager_enter_UT_C0_exception, test_processmanager_enter_UT_C0_oserror, test_processmanager_exit_UT_C0_delete_file_error_exception, test_processmanager_exit_UT_C0_exception
        - テスト定義:
                - テストカテゴリ: C0
                - テスト区分: 正常系/UT
                - テストシナリオ: ロック開放時にエラー Exceptionが発生する場合
        :
2024-01-21 22:46:21 [DEBUG] common_utils - <module> line 38: Config(env='local', common_config={'logger_path': {'LOGGER_DEF_FILE': 'tests/def/mfaUtilsLoggingHelper/logging_TimedRotate.json', 'LOGGER_MSG_FILE': 'tests/def/mfaUtilsLoggingHelper/config_MessageList.toml'}, 'input_file_path': {'UPDATE_EXCEL_PATH': 'tests/share/receive'}, 'output_file_path': {'SEND_REFFERENCE_MASTER_PATH': 'tests/share/receive'}}, package_config={'test': {'local_test': 'test'}}, log_message=<bound method LoggerPackage.log_message of <src.lib.common_utils.ibr_logger_package.LoggerPackage object at 0x7f1c76411a50>>):
2024-01-21 22:46:21 [DEBUG] common_utils - test_processmanager_UT_C0_normal line 78: 
        - テスト関数: test_processmanager_UT_C0_normal, test_processmanager_enter_UT_C0_exception, test_processmanager_enter_UT_C0_oserror, test_processmanager_exit_UT_C0_delete_file_error_exception, test_processmanager_exit_UT_C0_exception
        - テスト定義:
                - テストカテゴリ: C0
                - テスト区分: 正常系/UT
                - テストシナリオ:
                    with ProcessManager('test_package'): ステートメントを使用すると
                    ProcessManager クラスのインスタンスがコンテキストマネージャとして機能します。
                    Pythonのコンテキストマネージャは、with ステートメントのブロックに入る際に
                    __enter__ メソッドを呼び出し、ブロックを抜ける際に __exit__ メソッドを呼び出します。

                    このテストケースでは、ProcessManager の __enter__ メソッドが呼び出されると
                    fcntl.flock を使用してファイルロックを試みます。
                    これは、プロセスが排他的にリソースを使用することを保証するためです。
                    with ブロックを抜けると、ProcessManager の __exit__ メソッドが呼び出され
                    fcntl.flock を使用してファイルロックを解放します。

                    呼び出しの引数は、最初が (5, 6) で、2回目が (5, 8) です。
                    5 はファイル記述子
                    6 は fcntl.LOCK_EX | fcntl.LOCK_NB(排他的ロックを試みる)
                    8 は fcntl.LOCK_UN(ロックの解放)
                    を表しています。
        :
2024-01-21 22:46:21 [DEBUG] common_utils - test_processmanager_enter_UT_C0_oserror line 116: 
        - テスト関数: test_processmanager_UT_C0_normal, test_processmanager_enter_UT_C0_exception, test_processmanager_enter_UT_C0_oserror, test_processmanager_exit_UT_C0_delete_file_error_exception, test_processmanager_exit_UT_C0_exception
        - テスト定義:
                - テストカテゴリ: C0
                - テスト区分: 正常系/UT
                - テストシナリオ: ロック作成時にエラー OSErrorが発生する場合
        :
2024-01-21 22:46:21 [ERROR] common_utils - __enter__ line 80: already runnning: test_package:
2024-01-21 22:46:21 [DEBUG] common_utils - test_processmanager_enter_UT_C0_exception line 150: 
        - テスト関数: test_processmanager_UT_C0_normal, test_processmanager_enter_UT_C0_exception, test_processmanager_enter_UT_C0_oserror, test_processmanager_exit_UT_C0_delete_file_error_exception, test_processmanager_exit_UT_C0_exception
        - テスト定義:
                - テストカテゴリ: C0
                - テスト区分: 正常系/UT
                - テストシナリオ: ロック作成時にエラー Exceptionが発生する場合
        :
2024-01-21 22:46:21 [ERROR] common_utils - __enter__ line 83: Failed to multiprocess check: :
2024-01-21 22:46:21 [ERROR] common_utils - __enter__ line 85: Traceback (most recent call last):
  File "/developer/library_dev/project_1/src/lib/common_utils/ibr_multiprocess_lock.py", line 78, in __enter__
    fcntl.flock(self.lock_file.fileno(), fcntl.LOCK_EX | fcntl.LOCK_NB)
  File "/home/satoshi/.pyenv/versions/3.11.6/lib/python3.11/unittest/mock.py", line 1124, in __call__
    return self._mock_call(*args, **kwargs)
           ^^^^^^^^^^^^^^^^^^^^^^^^^^^^^^^^
  File "/home/satoshi/.pyenv/versions/3.11.6/lib/python3.11/unittest/mock.py", line 1128, in _mock_call
    return self._execute_mock_call(*args, **kwargs)
           ^^^^^^^^^^^^^^^^^^^^^^^^^^^^^^^^^^^^^^^^
  File "/home/satoshi/.pyenv/versions/3.11.6/lib/python3.11/unittest/mock.py", line 1187, in _execute_mock_call
    raise result
Exception
:
2024-01-21 22:46:21 [DEBUG] common_utils - test_processmanager_exit_UT_C0_exception line 183: 
        - テスト関数: test_processmanager_UT_C0_normal, test_processmanager_enter_UT_C0_exception, test_processmanager_enter_UT_C0_oserror, test_processmanager_exit_UT_C0_delete_file_error_exception, test_processmanager_exit_UT_C0_exception
        - テスト定義:
                - テストカテゴリ: C0
                - テスト区分: 正常系/UT
                - テストシナリオ: ロック開放時にエラー Exceptionが発生する場合
        :
2024-01-21 22:46:21 [ERROR] common_utils - __exit__ line 95: Failed to release lockfile: :
2024-01-21 22:46:21 [DEBUG] common_utils - test_processmanager_exit_UT_C0_delete_file_error_exception line 217: 
        - テスト関数: test_processmanager_UT_C0_normal, test_processmanager_enter_UT_C0_exception, test_processmanager_enter_UT_C0_oserror, test_processmanager_exit_UT_C0_delete_file_error_exception, test_processmanager_exit_UT_C0_exception
        - テスト定義:
                - テストカテゴリ: C0
                - テスト区分: 正常系/UT
                - テストシナリオ: ロック開放時にエラー Exceptionが発生する場合
        :
2024-01-21 22:47:45 [DEBUG] common_utils - <module> line 38: Config(env='local', common_config={'logger_path': {'LOGGER_DEF_FILE': 'tests/def/mfaUtilsLoggingHelper/logging_TimedRotate.json', 'LOGGER_MSG_FILE': 'tests/def/mfaUtilsLoggingHelper/config_MessageList.toml'}, 'input_file_path': {'UPDATE_EXCEL_PATH': 'tests/share/receive'}, 'output_file_path': {'SEND_REFFERENCE_MASTER_PATH': 'tests/share/receive'}}, package_config={'test': {'local_test': 'test'}}, log_message=<bound method LoggerPackage.log_message of <src.lib.common_utils.ibr_logger_package.LoggerPackage object at 0x7f7405843a50>>):
2024-01-21 22:47:45 [DEBUG] common_utils - test_processmanager_UT_C0_normal line 78: 
        - テスト関数: test_processmanager_UT_C0_normal, test_processmanager_enter_UT_C0_exception, test_processmanager_enter_UT_C0_oserror, test_processmanager_exit_UT_C0_delete_file_error_exception, test_processmanager_exit_UT_C0_exception
        - テスト定義:
                - テストカテゴリ: C0
                - テスト区分: 正常系/UT
                - テストシナリオ:
                    with ProcessManager('test_package'): ステートメントを使用すると
                    ProcessManager クラスのインスタンスがコンテキストマネージャとして機能します。
                    Pythonのコンテキストマネージャは、with ステートメントのブロックに入る際に
                    __enter__ メソッドを呼び出し、ブロックを抜ける際に __exit__ メソッドを呼び出します。

                    このテストケースでは、ProcessManager の __enter__ メソッドが呼び出されると
                    fcntl.flock を使用してファイルロックを試みます。
                    これは、プロセスが排他的にリソースを使用することを保証するためです。
                    with ブロックを抜けると、ProcessManager の __exit__ メソッドが呼び出され
                    fcntl.flock を使用してファイルロックを解放します。

                    呼び出しの引数は、最初が (5, 6) で、2回目が (5, 8) です。
                    5 はファイル記述子
                    6 は fcntl.LOCK_EX | fcntl.LOCK_NB(排他的ロックを試みる)
                    8 は fcntl.LOCK_UN(ロックの解放)
                    を表しています。
        :
2024-01-21 22:47:45 [DEBUG] common_utils - test_processmanager_enter_UT_C0_oserror line 116: 
        - テスト関数: test_processmanager_UT_C0_normal, test_processmanager_enter_UT_C0_exception, test_processmanager_enter_UT_C0_oserror, test_processmanager_exit_UT_C0_delete_file_error_exception, test_processmanager_exit_UT_C0_exception
        - テスト定義:
                - テストカテゴリ: C0
                - テスト区分: 正常系/UT
                - テストシナリオ: ロック作成時にエラー OSErrorが発生する場合
        :
2024-01-21 22:47:45 [ERROR] common_utils - __enter__ line 80: already runnning: test_package:
2024-01-21 22:47:45 [DEBUG] common_utils - test_processmanager_enter_UT_C0_exception line 150: 
        - テスト関数: test_processmanager_UT_C0_normal, test_processmanager_enter_UT_C0_exception, test_processmanager_enter_UT_C0_oserror, test_processmanager_exit_UT_C0_delete_file_error_exception, test_processmanager_exit_UT_C0_exception
        - テスト定義:
                - テストカテゴリ: C0
                - テスト区分: 正常系/UT
                - テストシナリオ: ロック作成時にエラー Exceptionが発生する場合
        :
2024-01-21 22:47:45 [ERROR] common_utils - __enter__ line 83: Failed to multiprocess check: :
2024-01-21 22:47:45 [ERROR] common_utils - __enter__ line 85: Traceback (most recent call last):
  File "/developer/library_dev/project_1/src/lib/common_utils/ibr_multiprocess_lock.py", line 78, in __enter__
    fcntl.flock(self.lock_file.fileno(), fcntl.LOCK_EX | fcntl.LOCK_NB)
  File "/home/satoshi/.pyenv/versions/3.11.6/lib/python3.11/unittest/mock.py", line 1124, in __call__
    return self._mock_call(*args, **kwargs)
           ^^^^^^^^^^^^^^^^^^^^^^^^^^^^^^^^
  File "/home/satoshi/.pyenv/versions/3.11.6/lib/python3.11/unittest/mock.py", line 1128, in _mock_call
    return self._execute_mock_call(*args, **kwargs)
           ^^^^^^^^^^^^^^^^^^^^^^^^^^^^^^^^^^^^^^^^
  File "/home/satoshi/.pyenv/versions/3.11.6/lib/python3.11/unittest/mock.py", line 1187, in _execute_mock_call
    raise result
Exception
:
2024-01-21 22:47:45 [DEBUG] common_utils - test_processmanager_exit_UT_C0_exception line 183: 
        - テスト関数: test_processmanager_UT_C0_normal, test_processmanager_enter_UT_C0_exception, test_processmanager_enter_UT_C0_oserror, test_processmanager_exit_UT_C0_delete_file_error_exception, test_processmanager_exit_UT_C0_exception
        - テスト定義:
                - テストカテゴリ: C0
                - テスト区分: 正常系/UT
                - テストシナリオ: ロック開放時にエラー Exceptionが発生する場合
        :
2024-01-21 22:47:45 [ERROR] common_utils - __exit__ line 95: Failed to release lockfile: :
2024-01-21 22:47:45 [DEBUG] common_utils - test_processmanager_exit_UT_C0_delete_file_error_exception line 217: 
        - テスト関数: test_processmanager_UT_C0_normal, test_processmanager_enter_UT_C0_exception, test_processmanager_enter_UT_C0_oserror, test_processmanager_exit_UT_C0_delete_file_error_exception, test_processmanager_exit_UT_C0_exception
        - テスト定義:
                - テストカテゴリ: C0
                - テスト区分: 正常系/UT
                - テストシナリオ: ロック開放時にエラー Exceptionが発生する場合
        :
2024-01-21 23:07:33 [DEBUG] common_utils - <module> line 39: Config(env='local', common_config={'logger_path': {'LOGGER_DEF_FILE': 'tests/def/mfaUtilsLoggingHelper/logging_TimedRotate.json', 'LOGGER_MSG_FILE': 'tests/def/mfaUtilsLoggingHelper/config_MessageList.toml'}, 'input_file_path': {'UPDATE_EXCEL_PATH': 'tests/share/receive'}, 'output_file_path': {'SEND_REFFERENCE_MASTER_PATH': 'tests/share/receive'}}, package_config={'test': {'local_test': 'test'}}, log_message=<bound method LoggerPackage.log_message of <src.lib.common_utils.ibr_logger_package.LoggerPackage object at 0x7fce2de11a50>>):
2024-01-21 23:07:33 [DEBUG] common_utils - test_processmanager_UT_C0_normal line 79: 
        - テスト関数: test_processmanager_UT_C0_normal, test_processmanager_enter_UT_C0_exception, test_processmanager_enter_UT_C0_oserror, test_processmanager_exit_UT_C0_delete_file_error_exception, test_processmanager_exit_UT_C0_exception
        - テスト定義:
                - テストカテゴリ: C0
                - テスト区分: 正常系/UT
                - テストシナリオ:
                    with ProcessManager('test_package'): ステートメントを使用すると
                    ProcessManager クラスのインスタンスがコンテキストマネージャとして機能します。
                    Pythonのコンテキストマネージャは、with ステートメントのブロックに入る際に
                    __enter__ メソッドを呼び出し、ブロックを抜ける際に __exit__ メソッドを呼び出します。

                    このテストケースでは、ProcessManager の __enter__ メソッドが呼び出されると
                    fcntl.flock を使用してファイルロックを試みます。
                    これは、プロセスが排他的にリソースを使用することを保証するためです。
                    with ブロックを抜けると、ProcessManager の __exit__ メソッドが呼び出され
                    fcntl.flock を使用してファイルロックを解放します。

                    呼び出しの引数は、最初が (5, 6) で、2回目が (5, 8) です。
                    5 はファイル記述子
                    6 は fcntl.LOCK_EX | fcntl.LOCK_NB(排他的ロックを試みる)
                    8 は fcntl.LOCK_UN(ロックの解放)
                    を表しています。
        :
2024-01-21 23:07:33 [DEBUG] common_utils - test_processmanager_enter_UT_C0_oserror line 117: 
        - テスト関数: test_processmanager_UT_C0_normal, test_processmanager_enter_UT_C0_exception, test_processmanager_enter_UT_C0_oserror, test_processmanager_exit_UT_C0_delete_file_error_exception, test_processmanager_exit_UT_C0_exception
        - テスト定義:
                - テストカテゴリ: C0
                - テスト区分: 正常系/UT
                - テストシナリオ: ロック作成時にエラー OSErrorが発生する場合
        :
2024-01-21 23:07:33 [ERROR] common_utils - __enter__ line 80: already runnning: test_package:
2024-01-21 23:07:33 [DEBUG] common_utils - test_processmanager_enter_UT_C0_exception line 151: 
        - テスト関数: test_processmanager_UT_C0_normal, test_processmanager_enter_UT_C0_exception, test_processmanager_enter_UT_C0_oserror, test_processmanager_exit_UT_C0_delete_file_error_exception, test_processmanager_exit_UT_C0_exception
        - テスト定義:
                - テストカテゴリ: C0
                - テスト区分: 正常系/UT
                - テストシナリオ: ロック作成時にエラー Exceptionが発生する場合
        :
2024-01-21 23:07:33 [ERROR] common_utils - __enter__ line 83: Failed to multiprocess check: :
2024-01-21 23:07:33 [ERROR] common_utils - __enter__ line 85: Traceback (most recent call last):
  File "/developer/library_dev/project_1/src/lib/common_utils/ibr_multiprocess_lock.py", line 78, in __enter__
    fcntl.flock(self.lock_file.fileno(), fcntl.LOCK_EX | fcntl.LOCK_NB)
  File "/home/satoshi/.pyenv/versions/3.11.6/lib/python3.11/unittest/mock.py", line 1124, in __call__
    return self._mock_call(*args, **kwargs)
           ^^^^^^^^^^^^^^^^^^^^^^^^^^^^^^^^
  File "/home/satoshi/.pyenv/versions/3.11.6/lib/python3.11/unittest/mock.py", line 1128, in _mock_call
    return self._execute_mock_call(*args, **kwargs)
           ^^^^^^^^^^^^^^^^^^^^^^^^^^^^^^^^^^^^^^^^
  File "/home/satoshi/.pyenv/versions/3.11.6/lib/python3.11/unittest/mock.py", line 1187, in _execute_mock_call
    raise result
Exception
:
2024-01-21 23:07:33 [DEBUG] common_utils - test_processmanager_exit_UT_C0_exception line 184: 
        - テスト関数: test_processmanager_UT_C0_normal, test_processmanager_enter_UT_C0_exception, test_processmanager_enter_UT_C0_oserror, test_processmanager_exit_UT_C0_delete_file_error_exception, test_processmanager_exit_UT_C0_exception
        - テスト定義:
                - テストカテゴリ: C0
                - テスト区分: 正常系/UT
                - テストシナリオ: ロック開放時にエラー Exceptionが発生する場合
        :
2024-01-21 23:07:33 [ERROR] common_utils - __exit__ line 95: Failed to release lockfile: :
2024-01-21 23:07:33 [DEBUG] common_utils - test_processmanager_exit_UT_C0_delete_file_error_exception line 218: 
        - テスト関数: test_processmanager_UT_C0_normal, test_processmanager_enter_UT_C0_exception, test_processmanager_enter_UT_C0_oserror, test_processmanager_exit_UT_C0_delete_file_error_exception, test_processmanager_exit_UT_C0_exception
        - テスト定義:
                - テストカテゴリ: C0
                - テスト区分: 正常系/UT
                - テストシナリオ: ロック開放時にエラー Exceptionが発生する場合
        :
2024-01-21 23:08:02 [DEBUG] common_utils - <module> line 39: Config(env='local', common_config={'logger_path': {'LOGGER_DEF_FILE': 'tests/def/mfaUtilsLoggingHelper/logging_TimedRotate.json', 'LOGGER_MSG_FILE': 'tests/def/mfaUtilsLoggingHelper/config_MessageList.toml'}, 'input_file_path': {'UPDATE_EXCEL_PATH': 'tests/share/receive'}, 'output_file_path': {'SEND_REFFERENCE_MASTER_PATH': 'tests/share/receive'}}, package_config={'test': {'local_test': 'test'}}, log_message=<bound method LoggerPackage.log_message of <src.lib.common_utils.ibr_logger_package.LoggerPackage object at 0x7f84e5a4fc50>>):
2024-01-21 23:08:02 [DEBUG] common_utils - test_processmanager_UT_C0_normal line 79: 
        - テスト関数: test_processmanager_UT_C0_normal, test_processmanager_enter_UT_C0_exception, test_processmanager_enter_UT_C0_oserror, test_processmanager_exit_UT_C0_delete_file_error_exception, test_processmanager_exit_UT_C0_exception
        - テスト定義:
                - テストカテゴリ: C0
                - テスト区分: 正常系/UT
                - テストシナリオ:
                    with ProcessManager('test_package'): ステートメントを使用すると
                    ProcessManager クラスのインスタンスがコンテキストマネージャとして機能します。
                    Pythonのコンテキストマネージャは、with ステートメントのブロックに入る際に
                    __enter__ メソッドを呼び出し、ブロックを抜ける際に __exit__ メソッドを呼び出します。

                    このテストケースでは、ProcessManager の __enter__ メソッドが呼び出されると
                    fcntl.flock を使用してファイルロックを試みます。
                    これは、プロセスが排他的にリソースを使用することを保証するためです。
                    with ブロックを抜けると、ProcessManager の __exit__ メソッドが呼び出され
                    fcntl.flock を使用してファイルロックを解放します。

                    呼び出しの引数は、最初が (5, 6) で、2回目が (5, 8) です。
                    5 はファイル記述子
                    6 は fcntl.LOCK_EX | fcntl.LOCK_NB(排他的ロックを試みる)
                    8 は fcntl.LOCK_UN(ロックの解放)
                    を表しています。
        :
2024-01-21 23:08:02 [DEBUG] common_utils - test_processmanager_enter_UT_C0_oserror line 117: 
        - テスト関数: test_processmanager_UT_C0_normal, test_processmanager_enter_UT_C0_exception, test_processmanager_enter_UT_C0_oserror, test_processmanager_exit_UT_C0_delete_file_error_exception, test_processmanager_exit_UT_C0_exception
        - テスト定義:
                - テストカテゴリ: C0
                - テスト区分: 正常系/UT
                - テストシナリオ: ロック作成時にエラー OSErrorが発生する場合
        :
2024-01-21 23:08:02 [ERROR] common_utils - __enter__ line 80: already runnning: test_package:
2024-01-21 23:08:02 [DEBUG] common_utils - test_processmanager_enter_UT_C0_exception line 151: 
        - テスト関数: test_processmanager_UT_C0_normal, test_processmanager_enter_UT_C0_exception, test_processmanager_enter_UT_C0_oserror, test_processmanager_exit_UT_C0_delete_file_error_exception, test_processmanager_exit_UT_C0_exception
        - テスト定義:
                - テストカテゴリ: C0
                - テスト区分: 正常系/UT
                - テストシナリオ: ロック作成時にエラー Exceptionが発生する場合
        :
2024-01-21 23:08:02 [ERROR] common_utils - __enter__ line 83: Failed to multiprocess check: :
2024-01-21 23:08:02 [ERROR] common_utils - __enter__ line 85: Traceback (most recent call last):
  File "/developer/library_dev/project_1/src/lib/common_utils/ibr_multiprocess_lock.py", line 78, in __enter__
    fcntl.flock(self.lock_file.fileno(), fcntl.LOCK_EX | fcntl.LOCK_NB)
  File "/home/satoshi/.pyenv/versions/3.11.6/lib/python3.11/unittest/mock.py", line 1124, in __call__
    return self._mock_call(*args, **kwargs)
           ^^^^^^^^^^^^^^^^^^^^^^^^^^^^^^^^
  File "/home/satoshi/.pyenv/versions/3.11.6/lib/python3.11/unittest/mock.py", line 1128, in _mock_call
    return self._execute_mock_call(*args, **kwargs)
           ^^^^^^^^^^^^^^^^^^^^^^^^^^^^^^^^^^^^^^^^
  File "/home/satoshi/.pyenv/versions/3.11.6/lib/python3.11/unittest/mock.py", line 1187, in _execute_mock_call
    raise result
Exception
:
2024-01-21 23:08:02 [DEBUG] common_utils - test_processmanager_exit_UT_C0_exception line 184: 
        - テスト関数: test_processmanager_UT_C0_normal, test_processmanager_enter_UT_C0_exception, test_processmanager_enter_UT_C0_oserror, test_processmanager_exit_UT_C0_delete_file_error_exception, test_processmanager_exit_UT_C0_exception
        - テスト定義:
                - テストカテゴリ: C0
                - テスト区分: 正常系/UT
                - テストシナリオ: ロック開放時にエラー Exceptionが発生する場合
        :
2024-01-21 23:08:02 [ERROR] common_utils - __exit__ line 95: Failed to release lockfile: :
2024-01-21 23:08:02 [DEBUG] common_utils - test_processmanager_exit_UT_C0_delete_file_error_exception line 218: 
        - テスト関数: test_processmanager_UT_C0_normal, test_processmanager_enter_UT_C0_exception, test_processmanager_enter_UT_C0_oserror, test_processmanager_exit_UT_C0_delete_file_error_exception, test_processmanager_exit_UT_C0_exception
        - テスト定義:
                - テストカテゴリ: C0
                - テスト区分: 正常系/UT
                - テストシナリオ: ロック開放時にエラー Exceptionが発生する場合
        :
2024-01-21 23:08:18 [DEBUG] common_utils - <module> line 39: Config(env='local', common_config={'logger_path': {'LOGGER_DEF_FILE': 'tests/def/mfaUtilsLoggingHelper/logging_TimedRotate.json', 'LOGGER_MSG_FILE': 'tests/def/mfaUtilsLoggingHelper/config_MessageList.toml'}, 'input_file_path': {'UPDATE_EXCEL_PATH': 'tests/share/receive'}, 'output_file_path': {'SEND_REFFERENCE_MASTER_PATH': 'tests/share/receive'}}, package_config={'test': {'local_test': 'test'}}, log_message=<bound method LoggerPackage.log_message of <src.lib.common_utils.ibr_logger_package.LoggerPackage object at 0x7f97a0c04290>>):
2024-01-21 23:08:18 [DEBUG] common_utils - test_processmanager_UT_C0_normal line 79: 
        - テスト関数: test_processmanager_UT_C0_normal, test_processmanager_enter_UT_C0_exception, test_processmanager_enter_UT_C0_oserror, test_processmanager_exit_UT_C0_delete_file_error_exception, test_processmanager_exit_UT_C0_exception
        - テスト定義:
                - テストカテゴリ: C0
                - テスト区分: 正常系/UT
                - テストシナリオ:
                    with ProcessManager('test_package'): ステートメントを使用すると
                    ProcessManager クラスのインスタンスがコンテキストマネージャとして機能します。
                    Pythonのコンテキストマネージャは、with ステートメントのブロックに入る際に
                    __enter__ メソッドを呼び出し、ブロックを抜ける際に __exit__ メソッドを呼び出します。

                    このテストケースでは、ProcessManager の __enter__ メソッドが呼び出されると
                    fcntl.flock を使用してファイルロックを試みます。
                    これは、プロセスが排他的にリソースを使用することを保証するためです。
                    with ブロックを抜けると、ProcessManager の __exit__ メソッドが呼び出され
                    fcntl.flock を使用してファイルロックを解放します。

                    呼び出しの引数は、最初が (5, 6) で、2回目が (5, 8) です。
                    5 はファイル記述子
                    6 は fcntl.LOCK_EX | fcntl.LOCK_NB(排他的ロックを試みる)
                    8 は fcntl.LOCK_UN(ロックの解放)
                    を表しています。
        :
2024-01-21 23:08:18 [DEBUG] common_utils - test_processmanager_enter_UT_C0_oserror line 117: 
        - テスト関数: test_processmanager_UT_C0_normal, test_processmanager_enter_UT_C0_exception, test_processmanager_enter_UT_C0_oserror, test_processmanager_exit_UT_C0_delete_file_error_exception, test_processmanager_exit_UT_C0_exception
        - テスト定義:
                - テストカテゴリ: C0
                - テスト区分: 正常系/UT
                - テストシナリオ: ロック作成時にエラー OSErrorが発生する場合
        :
2024-01-21 23:08:18 [ERROR] common_utils - __enter__ line 80: already runnning: test_package:
2024-01-21 23:08:18 [DEBUG] common_utils - test_processmanager_enter_UT_C0_exception line 151: 
        - テスト関数: test_processmanager_UT_C0_normal, test_processmanager_enter_UT_C0_exception, test_processmanager_enter_UT_C0_oserror, test_processmanager_exit_UT_C0_delete_file_error_exception, test_processmanager_exit_UT_C0_exception
        - テスト定義:
                - テストカテゴリ: C0
                - テスト区分: 正常系/UT
                - テストシナリオ: ロック作成時にエラー Exceptionが発生する場合
        :
2024-01-21 23:08:18 [ERROR] common_utils - __enter__ line 83: Failed to multiprocess check: :
2024-01-21 23:08:18 [ERROR] common_utils - __enter__ line 85: Traceback (most recent call last):
  File "/developer/library_dev/project_1/src/lib/common_utils/ibr_multiprocess_lock.py", line 78, in __enter__
    fcntl.flock(self.lock_file.fileno(), fcntl.LOCK_EX | fcntl.LOCK_NB)
  File "/home/satoshi/.pyenv/versions/3.11.6/lib/python3.11/unittest/mock.py", line 1124, in __call__
    return self._mock_call(*args, **kwargs)
           ^^^^^^^^^^^^^^^^^^^^^^^^^^^^^^^^
  File "/home/satoshi/.pyenv/versions/3.11.6/lib/python3.11/unittest/mock.py", line 1128, in _mock_call
    return self._execute_mock_call(*args, **kwargs)
           ^^^^^^^^^^^^^^^^^^^^^^^^^^^^^^^^^^^^^^^^
  File "/home/satoshi/.pyenv/versions/3.11.6/lib/python3.11/unittest/mock.py", line 1187, in _execute_mock_call
    raise result
Exception
:
2024-01-21 23:08:18 [DEBUG] common_utils - test_processmanager_exit_UT_C0_exception line 184: 
        - テスト関数: test_processmanager_UT_C0_normal, test_processmanager_enter_UT_C0_exception, test_processmanager_enter_UT_C0_oserror, test_processmanager_exit_UT_C0_delete_file_error_exception, test_processmanager_exit_UT_C0_exception
        - テスト定義:
                - テストカテゴリ: C0
                - テスト区分: 正常系/UT
                - テストシナリオ: ロック開放時にエラー Exceptionが発生する場合
        :
2024-01-21 23:08:18 [ERROR] common_utils - __exit__ line 95: Failed to release lockfile: :
2024-01-21 23:08:18 [DEBUG] common_utils - test_processmanager_exit_UT_C0_delete_file_error_exception line 218: 
        - テスト関数: test_processmanager_UT_C0_normal, test_processmanager_enter_UT_C0_exception, test_processmanager_enter_UT_C0_oserror, test_processmanager_exit_UT_C0_delete_file_error_exception, test_processmanager_exit_UT_C0_exception
        - テスト定義:
                - テストカテゴリ: C0
                - テスト区分: 正常系/UT
                - テストシナリオ: ロック開放時にエラー Exceptionが発生する場合
        :
2024-01-21 23:09:10 [DEBUG] common_utils - <module> line 39: Config(env='local', common_config={'logger_path': {'LOGGER_DEF_FILE': 'tests/def/mfaUtilsLoggingHelper/logging_TimedRotate.json', 'LOGGER_MSG_FILE': 'tests/def/mfaUtilsLoggingHelper/config_MessageList.toml'}, 'input_file_path': {'UPDATE_EXCEL_PATH': 'tests/share/receive'}, 'output_file_path': {'SEND_REFFERENCE_MASTER_PATH': 'tests/share/receive'}}, package_config={'test': {'local_test': 'test'}}, log_message=<bound method LoggerPackage.log_message of <src.lib.common_utils.ibr_logger_package.LoggerPackage object at 0x7f3f241e7a50>>):
2024-01-21 23:09:10 [DEBUG] common_utils - test_processmanager_UT_C0_normal line 79: 
        - テスト関数: test_processmanager_UT_C0_normal, test_processmanager_enter_UT_C0_exception, test_processmanager_enter_UT_C0_oserror, test_processmanager_exit_UT_C0_delete_file_error_exception, test_processmanager_exit_UT_C0_exception
        - テスト定義:
                - テストカテゴリ: C0
                - テスト区分: 正常系/UT
                - テストシナリオ:
                    with ProcessManager('test_package'): ステートメントを使用すると
                    ProcessManager クラスのインスタンスがコンテキストマネージャとして機能します。
                    Pythonのコンテキストマネージャは、with ステートメントのブロックに入る際に
                    __enter__ メソッドを呼び出し、ブロックを抜ける際に __exit__ メソッドを呼び出します。

                    このテストケースでは、ProcessManager の __enter__ メソッドが呼び出されると
                    fcntl.flock を使用してファイルロックを試みます。
                    これは、プロセスが排他的にリソースを使用することを保証するためです。
                    with ブロックを抜けると、ProcessManager の __exit__ メソッドが呼び出され
                    fcntl.flock を使用してファイルロックを解放します。

                    呼び出しの引数は、最初が (5, 6) で、2回目が (5, 8) です。
                    5 はファイル記述子
                    6 は fcntl.LOCK_EX | fcntl.LOCK_NB(排他的ロックを試みる)
                    8 は fcntl.LOCK_UN(ロックの解放)
                    を表しています。
        :
2024-01-21 23:09:10 [DEBUG] common_utils - test_processmanager_enter_UT_C0_oserror line 117: 
        - テスト関数: test_processmanager_UT_C0_normal, test_processmanager_enter_UT_C0_exception, test_processmanager_enter_UT_C0_oserror, test_processmanager_exit_UT_C0_delete_file_error_exception, test_processmanager_exit_UT_C0_exception
        - テスト定義:
                - テストカテゴリ: C0
                - テスト区分: 正常系/UT
                - テストシナリオ: ロック作成時にエラー OSErrorが発生する場合
        :
2024-01-21 23:09:10 [ERROR] common_utils - __enter__ line 80: already runnning: test_package:
2024-01-21 23:09:10 [DEBUG] common_utils - test_processmanager_enter_UT_C0_exception line 151: 
        - テスト関数: test_processmanager_UT_C0_normal, test_processmanager_enter_UT_C0_exception, test_processmanager_enter_UT_C0_oserror, test_processmanager_exit_UT_C0_delete_file_error_exception, test_processmanager_exit_UT_C0_exception
        - テスト定義:
                - テストカテゴリ: C0
                - テスト区分: 正常系/UT
                - テストシナリオ: ロック作成時にエラー Exceptionが発生する場合
        :
2024-01-21 23:09:10 [ERROR] common_utils - __enter__ line 83: Failed to multiprocess check: :
2024-01-21 23:09:10 [ERROR] common_utils - __enter__ line 85: Traceback (most recent call last):
  File "/developer/library_dev/project_1/src/lib/common_utils/ibr_multiprocess_lock.py", line 78, in __enter__
    fcntl.flock(self.lock_file.fileno(), fcntl.LOCK_EX | fcntl.LOCK_NB)
  File "/home/satoshi/.pyenv/versions/3.11.6/lib/python3.11/unittest/mock.py", line 1124, in __call__
    return self._mock_call(*args, **kwargs)
           ^^^^^^^^^^^^^^^^^^^^^^^^^^^^^^^^
  File "/home/satoshi/.pyenv/versions/3.11.6/lib/python3.11/unittest/mock.py", line 1128, in _mock_call
    return self._execute_mock_call(*args, **kwargs)
           ^^^^^^^^^^^^^^^^^^^^^^^^^^^^^^^^^^^^^^^^
  File "/home/satoshi/.pyenv/versions/3.11.6/lib/python3.11/unittest/mock.py", line 1187, in _execute_mock_call
    raise result
Exception
:
2024-01-21 23:09:10 [DEBUG] common_utils - test_processmanager_exit_UT_C0_exception line 184: 
        - テスト関数: test_processmanager_UT_C0_normal, test_processmanager_enter_UT_C0_exception, test_processmanager_enter_UT_C0_oserror, test_processmanager_exit_UT_C0_delete_file_error_exception, test_processmanager_exit_UT_C0_exception
        - テスト定義:
                - テストカテゴリ: C0
                - テスト区分: 正常系/UT
                - テストシナリオ: ロック開放時にエラー Exceptionが発生する場合
        :
2024-01-21 23:09:10 [ERROR] common_utils - __exit__ line 95: Failed to release lockfile: :
2024-01-21 23:09:10 [DEBUG] common_utils - test_processmanager_exit_UT_C0_delete_file_error_exception line 218: 
        - テスト関数: test_processmanager_UT_C0_normal, test_processmanager_enter_UT_C0_exception, test_processmanager_enter_UT_C0_oserror, test_processmanager_exit_UT_C0_delete_file_error_exception, test_processmanager_exit_UT_C0_exception
        - テスト定義:
                - テストカテゴリ: C0
                - テスト区分: 正常系/UT
                - テストシナリオ: ロック開放時にエラー Exceptionが発生する場合
        :
2024-01-21 23:09:33 [DEBUG] common_utils - <module> line 39: Config(env='local', common_config={'logger_path': {'LOGGER_DEF_FILE': 'tests/def/mfaUtilsLoggingHelper/logging_TimedRotate.json', 'LOGGER_MSG_FILE': 'tests/def/mfaUtilsLoggingHelper/config_MessageList.toml'}, 'input_file_path': {'UPDATE_EXCEL_PATH': 'tests/share/receive'}, 'output_file_path': {'SEND_REFFERENCE_MASTER_PATH': 'tests/share/receive'}}, package_config={'test': {'local_test': 'test'}}, log_message=<bound method LoggerPackage.log_message of <src.lib.common_utils.ibr_logger_package.LoggerPackage object at 0x7fdb5e1086d0>>):
2024-01-21 23:09:33 [DEBUG] common_utils - test_processmanager_UT_C0_normal line 79: 
        - テスト関数: test_processmanager_UT_C0_normal, test_processmanager_enter_UT_C0_exception, test_processmanager_enter_UT_C0_oserror, test_processmanager_exit_UT_C0_delete_file_error_exception, test_processmanager_exit_UT_C0_exception
        - テスト定義:
                - テストカテゴリ: C0
                - テスト区分: 正常系/UT
                - テストシナリオ:
                    with ProcessManager('test_package'): ステートメントを使用すると
                    ProcessManager クラスのインスタンスがコンテキストマネージャとして機能します。
                    Pythonのコンテキストマネージャは、with ステートメントのブロックに入る際に
                    __enter__ メソッドを呼び出し、ブロックを抜ける際に __exit__ メソッドを呼び出します。

                    このテストケースでは、ProcessManager の __enter__ メソッドが呼び出されると
                    fcntl.flock を使用してファイルロックを試みます。
                    これは、プロセスが排他的にリソースを使用することを保証するためです。
                    with ブロックを抜けると、ProcessManager の __exit__ メソッドが呼び出され
                    fcntl.flock を使用してファイルロックを解放します。

                    呼び出しの引数は、最初が (5, 6) で、2回目が (5, 8) です。
                    5 はファイル記述子
                    6 は fcntl.LOCK_EX | fcntl.LOCK_NB(排他的ロックを試みる)
                    8 は fcntl.LOCK_UN(ロックの解放)
                    を表しています。
        :
2024-01-21 23:09:33 [DEBUG] common_utils - test_processmanager_enter_UT_C0_oserror line 117: 
        - テスト関数: test_processmanager_UT_C0_normal, test_processmanager_enter_UT_C0_exception, test_processmanager_enter_UT_C0_oserror, test_processmanager_exit_UT_C0_delete_file_error_exception, test_processmanager_exit_UT_C0_exception
        - テスト定義:
                - テストカテゴリ: C0
                - テスト区分: 正常系/UT
                - テストシナリオ: ロック作成時にエラー OSErrorが発生する場合
        :
2024-01-21 23:09:33 [ERROR] common_utils - __enter__ line 80: already runnning: test_package:
2024-01-21 23:09:33 [DEBUG] common_utils - test_processmanager_enter_UT_C0_exception line 151: 
        - テスト関数: test_processmanager_UT_C0_normal, test_processmanager_enter_UT_C0_exception, test_processmanager_enter_UT_C0_oserror, test_processmanager_exit_UT_C0_delete_file_error_exception, test_processmanager_exit_UT_C0_exception
        - テスト定義:
                - テストカテゴリ: C0
                - テスト区分: 正常系/UT
                - テストシナリオ: ロック作成時にエラー Exceptionが発生する場合
        :
2024-01-21 23:09:33 [ERROR] common_utils - __enter__ line 83: Failed to multiprocess check: :
2024-01-21 23:09:33 [ERROR] common_utils - __enter__ line 85: Traceback (most recent call last):
  File "/developer/library_dev/project_1/src/lib/common_utils/ibr_multiprocess_lock.py", line 78, in __enter__
    fcntl.flock(self.lock_file.fileno(), fcntl.LOCK_EX | fcntl.LOCK_NB)
  File "/home/satoshi/.pyenv/versions/3.11.6/lib/python3.11/unittest/mock.py", line 1124, in __call__
    return self._mock_call(*args, **kwargs)
           ^^^^^^^^^^^^^^^^^^^^^^^^^^^^^^^^
  File "/home/satoshi/.pyenv/versions/3.11.6/lib/python3.11/unittest/mock.py", line 1128, in _mock_call
    return self._execute_mock_call(*args, **kwargs)
           ^^^^^^^^^^^^^^^^^^^^^^^^^^^^^^^^^^^^^^^^
  File "/home/satoshi/.pyenv/versions/3.11.6/lib/python3.11/unittest/mock.py", line 1187, in _execute_mock_call
    raise result
Exception
:
2024-01-21 23:09:33 [DEBUG] common_utils - test_processmanager_exit_UT_C0_exception line 184: 
        - テスト関数: test_processmanager_UT_C0_normal, test_processmanager_enter_UT_C0_exception, test_processmanager_enter_UT_C0_oserror, test_processmanager_exit_UT_C0_delete_file_error_exception, test_processmanager_exit_UT_C0_exception
        - テスト定義:
                - テストカテゴリ: C0
                - テスト区分: 正常系/UT
                - テストシナリオ: ロック開放時にエラー Exceptionが発生する場合
        :
2024-01-21 23:09:33 [ERROR] common_utils - __exit__ line 95: Failed to release lockfile: :
2024-01-21 23:09:33 [DEBUG] common_utils - test_processmanager_exit_UT_C0_delete_file_error_exception line 218: 
        - テスト関数: test_processmanager_UT_C0_normal, test_processmanager_enter_UT_C0_exception, test_processmanager_enter_UT_C0_oserror, test_processmanager_exit_UT_C0_delete_file_error_exception, test_processmanager_exit_UT_C0_exception
        - テスト定義:
                - テストカテゴリ: C0
                - テスト区分: 正常系/UT
                - テストシナリオ: ロック開放時にエラー Exceptionが発生する場合
        :
2024-01-21 23:16:28 [DEBUG] common_utils - <module> line 39: Config(env='local', common_config={'logger_path': {'LOGGER_DEF_FILE': 'tests/def/mfaUtilsLoggingHelper/logging_TimedRotate.json', 'LOGGER_MSG_FILE': 'tests/def/mfaUtilsLoggingHelper/config_MessageList.toml'}, 'input_file_path': {'UPDATE_EXCEL_PATH': 'tests/share/receive'}, 'output_file_path': {'SEND_REFFERENCE_MASTER_PATH': 'tests/share/receive'}}, package_config={'test': {'local_test': 'test'}}, log_message=<bound method LoggerPackage.log_message of <src.lib.common_utils.ibr_logger_package.LoggerPackage object at 0x7f1f58e3e110>>):
2024-01-21 23:16:28 [DEBUG] common_utils - test_processmanager_UT_C0_normal line 79: 
        - テスト関数: test_processmanager_UT_C0_normal, test_processmanager_enter_UT_C0_exception, test_processmanager_enter_UT_C0_oserror, test_processmanager_exit_UT_C0_delete_file_error_exception, test_processmanager_exit_UT_C0_exception
        - テスト定義:
                - テストカテゴリ: C0
                - テスト区分: 正常系/UT
                - テストシナリオ:
                    with ProcessManager('test_package'): ステートメントを使用すると
                    ProcessManager クラスのインスタンスがコンテキストマネージャとして機能します。
                    Pythonのコンテキストマネージャは、with ステートメントのブロックに入る際に
                    __enter__ メソッドを呼び出し、ブロックを抜ける際に __exit__ メソッドを呼び出します。

                    このテストケースでは、ProcessManager の __enter__ メソッドが呼び出されると
                    fcntl.flock を使用してファイルロックを試みます。
                    これは、プロセスが排他的にリソースを使用することを保証するためです。
                    with ブロックを抜けると、ProcessManager の __exit__ メソッドが呼び出され
                    fcntl.flock を使用してファイルロックを解放します。

                    呼び出しの引数は、最初が (5, 6) で、2回目が (5, 8) です。
                    5 はファイル記述子
                    6 は fcntl.LOCK_EX | fcntl.LOCK_NB(排他的ロックを試みる)
                    8 は fcntl.LOCK_UN(ロックの解放)
                    を表しています。
        :
2024-01-21 23:16:28 [DEBUG] common_utils - test_processmanager_enter_UT_C0_oserror line 117: 
        - テスト関数: test_processmanager_UT_C0_normal, test_processmanager_enter_UT_C0_exception, test_processmanager_enter_UT_C0_oserror, test_processmanager_exit_UT_C0_delete_file_error_exception, test_processmanager_exit_UT_C0_exception
        - テスト定義:
                - テストカテゴリ: C0
                - テスト区分: 正常系/UT
                - テストシナリオ: ロック作成時にエラー OSErrorが発生する場合
        :
2024-01-21 23:16:28 [ERROR] common_utils - __enter__ line 80: already runnning: test_package:
2024-01-21 23:16:28 [DEBUG] common_utils - test_processmanager_enter_UT_C0_exception line 151: 
        - テスト関数: test_processmanager_UT_C0_normal, test_processmanager_enter_UT_C0_exception, test_processmanager_enter_UT_C0_oserror, test_processmanager_exit_UT_C0_delete_file_error_exception, test_processmanager_exit_UT_C0_exception
        - テスト定義:
                - テストカテゴリ: C0
                - テスト区分: 正常系/UT
                - テストシナリオ: ロック作成時にエラー Exceptionが発生する場合
        :
2024-01-21 23:16:28 [ERROR] common_utils - __enter__ line 83: Failed to multiprocess check: :
2024-01-21 23:16:28 [ERROR] common_utils - __enter__ line 85: Traceback (most recent call last):
  File "/developer/library_dev/project_1/src/lib/common_utils/ibr_multiprocess_lock.py", line 78, in __enter__
    fcntl.flock(self.lock_file.fileno(), fcntl.LOCK_EX | fcntl.LOCK_NB)
  File "/home/satoshi/.pyenv/versions/3.11.6/lib/python3.11/unittest/mock.py", line 1124, in __call__
    return self._mock_call(*args, **kwargs)
           ^^^^^^^^^^^^^^^^^^^^^^^^^^^^^^^^
  File "/home/satoshi/.pyenv/versions/3.11.6/lib/python3.11/unittest/mock.py", line 1128, in _mock_call
    return self._execute_mock_call(*args, **kwargs)
           ^^^^^^^^^^^^^^^^^^^^^^^^^^^^^^^^^^^^^^^^
  File "/home/satoshi/.pyenv/versions/3.11.6/lib/python3.11/unittest/mock.py", line 1187, in _execute_mock_call
    raise result
Exception
:
2024-01-21 23:16:28 [DEBUG] common_utils - test_processmanager_exit_UT_C0_exception line 184: 
        - テスト関数: test_processmanager_UT_C0_normal, test_processmanager_enter_UT_C0_exception, test_processmanager_enter_UT_C0_oserror, test_processmanager_exit_UT_C0_delete_file_error_exception, test_processmanager_exit_UT_C0_exception
        - テスト定義:
                - テストカテゴリ: C0
                - テスト区分: 正常系/UT
                - テストシナリオ: ロック開放時にエラー Exceptionが発生する場合
        :
2024-01-21 23:16:28 [ERROR] common_utils - __exit__ line 95: Failed to release lockfile: :
2024-01-21 23:16:28 [DEBUG] common_utils - test_processmanager_exit_UT_C0_delete_file_error_exception line 218: 
        - テスト関数: test_processmanager_UT_C0_normal, test_processmanager_enter_UT_C0_exception, test_processmanager_enter_UT_C0_oserror, test_processmanager_exit_UT_C0_delete_file_error_exception, test_processmanager_exit_UT_C0_exception
        - テスト定義:
                - テストカテゴリ: C0
                - テスト区分: 正常系/UT
                - テストシナリオ: ロック開放時にエラー Exceptionが発生する場合
        :
2024-01-21 23:19:51 [DEBUG] common_utils - <module> line 39: Config(env='local', common_config={'logger_path': {'LOGGER_DEF_FILE': 'tests/def/mfaUtilsLoggingHelper/logging_TimedRotate.json', 'LOGGER_MSG_FILE': 'tests/def/mfaUtilsLoggingHelper/config_MessageList.toml'}, 'input_file_path': {'UPDATE_EXCEL_PATH': 'tests/share/receive'}, 'output_file_path': {'SEND_REFFERENCE_MASTER_PATH': 'tests/share/receive'}}, package_config={'test': {'local_test': 'test'}}, log_message=<bound method LoggerPackage.log_message of <src.lib.common_utils.ibr_logger_package.LoggerPackage object at 0x7f5e38f8ba50>>):
2024-01-21 23:19:51 [DEBUG] common_utils - test_processmanager_UT_C0_normal line 79: 
        - テスト関数: test_processmanager_UT_C0_normal, test_processmanager_enter_UT_C0_exception, test_processmanager_enter_UT_C0_oserror, test_processmanager_exit_UT_C0_delete_file_error_exception, test_processmanager_exit_UT_C0_exception
        - テスト定義:
                - テストカテゴリ: C0
                - テスト区分: 正常系/UT
                - テストシナリオ:
                    with ProcessManager('test_package'): ステートメントを使用すると
                    ProcessManager クラスのインスタンスがコンテキストマネージャとして機能します。
                    Pythonのコンテキストマネージャは、with ステートメントのブロックに入る際に
                    __enter__ メソッドを呼び出し、ブロックを抜ける際に __exit__ メソッドを呼び出します。

                    このテストケースでは、ProcessManager の __enter__ メソッドが呼び出されると
                    fcntl.flock を使用してファイルロックを試みます。
                    これは、プロセスが排他的にリソースを使用することを保証するためです。
                    with ブロックを抜けると、ProcessManager の __exit__ メソッドが呼び出され
                    fcntl.flock を使用してファイルロックを解放します。

                    呼び出しの引数は、最初が (5, 6) で、2回目が (5, 8) です。
                    5 はファイル記述子
                    6 は fcntl.LOCK_EX | fcntl.LOCK_NB(排他的ロックを試みる)
                    8 は fcntl.LOCK_UN(ロックの解放)
                    を表しています。
        :
2024-01-21 23:19:51 [DEBUG] common_utils - test_processmanager_enter_UT_C0_oserror line 117: 
        - テスト関数: test_processmanager_UT_C0_normal, test_processmanager_enter_UT_C0_exception, test_processmanager_enter_UT_C0_oserror, test_processmanager_exit_UT_C0_delete_file_error_exception, test_processmanager_exit_UT_C0_exception
        - テスト定義:
                - テストカテゴリ: C0
                - テスト区分: 正常系/UT
                - テストシナリオ: ロック作成時にエラー OSErrorが発生する場合
        :
2024-01-21 23:19:51 [ERROR] common_utils - __enter__ line 80: already runnning: test_package:
2024-01-21 23:19:51 [DEBUG] common_utils - test_processmanager_enter_UT_C0_exception line 151: 
        - テスト関数: test_processmanager_UT_C0_normal, test_processmanager_enter_UT_C0_exception, test_processmanager_enter_UT_C0_oserror, test_processmanager_exit_UT_C0_delete_file_error_exception, test_processmanager_exit_UT_C0_exception
        - テスト定義:
                - テストカテゴリ: C0
                - テスト区分: 正常系/UT
                - テストシナリオ: ロック作成時にエラー Exceptionが発生する場合
        :
2024-01-21 23:19:51 [ERROR] common_utils - __enter__ line 83: Failed to multiprocess check: :
2024-01-21 23:19:51 [ERROR] common_utils - __enter__ line 85: Traceback (most recent call last):
  File "/developer/library_dev/project_1/src/lib/common_utils/ibr_multiprocess_lock.py", line 78, in __enter__
    fcntl.flock(self.lock_file.fileno(), fcntl.LOCK_EX | fcntl.LOCK_NB)
  File "/home/satoshi/.pyenv/versions/3.11.6/lib/python3.11/unittest/mock.py", line 1124, in __call__
    return self._mock_call(*args, **kwargs)
           ^^^^^^^^^^^^^^^^^^^^^^^^^^^^^^^^
  File "/home/satoshi/.pyenv/versions/3.11.6/lib/python3.11/unittest/mock.py", line 1128, in _mock_call
    return self._execute_mock_call(*args, **kwargs)
           ^^^^^^^^^^^^^^^^^^^^^^^^^^^^^^^^^^^^^^^^
  File "/home/satoshi/.pyenv/versions/3.11.6/lib/python3.11/unittest/mock.py", line 1187, in _execute_mock_call
    raise result
Exception
:
2024-01-21 23:19:51 [DEBUG] common_utils - test_processmanager_exit_UT_C0_exception line 184: 
        - テスト関数: test_processmanager_UT_C0_normal, test_processmanager_enter_UT_C0_exception, test_processmanager_enter_UT_C0_oserror, test_processmanager_exit_UT_C0_delete_file_error_exception, test_processmanager_exit_UT_C0_exception
        - テスト定義:
                - テストカテゴリ: C0
                - テスト区分: 正常系/UT
                - テストシナリオ: ロック開放時にエラー Exceptionが発生する場合
        :
2024-01-21 23:19:51 [ERROR] common_utils - __exit__ line 95: Failed to release lockfile: :
2024-01-21 23:19:51 [DEBUG] common_utils - test_processmanager_exit_UT_C0_delete_file_error_exception line 218: 
        - テスト関数: test_processmanager_UT_C0_normal, test_processmanager_enter_UT_C0_exception, test_processmanager_enter_UT_C0_oserror, test_processmanager_exit_UT_C0_delete_file_error_exception, test_processmanager_exit_UT_C0_exception
        - テスト定義:
                - テストカテゴリ: C0
                - テスト区分: 正常系/UT
                - テストシナリオ: ロック開放時にエラー Exceptionが発生する場合
        :
2024-01-21 23:19:51 [ERROR] common_utils - __exit__ line 95: Failed to release lockfile: :
2024-01-21 23:20:51 [DEBUG] common_utils - <module> line 39: Config(env='local', common_config={'logger_path': {'LOGGER_DEF_FILE': 'tests/def/mfaUtilsLoggingHelper/logging_TimedRotate.json', 'LOGGER_MSG_FILE': 'tests/def/mfaUtilsLoggingHelper/config_MessageList.toml'}, 'input_file_path': {'UPDATE_EXCEL_PATH': 'tests/share/receive'}, 'output_file_path': {'SEND_REFFERENCE_MASTER_PATH': 'tests/share/receive'}}, package_config={'test': {'local_test': 'test'}}, log_message=<bound method LoggerPackage.log_message of <src.lib.common_utils.ibr_logger_package.LoggerPackage object at 0x7fea96305a50>>):
2024-01-21 23:20:51 [DEBUG] common_utils - test_processmanager_UT_C0_normal line 79: 
        - テスト関数: test_processmanager_UT_C0_normal, test_processmanager_enter_UT_C0_exception, test_processmanager_enter_UT_C0_oserror, test_processmanager_exit_UT_C0_delete_file_error_exception, test_processmanager_exit_UT_C0_exception
        - テスト定義:
                - テストカテゴリ: C0
                - テスト区分: 正常系/UT
                - テストシナリオ:
                    with ProcessManager('test_package'): ステートメントを使用すると
                    ProcessManager クラスのインスタンスがコンテキストマネージャとして機能します。
                    Pythonのコンテキストマネージャは、with ステートメントのブロックに入る際に
                    __enter__ メソッドを呼び出し、ブロックを抜ける際に __exit__ メソッドを呼び出します。

                    このテストケースでは、ProcessManager の __enter__ メソッドが呼び出されると
                    fcntl.flock を使用してファイルロックを試みます。
                    これは、プロセスが排他的にリソースを使用することを保証するためです。
                    with ブロックを抜けると、ProcessManager の __exit__ メソッドが呼び出され
                    fcntl.flock を使用してファイルロックを解放します。

                    呼び出しの引数は、最初が (5, 6) で、2回目が (5, 8) です。
                    5 はファイル記述子
                    6 は fcntl.LOCK_EX | fcntl.LOCK_NB(排他的ロックを試みる)
                    8 は fcntl.LOCK_UN(ロックの解放)
                    を表しています。
        :
2024-01-21 23:20:51 [DEBUG] common_utils - test_processmanager_enter_UT_C0_oserror line 117: 
        - テスト関数: test_processmanager_UT_C0_normal, test_processmanager_enter_UT_C0_exception, test_processmanager_enter_UT_C0_oserror, test_processmanager_exit_UT_C0_delete_file_error_exception, test_processmanager_exit_UT_C0_exception
        - テスト定義:
                - テストカテゴリ: C0
                - テスト区分: 正常系/UT
                - テストシナリオ: ロック作成時にエラー OSErrorが発生する場合
        :
2024-01-21 23:20:51 [ERROR] common_utils - __enter__ line 80: already runnning: test_package:
2024-01-21 23:20:51 [DEBUG] common_utils - test_processmanager_enter_UT_C0_exception line 151: 
        - テスト関数: test_processmanager_UT_C0_normal, test_processmanager_enter_UT_C0_exception, test_processmanager_enter_UT_C0_oserror, test_processmanager_exit_UT_C0_delete_file_error_exception, test_processmanager_exit_UT_C0_exception
        - テスト定義:
                - テストカテゴリ: C0
                - テスト区分: 正常系/UT
                - テストシナリオ: ロック作成時にエラー Exceptionが発生する場合
        :
2024-01-21 23:20:51 [ERROR] common_utils - __enter__ line 83: Failed to multiprocess check: :
2024-01-21 23:20:51 [ERROR] common_utils - __enter__ line 85: Traceback (most recent call last):
  File "/developer/library_dev/project_1/src/lib/common_utils/ibr_multiprocess_lock.py", line 78, in __enter__
    fcntl.flock(self.lock_file.fileno(), fcntl.LOCK_EX | fcntl.LOCK_NB)
  File "/home/satoshi/.pyenv/versions/3.11.6/lib/python3.11/unittest/mock.py", line 1124, in __call__
    return self._mock_call(*args, **kwargs)
           ^^^^^^^^^^^^^^^^^^^^^^^^^^^^^^^^
  File "/home/satoshi/.pyenv/versions/3.11.6/lib/python3.11/unittest/mock.py", line 1128, in _mock_call
    return self._execute_mock_call(*args, **kwargs)
           ^^^^^^^^^^^^^^^^^^^^^^^^^^^^^^^^^^^^^^^^
  File "/home/satoshi/.pyenv/versions/3.11.6/lib/python3.11/unittest/mock.py", line 1187, in _execute_mock_call
    raise result
Exception
:
2024-01-21 23:20:51 [DEBUG] common_utils - test_processmanager_exit_UT_C0_exception line 184: 
        - テスト関数: test_processmanager_UT_C0_normal, test_processmanager_enter_UT_C0_exception, test_processmanager_enter_UT_C0_oserror, test_processmanager_exit_UT_C0_delete_file_error_exception, test_processmanager_exit_UT_C0_exception
        - テスト定義:
                - テストカテゴリ: C0
                - テスト区分: 正常系/UT
                - テストシナリオ: ロック開放時にエラー Exceptionが発生する場合
        :
2024-01-21 23:20:51 [ERROR] common_utils - __exit__ line 94: Failed to release lockfile: :
2024-01-21 23:20:51 [DEBUG] common_utils - test_processmanager_exit_UT_C0_delete_file_error_exception line 218: 
        - テスト関数: test_processmanager_UT_C0_normal, test_processmanager_enter_UT_C0_exception, test_processmanager_enter_UT_C0_oserror, test_processmanager_exit_UT_C0_delete_file_error_exception, test_processmanager_exit_UT_C0_exception
        - テスト定義:
                - テストカテゴリ: C0
                - テスト区分: 正常系/UT
                - テストシナリオ: ロック開放時にエラー Exceptionが発生する場合
        :
2024-01-21 23:20:51 [ERROR] common_utils - __exit__ line 101: Failed to unlink lockfile: :
2024-01-21 23:21:08 [DEBUG] common_utils - <module> line 39: Config(env='local', common_config={'logger_path': {'LOGGER_DEF_FILE': 'tests/def/mfaUtilsLoggingHelper/logging_TimedRotate.json', 'LOGGER_MSG_FILE': 'tests/def/mfaUtilsLoggingHelper/config_MessageList.toml'}, 'input_file_path': {'UPDATE_EXCEL_PATH': 'tests/share/receive'}, 'output_file_path': {'SEND_REFFERENCE_MASTER_PATH': 'tests/share/receive'}}, package_config={'test': {'local_test': 'test'}}, log_message=<bound method LoggerPackage.log_message of <src.lib.common_utils.ibr_logger_package.LoggerPackage object at 0x7f8d16e20790>>):
2024-01-21 23:21:08 [DEBUG] common_utils - test_processmanager_UT_C0_normal line 79: 
        - テスト関数: test_processmanager_UT_C0_normal, test_processmanager_enter_UT_C0_exception, test_processmanager_enter_UT_C0_oserror, test_processmanager_exit_UT_C0_delete_file_error_exception, test_processmanager_exit_UT_C0_exception
        - テスト定義:
                - テストカテゴリ: C0
                - テスト区分: 正常系/UT
                - テストシナリオ:
                    with ProcessManager('test_package'): ステートメントを使用すると
                    ProcessManager クラスのインスタンスがコンテキストマネージャとして機能します。
                    Pythonのコンテキストマネージャは、with ステートメントのブロックに入る際に
                    __enter__ メソッドを呼び出し、ブロックを抜ける際に __exit__ メソッドを呼び出します。

                    このテストケースでは、ProcessManager の __enter__ メソッドが呼び出されると
                    fcntl.flock を使用してファイルロックを試みます。
                    これは、プロセスが排他的にリソースを使用することを保証するためです。
                    with ブロックを抜けると、ProcessManager の __exit__ メソッドが呼び出され
                    fcntl.flock を使用してファイルロックを解放します。

                    呼び出しの引数は、最初が (5, 6) で、2回目が (5, 8) です。
                    5 はファイル記述子
                    6 は fcntl.LOCK_EX | fcntl.LOCK_NB(排他的ロックを試みる)
                    8 は fcntl.LOCK_UN(ロックの解放)
                    を表しています。
        :
2024-01-21 23:21:08 [DEBUG] common_utils - test_processmanager_enter_UT_C0_oserror line 117: 
        - テスト関数: test_processmanager_UT_C0_normal, test_processmanager_enter_UT_C0_exception, test_processmanager_enter_UT_C0_oserror, test_processmanager_exit_UT_C0_delete_file_error_exception, test_processmanager_exit_UT_C0_exception
        - テスト定義:
                - テストカテゴリ: C0
                - テスト区分: 正常系/UT
                - テストシナリオ: ロック作成時にエラー OSErrorが発生する場合
        :
2024-01-21 23:21:08 [ERROR] common_utils - __enter__ line 80: already runnning: test_package:
2024-01-21 23:21:08 [DEBUG] common_utils - test_processmanager_enter_UT_C0_exception line 151: 
        - テスト関数: test_processmanager_UT_C0_normal, test_processmanager_enter_UT_C0_exception, test_processmanager_enter_UT_C0_oserror, test_processmanager_exit_UT_C0_delete_file_error_exception, test_processmanager_exit_UT_C0_exception
        - テスト定義:
                - テストカテゴリ: C0
                - テスト区分: 正常系/UT
                - テストシナリオ: ロック作成時にエラー Exceptionが発生する場合
        :
2024-01-21 23:21:08 [ERROR] common_utils - __enter__ line 83: Failed to multiprocess check: :
2024-01-21 23:21:08 [ERROR] common_utils - __enter__ line 85: Traceback (most recent call last):
  File "/developer/library_dev/project_1/src/lib/common_utils/ibr_multiprocess_lock.py", line 78, in __enter__
    fcntl.flock(self.lock_file.fileno(), fcntl.LOCK_EX | fcntl.LOCK_NB)
  File "/home/satoshi/.pyenv/versions/3.11.6/lib/python3.11/unittest/mock.py", line 1124, in __call__
    return self._mock_call(*args, **kwargs)
           ^^^^^^^^^^^^^^^^^^^^^^^^^^^^^^^^
  File "/home/satoshi/.pyenv/versions/3.11.6/lib/python3.11/unittest/mock.py", line 1128, in _mock_call
    return self._execute_mock_call(*args, **kwargs)
           ^^^^^^^^^^^^^^^^^^^^^^^^^^^^^^^^^^^^^^^^
  File "/home/satoshi/.pyenv/versions/3.11.6/lib/python3.11/unittest/mock.py", line 1187, in _execute_mock_call
    raise result
Exception
:
2024-01-21 23:21:08 [DEBUG] common_utils - test_processmanager_exit_UT_C0_exception line 184: 
        - テスト関数: test_processmanager_UT_C0_normal, test_processmanager_enter_UT_C0_exception, test_processmanager_enter_UT_C0_oserror, test_processmanager_exit_UT_C0_delete_file_error_exception, test_processmanager_exit_UT_C0_exception
        - テスト定義:
                - テストカテゴリ: C0
                - テスト区分: 正常系/UT
                - テストシナリオ: ロック開放時にエラー Exceptionが発生する場合
        :
2024-01-21 23:21:08 [ERROR] common_utils - __exit__ line 94: Failed to release lockfile: :
2024-01-21 23:21:08 [DEBUG] common_utils - test_processmanager_exit_UT_C0_delete_file_error_exception line 218: 
        - テスト関数: test_processmanager_UT_C0_normal, test_processmanager_enter_UT_C0_exception, test_processmanager_enter_UT_C0_oserror, test_processmanager_exit_UT_C0_delete_file_error_exception, test_processmanager_exit_UT_C0_exception
        - テスト定義:
                - テストカテゴリ: C0
                - テスト区分: 正常系/UT
                - テストシナリオ: ロック開放時にエラー Exceptionが発生する場合
        :
2024-01-21 23:21:08 [ERROR] common_utils - __exit__ line 101: Failed to unlink lockfile: :
2024-01-21 23:22:40 [DEBUG] common_utils - <module> line 39: Config(env='local', common_config={'logger_path': {'LOGGER_DEF_FILE': 'tests/def/mfaUtilsLoggingHelper/logging_TimedRotate.json', 'LOGGER_MSG_FILE': 'tests/def/mfaUtilsLoggingHelper/config_MessageList.toml'}, 'input_file_path': {'UPDATE_EXCEL_PATH': 'tests/share/receive'}, 'output_file_path': {'SEND_REFFERENCE_MASTER_PATH': 'tests/share/receive'}}, package_config={'test': {'local_test': 'test'}}, log_message=<bound method LoggerPackage.log_message of <src.lib.common_utils.ibr_logger_package.LoggerPackage object at 0x7f3bdda24b10>>):
2024-01-21 23:22:40 [DEBUG] common_utils - test_processmanager_UT_C0_normal line 79: 
        - テスト関数: test_mutex_manager_UT_C0_normal_multiprocess, test_processmanager_UT_C0_normal, test_processmanager_enter_UT_C0_exception, test_processmanager_enter_UT_C0_oserror, test_processmanager_exit_UT_C0_delete_file_error_exception, test_processmanager_exit_UT_C0_exception
        - テスト定義:
                - テストカテゴリ: C0
                - テスト区分: 正常系/UT
                - テストシナリオ:
                    with ProcessManager('test_package'): ステートメントを使用すると
                    ProcessManager クラスのインスタンスがコンテキストマネージャとして機能します。
                    Pythonのコンテキストマネージャは、with ステートメントのブロックに入る際に
                    __enter__ メソッドを呼び出し、ブロックを抜ける際に __exit__ メソッドを呼び出します。

                    このテストケースでは、ProcessManager の __enter__ メソッドが呼び出されると
                    fcntl.flock を使用してファイルロックを試みます。
                    これは、プロセスが排他的にリソースを使用することを保証するためです。
                    with ブロックを抜けると、ProcessManager の __exit__ メソッドが呼び出され
                    fcntl.flock を使用してファイルロックを解放します。

                    呼び出しの引数は、最初が (5, 6) で、2回目が (5, 8) です。
                    5 はファイル記述子
                    6 は fcntl.LOCK_EX | fcntl.LOCK_NB(排他的ロックを試みる)
                    8 は fcntl.LOCK_UN(ロックの解放)
                    を表しています。
        :
2024-01-21 23:22:40 [DEBUG] common_utils - test_processmanager_enter_UT_C0_oserror line 117: 
        - テスト関数: test_mutex_manager_UT_C0_normal_multiprocess, test_processmanager_UT_C0_normal, test_processmanager_enter_UT_C0_exception, test_processmanager_enter_UT_C0_oserror, test_processmanager_exit_UT_C0_delete_file_error_exception, test_processmanager_exit_UT_C0_exception
        - テスト定義:
                - テストカテゴリ: C0
                - テスト区分: 正常系/UT
                - テストシナリオ: ロック作成時にエラー OSErrorが発生する場合
        :
2024-01-21 23:22:40 [ERROR] common_utils - __enter__ line 80: already runnning: test_package:
2024-01-21 23:22:40 [DEBUG] common_utils - test_processmanager_enter_UT_C0_exception line 151: 
        - テスト関数: test_mutex_manager_UT_C0_normal_multiprocess, test_processmanager_UT_C0_normal, test_processmanager_enter_UT_C0_exception, test_processmanager_enter_UT_C0_oserror, test_processmanager_exit_UT_C0_delete_file_error_exception, test_processmanager_exit_UT_C0_exception
        - テスト定義:
                - テストカテゴリ: C0
                - テスト区分: 正常系/UT
                - テストシナリオ: ロック作成時にエラー Exceptionが発生する場合
        :
2024-01-21 23:22:40 [ERROR] common_utils - __enter__ line 83: Failed to multiprocess check: :
2024-01-21 23:22:40 [ERROR] common_utils - __enter__ line 85: Traceback (most recent call last):
  File "/developer/library_dev/project_1/src/lib/common_utils/ibr_multiprocess_lock.py", line 78, in __enter__
    fcntl.flock(self.lock_file.fileno(), fcntl.LOCK_EX | fcntl.LOCK_NB)
  File "/home/satoshi/.pyenv/versions/3.11.6/lib/python3.11/unittest/mock.py", line 1124, in __call__
    return self._mock_call(*args, **kwargs)
           ^^^^^^^^^^^^^^^^^^^^^^^^^^^^^^^^
  File "/home/satoshi/.pyenv/versions/3.11.6/lib/python3.11/unittest/mock.py", line 1128, in _mock_call
    return self._execute_mock_call(*args, **kwargs)
           ^^^^^^^^^^^^^^^^^^^^^^^^^^^^^^^^^^^^^^^^
  File "/home/satoshi/.pyenv/versions/3.11.6/lib/python3.11/unittest/mock.py", line 1187, in _execute_mock_call
    raise result
Exception
:
2024-01-21 23:22:40 [DEBUG] common_utils - test_processmanager_exit_UT_C0_exception line 184: 
        - テスト関数: test_mutex_manager_UT_C0_normal_multiprocess, test_processmanager_UT_C0_normal, test_processmanager_enter_UT_C0_exception, test_processmanager_enter_UT_C0_oserror, test_processmanager_exit_UT_C0_delete_file_error_exception, test_processmanager_exit_UT_C0_exception
        - テスト定義:
                - テストカテゴリ: C0
                - テスト区分: 正常系/UT
                - テストシナリオ: ロック開放時にエラー Exceptionが発生する場合
        :
2024-01-21 23:22:40 [ERROR] common_utils - __exit__ line 94: Failed to release lockfile: :
2024-01-21 23:22:40 [DEBUG] common_utils - test_processmanager_exit_UT_C0_delete_file_error_exception line 218: 
        - テスト関数: test_mutex_manager_UT_C0_normal_multiprocess, test_processmanager_UT_C0_normal, test_processmanager_enter_UT_C0_exception, test_processmanager_enter_UT_C0_oserror, test_processmanager_exit_UT_C0_delete_file_error_exception, test_processmanager_exit_UT_C0_exception
        - テスト定義:
                - テストカテゴリ: C0
                - テスト区分: 正常系/UT
                - テストシナリオ: ロック開放時にエラー Exceptionが発生する場合
        :
2024-01-21 23:22:40 [ERROR] common_utils - __exit__ line 101: Failed to unlink lockfile: :
2024-01-21 23:22:40 [DEBUG] common_utils - test_mutex_manager_UT_C0_normal_multiprocess line 248: 
        - テスト関数: test_mutex_manager_UT_C0_normal_multiprocess, test_processmanager_UT_C0_normal, test_processmanager_enter_UT_C0_exception, test_processmanager_enter_UT_C0_oserror, test_processmanager_exit_UT_C0_delete_file_error_exception, test_processmanager_exit_UT_C0_exception
        - テスト定義:
                - テストカテゴリ: C0
                - テスト区分: 正常系/UT
                - テストシナリオ:
        :
2024-01-21 23:22:50 [DEBUG] common_utils - <module> line 39: Config(env='local', common_config={'logger_path': {'LOGGER_DEF_FILE': 'tests/def/mfaUtilsLoggingHelper/logging_TimedRotate.json', 'LOGGER_MSG_FILE': 'tests/def/mfaUtilsLoggingHelper/config_MessageList.toml'}, 'input_file_path': {'UPDATE_EXCEL_PATH': 'tests/share/receive'}, 'output_file_path': {'SEND_REFFERENCE_MASTER_PATH': 'tests/share/receive'}}, package_config={'test': {'local_test': 'test'}}, log_message=<bound method LoggerPackage.log_message of <src.lib.common_utils.ibr_logger_package.LoggerPackage object at 0x7f0714fca810>>):
2024-01-21 23:22:50 [DEBUG] common_utils - test_processmanager_UT_C0_normal line 79: 
        - テスト関数: test_mutex_manager_UT_C0_normal_multiprocess, test_processmanager_UT_C0_normal, test_processmanager_enter_UT_C0_exception, test_processmanager_enter_UT_C0_oserror, test_processmanager_exit_UT_C0_delete_file_error_exception, test_processmanager_exit_UT_C0_exception
        - テスト定義:
                - テストカテゴリ: C0
                - テスト区分: 正常系/UT
                - テストシナリオ:
                    with ProcessManager('test_package'): ステートメントを使用すると
                    ProcessManager クラスのインスタンスがコンテキストマネージャとして機能します。
                    Pythonのコンテキストマネージャは、with ステートメントのブロックに入る際に
                    __enter__ メソッドを呼び出し、ブロックを抜ける際に __exit__ メソッドを呼び出します。

                    このテストケースでは、ProcessManager の __enter__ メソッドが呼び出されると
                    fcntl.flock を使用してファイルロックを試みます。
                    これは、プロセスが排他的にリソースを使用することを保証するためです。
                    with ブロックを抜けると、ProcessManager の __exit__ メソッドが呼び出され
                    fcntl.flock を使用してファイルロックを解放します。

                    呼び出しの引数は、最初が (5, 6) で、2回目が (5, 8) です。
                    5 はファイル記述子
                    6 は fcntl.LOCK_EX | fcntl.LOCK_NB(排他的ロックを試みる)
                    8 は fcntl.LOCK_UN(ロックの解放)
                    を表しています。
        :
2024-01-21 23:22:50 [DEBUG] common_utils - test_processmanager_enter_UT_C0_oserror line 117: 
        - テスト関数: test_mutex_manager_UT_C0_normal_multiprocess, test_processmanager_UT_C0_normal, test_processmanager_enter_UT_C0_exception, test_processmanager_enter_UT_C0_oserror, test_processmanager_exit_UT_C0_delete_file_error_exception, test_processmanager_exit_UT_C0_exception
        - テスト定義:
                - テストカテゴリ: C0
                - テスト区分: 正常系/UT
                - テストシナリオ: ロック作成時にエラー OSErrorが発生する場合
        :
2024-01-21 23:22:50 [ERROR] common_utils - __enter__ line 80: already runnning: test_package:
2024-01-21 23:22:50 [DEBUG] common_utils - test_processmanager_enter_UT_C0_exception line 151: 
        - テスト関数: test_mutex_manager_UT_C0_normal_multiprocess, test_processmanager_UT_C0_normal, test_processmanager_enter_UT_C0_exception, test_processmanager_enter_UT_C0_oserror, test_processmanager_exit_UT_C0_delete_file_error_exception, test_processmanager_exit_UT_C0_exception
        - テスト定義:
                - テストカテゴリ: C0
                - テスト区分: 正常系/UT
                - テストシナリオ: ロック作成時にエラー Exceptionが発生する場合
        :
2024-01-21 23:22:50 [ERROR] common_utils - __enter__ line 83: Failed to multiprocess check: :
2024-01-21 23:22:50 [ERROR] common_utils - __enter__ line 85: Traceback (most recent call last):
  File "/developer/library_dev/project_1/src/lib/common_utils/ibr_multiprocess_lock.py", line 78, in __enter__
    fcntl.flock(self.lock_file.fileno(), fcntl.LOCK_EX | fcntl.LOCK_NB)
  File "/home/satoshi/.pyenv/versions/3.11.6/lib/python3.11/unittest/mock.py", line 1124, in __call__
    return self._mock_call(*args, **kwargs)
           ^^^^^^^^^^^^^^^^^^^^^^^^^^^^^^^^
  File "/home/satoshi/.pyenv/versions/3.11.6/lib/python3.11/unittest/mock.py", line 1128, in _mock_call
    return self._execute_mock_call(*args, **kwargs)
           ^^^^^^^^^^^^^^^^^^^^^^^^^^^^^^^^^^^^^^^^
  File "/home/satoshi/.pyenv/versions/3.11.6/lib/python3.11/unittest/mock.py", line 1187, in _execute_mock_call
    raise result
Exception
:
2024-01-21 23:22:50 [DEBUG] common_utils - test_processmanager_exit_UT_C0_exception line 184: 
        - テスト関数: test_mutex_manager_UT_C0_normal_multiprocess, test_processmanager_UT_C0_normal, test_processmanager_enter_UT_C0_exception, test_processmanager_enter_UT_C0_oserror, test_processmanager_exit_UT_C0_delete_file_error_exception, test_processmanager_exit_UT_C0_exception
        - テスト定義:
                - テストカテゴリ: C0
                - テスト区分: 正常系/UT
                - テストシナリオ: ロック開放時にエラー Exceptionが発生する場合
        :
2024-01-21 23:22:50 [ERROR] common_utils - __exit__ line 94: Failed to release lockfile: :
2024-01-21 23:22:50 [DEBUG] common_utils - test_processmanager_exit_UT_C0_delete_file_error_exception line 218: 
        - テスト関数: test_mutex_manager_UT_C0_normal_multiprocess, test_processmanager_UT_C0_normal, test_processmanager_enter_UT_C0_exception, test_processmanager_enter_UT_C0_oserror, test_processmanager_exit_UT_C0_delete_file_error_exception, test_processmanager_exit_UT_C0_exception
        - テスト定義:
                - テストカテゴリ: C0
                - テスト区分: 正常系/UT
                - テストシナリオ: ロック開放時にエラー Exceptionが発生する場合
        :
2024-01-21 23:22:50 [ERROR] common_utils - __exit__ line 101: Failed to unlink lockfile: :
2024-01-21 23:22:50 [DEBUG] common_utils - test_mutex_manager_UT_C0_normal_multiprocess line 248: 
        - テスト関数: test_mutex_manager_UT_C0_normal_multiprocess, test_processmanager_UT_C0_normal, test_processmanager_enter_UT_C0_exception, test_processmanager_enter_UT_C0_oserror, test_processmanager_exit_UT_C0_delete_file_error_exception, test_processmanager_exit_UT_C0_exception
        - テスト定義:
                - テストカテゴリ: C0
                - テスト区分: 正常系/UT
                - テストシナリオ:
        :
2024-01-21 23:22:59 [DEBUG] common_utils - <module> line 39: Config(env='local', common_config={'logger_path': {'LOGGER_DEF_FILE': 'tests/def/mfaUtilsLoggingHelper/logging_TimedRotate.json', 'LOGGER_MSG_FILE': 'tests/def/mfaUtilsLoggingHelper/config_MessageList.toml'}, 'input_file_path': {'UPDATE_EXCEL_PATH': 'tests/share/receive'}, 'output_file_path': {'SEND_REFFERENCE_MASTER_PATH': 'tests/share/receive'}}, package_config={'test': {'local_test': 'test'}}, log_message=<bound method LoggerPackage.log_message of <src.lib.common_utils.ibr_logger_package.LoggerPackage object at 0x7f54496f8750>>):
2024-01-21 23:22:59 [DEBUG] common_utils - test_processmanager_UT_C0_normal line 79: 
        - テスト関数: test_mutex_manager_UT_C0_normal_multiprocess, test_processmanager_UT_C0_normal, test_processmanager_enter_UT_C0_exception, test_processmanager_enter_UT_C0_oserror, test_processmanager_exit_UT_C0_delete_file_error_exception, test_processmanager_exit_UT_C0_exception
        - テスト定義:
                - テストカテゴリ: C0
                - テスト区分: 正常系/UT
                - テストシナリオ:
                    with ProcessManager('test_package'): ステートメントを使用すると
                    ProcessManager クラスのインスタンスがコンテキストマネージャとして機能します。
                    Pythonのコンテキストマネージャは、with ステートメントのブロックに入る際に
                    __enter__ メソッドを呼び出し、ブロックを抜ける際に __exit__ メソッドを呼び出します。

                    このテストケースでは、ProcessManager の __enter__ メソッドが呼び出されると
                    fcntl.flock を使用してファイルロックを試みます。
                    これは、プロセスが排他的にリソースを使用することを保証するためです。
                    with ブロックを抜けると、ProcessManager の __exit__ メソッドが呼び出され
                    fcntl.flock を使用してファイルロックを解放します。

                    呼び出しの引数は、最初が (5, 6) で、2回目が (5, 8) です。
                    5 はファイル記述子
                    6 は fcntl.LOCK_EX | fcntl.LOCK_NB(排他的ロックを試みる)
                    8 は fcntl.LOCK_UN(ロックの解放)
                    を表しています。
        :
2024-01-21 23:22:59 [DEBUG] common_utils - test_processmanager_enter_UT_C0_oserror line 117: 
        - テスト関数: test_mutex_manager_UT_C0_normal_multiprocess, test_processmanager_UT_C0_normal, test_processmanager_enter_UT_C0_exception, test_processmanager_enter_UT_C0_oserror, test_processmanager_exit_UT_C0_delete_file_error_exception, test_processmanager_exit_UT_C0_exception
        - テスト定義:
                - テストカテゴリ: C0
                - テスト区分: 正常系/UT
                - テストシナリオ: ロック作成時にエラー OSErrorが発生する場合
        :
2024-01-21 23:22:59 [ERROR] common_utils - __enter__ line 80: already runnning: test_package:
2024-01-21 23:22:59 [DEBUG] common_utils - test_processmanager_enter_UT_C0_exception line 151: 
        - テスト関数: test_mutex_manager_UT_C0_normal_multiprocess, test_processmanager_UT_C0_normal, test_processmanager_enter_UT_C0_exception, test_processmanager_enter_UT_C0_oserror, test_processmanager_exit_UT_C0_delete_file_error_exception, test_processmanager_exit_UT_C0_exception
        - テスト定義:
                - テストカテゴリ: C0
                - テスト区分: 正常系/UT
                - テストシナリオ: ロック作成時にエラー Exceptionが発生する場合
        :
2024-01-21 23:22:59 [ERROR] common_utils - __enter__ line 83: Failed to multiprocess check: :
2024-01-21 23:22:59 [ERROR] common_utils - __enter__ line 85: Traceback (most recent call last):
  File "/developer/library_dev/project_1/src/lib/common_utils/ibr_multiprocess_lock.py", line 78, in __enter__
    fcntl.flock(self.lock_file.fileno(), fcntl.LOCK_EX | fcntl.LOCK_NB)
  File "/home/satoshi/.pyenv/versions/3.11.6/lib/python3.11/unittest/mock.py", line 1124, in __call__
    return self._mock_call(*args, **kwargs)
           ^^^^^^^^^^^^^^^^^^^^^^^^^^^^^^^^
  File "/home/satoshi/.pyenv/versions/3.11.6/lib/python3.11/unittest/mock.py", line 1128, in _mock_call
    return self._execute_mock_call(*args, **kwargs)
           ^^^^^^^^^^^^^^^^^^^^^^^^^^^^^^^^^^^^^^^^
  File "/home/satoshi/.pyenv/versions/3.11.6/lib/python3.11/unittest/mock.py", line 1187, in _execute_mock_call
    raise result
Exception
:
2024-01-21 23:22:59 [DEBUG] common_utils - test_processmanager_exit_UT_C0_exception line 184: 
        - テスト関数: test_mutex_manager_UT_C0_normal_multiprocess, test_processmanager_UT_C0_normal, test_processmanager_enter_UT_C0_exception, test_processmanager_enter_UT_C0_oserror, test_processmanager_exit_UT_C0_delete_file_error_exception, test_processmanager_exit_UT_C0_exception
        - テスト定義:
                - テストカテゴリ: C0
                - テスト区分: 正常系/UT
                - テストシナリオ: ロック開放時にエラー Exceptionが発生する場合
        :
2024-01-21 23:22:59 [ERROR] common_utils - __exit__ line 94: Failed to release lockfile: :
2024-01-21 23:22:59 [DEBUG] common_utils - test_processmanager_exit_UT_C0_delete_file_error_exception line 218: 
        - テスト関数: test_mutex_manager_UT_C0_normal_multiprocess, test_processmanager_UT_C0_normal, test_processmanager_enter_UT_C0_exception, test_processmanager_enter_UT_C0_oserror, test_processmanager_exit_UT_C0_delete_file_error_exception, test_processmanager_exit_UT_C0_exception
        - テスト定義:
                - テストカテゴリ: C0
                - テスト区分: 正常系/UT
                - テストシナリオ: ロック開放時にエラー Exceptionが発生する場合
        :
2024-01-21 23:22:59 [ERROR] common_utils - __exit__ line 101: Failed to unlink lockfile: :
2024-01-21 23:22:59 [DEBUG] common_utils - test_mutex_manager_UT_C0_normal_multiprocess line 248: 
        - テスト関数: test_mutex_manager_UT_C0_normal_multiprocess, test_processmanager_UT_C0_normal, test_processmanager_enter_UT_C0_exception, test_processmanager_enter_UT_C0_oserror, test_processmanager_exit_UT_C0_delete_file_error_exception, test_processmanager_exit_UT_C0_exception
        - テスト定義:
                - テストカテゴリ: C0
                - テスト区分: 正常系/UT
                - テストシナリオ:
        :
2024-01-21 23:27:17 [DEBUG] common_utils - <module> line 39: Config(env='local', common_config={'logger_path': {'LOGGER_DEF_FILE': 'tests/def/mfaUtilsLoggingHelper/logging_TimedRotate.json', 'LOGGER_MSG_FILE': 'tests/def/mfaUtilsLoggingHelper/config_MessageList.toml'}, 'input_file_path': {'UPDATE_EXCEL_PATH': 'tests/share/receive'}, 'output_file_path': {'SEND_REFFERENCE_MASTER_PATH': 'tests/share/receive'}}, package_config={'test': {'local_test': 'test'}}, log_message=<bound method LoggerPackage.log_message of <src.lib.common_utils.ibr_logger_package.LoggerPackage object at 0x7fecaa494a90>>):
2024-01-21 23:27:17 [DEBUG] common_utils - test_processmanager_UT_C0_normal line 88: 
        - テスト関数: test_mutex_manager_UT_C0_normal_multiprocess, test_processmanager_UT_C0_normal, test_processmanager_enter_UT_C0_exception, test_processmanager_enter_UT_C0_oserror, test_processmanager_exit_UT_C0_delete_file_error_exception, test_processmanager_exit_UT_C0_exception
        - テスト定義:
                - テストカテゴリ: C0
                - テスト区分: 正常系/UT
                - テストシナリオ:
                    with ProcessManager('test_package'): ステートメントを使用すると
                    ProcessManager クラスのインスタンスがコンテキストマネージャとして機能します。
                    Pythonのコンテキストマネージャは、with ステートメントのブロックに入る際に
                    __enter__ メソッドを呼び出し、ブロックを抜ける際に __exit__ メソッドを呼び出します。

                    このテストケースでは、ProcessManager の __enter__ メソッドが呼び出されると
                    fcntl.flock を使用してファイルロックを試みます。
                    これは、プロセスが排他的にリソースを使用することを保証するためです。
                    with ブロックを抜けると、ProcessManager の __exit__ メソッドが呼び出され
                    fcntl.flock を使用してファイルロックを解放します。

                    呼び出しの引数は、最初が (5, 6) で、2回目が (5, 8) です。
                    5 はファイル記述子
                    6 は fcntl.LOCK_EX | fcntl.LOCK_NB(排他的ロックを試みる)
                    8 は fcntl.LOCK_UN(ロックの解放)
                    を表しています。
        :
2024-01-21 23:27:17 [DEBUG] common_utils - test_processmanager_enter_UT_C0_oserror line 126: 
        - テスト関数: test_mutex_manager_UT_C0_normal_multiprocess, test_processmanager_UT_C0_normal, test_processmanager_enter_UT_C0_exception, test_processmanager_enter_UT_C0_oserror, test_processmanager_exit_UT_C0_delete_file_error_exception, test_processmanager_exit_UT_C0_exception
        - テスト定義:
                - テストカテゴリ: C0
                - テスト区分: 正常系/UT
                - テストシナリオ: ロック作成時にエラー OSErrorが発生する場合
        :
2024-01-21 23:27:17 [ERROR] common_utils - __enter__ line 80: already runnning: test_package:
2024-01-21 23:27:17 [DEBUG] common_utils - test_processmanager_enter_UT_C0_exception line 160: 
        - テスト関数: test_mutex_manager_UT_C0_normal_multiprocess, test_processmanager_UT_C0_normal, test_processmanager_enter_UT_C0_exception, test_processmanager_enter_UT_C0_oserror, test_processmanager_exit_UT_C0_delete_file_error_exception, test_processmanager_exit_UT_C0_exception
        - テスト定義:
                - テストカテゴリ: C0
                - テスト区分: 正常系/UT
                - テストシナリオ: ロック作成時にエラー Exceptionが発生する場合
        :
2024-01-21 23:27:17 [ERROR] common_utils - __enter__ line 83: Failed to multiprocess check: :
2024-01-21 23:27:17 [ERROR] common_utils - __enter__ line 85: Traceback (most recent call last):
  File "/developer/library_dev/project_1/src/lib/common_utils/ibr_multiprocess_lock.py", line 78, in __enter__
    fcntl.flock(self.lock_file.fileno(), fcntl.LOCK_EX | fcntl.LOCK_NB)
  File "/home/satoshi/.pyenv/versions/3.11.6/lib/python3.11/unittest/mock.py", line 1124, in __call__
    return self._mock_call(*args, **kwargs)
           ^^^^^^^^^^^^^^^^^^^^^^^^^^^^^^^^
  File "/home/satoshi/.pyenv/versions/3.11.6/lib/python3.11/unittest/mock.py", line 1128, in _mock_call
    return self._execute_mock_call(*args, **kwargs)
           ^^^^^^^^^^^^^^^^^^^^^^^^^^^^^^^^^^^^^^^^
  File "/home/satoshi/.pyenv/versions/3.11.6/lib/python3.11/unittest/mock.py", line 1187, in _execute_mock_call
    raise result
Exception
:
2024-01-21 23:27:17 [DEBUG] common_utils - test_processmanager_exit_UT_C0_exception line 193: 
        - テスト関数: test_mutex_manager_UT_C0_normal_multiprocess, test_processmanager_UT_C0_normal, test_processmanager_enter_UT_C0_exception, test_processmanager_enter_UT_C0_oserror, test_processmanager_exit_UT_C0_delete_file_error_exception, test_processmanager_exit_UT_C0_exception
        - テスト定義:
                - テストカテゴリ: C0
                - テスト区分: 正常系/UT
                - テストシナリオ: ロック開放時にエラー Exceptionが発生する場合
        :
2024-01-21 23:27:17 [ERROR] common_utils - __exit__ line 94: Failed to release lockfile: :
2024-01-21 23:27:17 [DEBUG] common_utils - test_processmanager_exit_UT_C0_delete_file_error_exception line 227: 
        - テスト関数: test_mutex_manager_UT_C0_normal_multiprocess, test_processmanager_UT_C0_normal, test_processmanager_enter_UT_C0_exception, test_processmanager_enter_UT_C0_oserror, test_processmanager_exit_UT_C0_delete_file_error_exception, test_processmanager_exit_UT_C0_exception
        - テスト定義:
                - テストカテゴリ: C0
                - テスト区分: 正常系/UT
                - テストシナリオ: ロック開放時にエラー Exceptionが発生する場合
        :
2024-01-21 23:27:17 [ERROR] common_utils - __exit__ line 101: Failed to unlink lockfile: :
2024-01-21 23:27:17 [DEBUG] common_utils - test_mutex_manager_UT_C0_normal_multiprocess line 257: 
        - テスト関数: test_mutex_manager_UT_C0_normal_multiprocess, test_processmanager_UT_C0_normal, test_processmanager_enter_UT_C0_exception, test_processmanager_enter_UT_C0_oserror, test_processmanager_exit_UT_C0_delete_file_error_exception, test_processmanager_exit_UT_C0_exception
        - テスト定義:
                - テストカテゴリ: C0
                - テスト区分: 正常系/UT
                - テストシナリオ:
        :
2024-01-21 23:28:03 [DEBUG] common_utils - <module> line 39: Config(env='local', common_config={'logger_path': {'LOGGER_DEF_FILE': 'tests/def/mfaUtilsLoggingHelper/logging_TimedRotate.json', 'LOGGER_MSG_FILE': 'tests/def/mfaUtilsLoggingHelper/config_MessageList.toml'}, 'input_file_path': {'UPDATE_EXCEL_PATH': 'tests/share/receive'}, 'output_file_path': {'SEND_REFFERENCE_MASTER_PATH': 'tests/share/receive'}}, package_config={'test': {'local_test': 'test'}}, log_message=<bound method LoggerPackage.log_message of <src.lib.common_utils.ibr_logger_package.LoggerPackage object at 0x7f2c9528fbd0>>):
2024-01-21 23:28:03 [DEBUG] common_utils - test_processmanager_UT_C0_normal line 88: 
        - テスト関数: test_mutex_manager_UT_C0_normal_multiprocess, test_processmanager_UT_C0_normal, test_processmanager_enter_UT_C0_exception, test_processmanager_enter_UT_C0_oserror, test_processmanager_exit_UT_C0_delete_file_error_exception, test_processmanager_exit_UT_C0_exception
        - テスト定義:
                - テストカテゴリ: C0
                - テスト区分: 正常系/UT
                - テストシナリオ:
                    with ProcessManager('test_package'): ステートメントを使用すると
                    ProcessManager クラスのインスタンスがコンテキストマネージャとして機能します。
                    Pythonのコンテキストマネージャは、with ステートメントのブロックに入る際に
                    __enter__ メソッドを呼び出し、ブロックを抜ける際に __exit__ メソッドを呼び出します。

                    このテストケースでは、ProcessManager の __enter__ メソッドが呼び出されると
                    fcntl.flock を使用してファイルロックを試みます。
                    これは、プロセスが排他的にリソースを使用することを保証するためです。
                    with ブロックを抜けると、ProcessManager の __exit__ メソッドが呼び出され
                    fcntl.flock を使用してファイルロックを解放します。

                    呼び出しの引数は、最初が (5, 6) で、2回目が (5, 8) です。
                    5 はファイル記述子
                    6 は fcntl.LOCK_EX | fcntl.LOCK_NB(排他的ロックを試みる)
                    8 は fcntl.LOCK_UN(ロックの解放)
                    を表しています。
        :
2024-01-21 23:28:03 [DEBUG] common_utils - test_processmanager_enter_UT_C0_oserror line 126: 
        - テスト関数: test_mutex_manager_UT_C0_normal_multiprocess, test_processmanager_UT_C0_normal, test_processmanager_enter_UT_C0_exception, test_processmanager_enter_UT_C0_oserror, test_processmanager_exit_UT_C0_delete_file_error_exception, test_processmanager_exit_UT_C0_exception
        - テスト定義:
                - テストカテゴリ: C0
                - テスト区分: 正常系/UT
                - テストシナリオ: ロック作成時にエラー OSErrorが発生する場合
        :
2024-01-21 23:28:03 [ERROR] common_utils - __enter__ line 80: already runnning: test_package:
2024-01-21 23:28:03 [DEBUG] common_utils - test_processmanager_enter_UT_C0_exception line 160: 
        - テスト関数: test_mutex_manager_UT_C0_normal_multiprocess, test_processmanager_UT_C0_normal, test_processmanager_enter_UT_C0_exception, test_processmanager_enter_UT_C0_oserror, test_processmanager_exit_UT_C0_delete_file_error_exception, test_processmanager_exit_UT_C0_exception
        - テスト定義:
                - テストカテゴリ: C0
                - テスト区分: 正常系/UT
                - テストシナリオ: ロック作成時にエラー Exceptionが発生する場合
        :
2024-01-21 23:28:03 [ERROR] common_utils - __enter__ line 83: Failed to multiprocess check: :
2024-01-21 23:28:03 [ERROR] common_utils - __enter__ line 85: Traceback (most recent call last):
  File "/developer/library_dev/project_1/src/lib/common_utils/ibr_multiprocess_lock.py", line 78, in __enter__
    fcntl.flock(self.lock_file.fileno(), fcntl.LOCK_EX | fcntl.LOCK_NB)
  File "/home/satoshi/.pyenv/versions/3.11.6/lib/python3.11/unittest/mock.py", line 1124, in __call__
    return self._mock_call(*args, **kwargs)
           ^^^^^^^^^^^^^^^^^^^^^^^^^^^^^^^^
  File "/home/satoshi/.pyenv/versions/3.11.6/lib/python3.11/unittest/mock.py", line 1128, in _mock_call
    return self._execute_mock_call(*args, **kwargs)
           ^^^^^^^^^^^^^^^^^^^^^^^^^^^^^^^^^^^^^^^^
  File "/home/satoshi/.pyenv/versions/3.11.6/lib/python3.11/unittest/mock.py", line 1187, in _execute_mock_call
    raise result
Exception
:
2024-01-21 23:28:03 [DEBUG] common_utils - test_processmanager_exit_UT_C0_exception line 193: 
        - テスト関数: test_mutex_manager_UT_C0_normal_multiprocess, test_processmanager_UT_C0_normal, test_processmanager_enter_UT_C0_exception, test_processmanager_enter_UT_C0_oserror, test_processmanager_exit_UT_C0_delete_file_error_exception, test_processmanager_exit_UT_C0_exception
        - テスト定義:
                - テストカテゴリ: C0
                - テスト区分: 正常系/UT
                - テストシナリオ: ロック開放時にエラー Exceptionが発生する場合
        :
2024-01-21 23:28:03 [ERROR] common_utils - __exit__ line 94: Failed to release lockfile: :
2024-01-21 23:28:03 [DEBUG] common_utils - test_processmanager_exit_UT_C0_delete_file_error_exception line 227: 
        - テスト関数: test_mutex_manager_UT_C0_normal_multiprocess, test_processmanager_UT_C0_normal, test_processmanager_enter_UT_C0_exception, test_processmanager_enter_UT_C0_oserror, test_processmanager_exit_UT_C0_delete_file_error_exception, test_processmanager_exit_UT_C0_exception
        - テスト定義:
                - テストカテゴリ: C0
                - テスト区分: 正常系/UT
                - テストシナリオ: ロック開放時にエラー Exceptionが発生する場合
        :
2024-01-21 23:28:03 [ERROR] common_utils - __exit__ line 101: Failed to unlink lockfile: :
2024-01-21 23:28:03 [DEBUG] common_utils - test_mutex_manager_UT_C0_normal_multiprocess line 257: 
        - テスト関数: test_mutex_manager_UT_C0_normal_multiprocess, test_processmanager_UT_C0_normal, test_processmanager_enter_UT_C0_exception, test_processmanager_enter_UT_C0_oserror, test_processmanager_exit_UT_C0_delete_file_error_exception, test_processmanager_exit_UT_C0_exception
        - テスト定義:
                - テストカテゴリ: C0
                - テスト区分: 正常系/UT
                - テストシナリオ:
        :
2024-01-21 23:28:46 [DEBUG] common_utils - <module> line 39: Config(env='local', common_config={'logger_path': {'LOGGER_DEF_FILE': 'tests/def/mfaUtilsLoggingHelper/logging_TimedRotate.json', 'LOGGER_MSG_FILE': 'tests/def/mfaUtilsLoggingHelper/config_MessageList.toml'}, 'input_file_path': {'UPDATE_EXCEL_PATH': 'tests/share/receive'}, 'output_file_path': {'SEND_REFFERENCE_MASTER_PATH': 'tests/share/receive'}}, package_config={'test': {'local_test': 'test'}}, log_message=<bound method LoggerPackage.log_message of <src.lib.common_utils.ibr_logger_package.LoggerPackage object at 0x7f95e4ef8a90>>):
2024-01-21 23:28:46 [DEBUG] common_utils - test_processmanager_UT_C0_normal line 88: 
        - テスト関数: test_mutex_manager_UT_C0_normal_multiprocess, test_processmanager_UT_C0_normal, test_processmanager_enter_UT_C0_exception, test_processmanager_enter_UT_C0_oserror, test_processmanager_exit_UT_C0_delete_file_error_exception, test_processmanager_exit_UT_C0_exception
        - テスト定義:
                - テストカテゴリ: C0
                - テスト区分: 正常系/UT
                - テストシナリオ:
                    with ProcessManager('test_package'): ステートメントを使用すると
                    ProcessManager クラスのインスタンスがコンテキストマネージャとして機能します。
                    Pythonのコンテキストマネージャは、with ステートメントのブロックに入る際に
                    __enter__ メソッドを呼び出し、ブロックを抜ける際に __exit__ メソッドを呼び出します。

                    このテストケースでは、ProcessManager の __enter__ メソッドが呼び出されると
                    fcntl.flock を使用してファイルロックを試みます。
                    これは、プロセスが排他的にリソースを使用することを保証するためです。
                    with ブロックを抜けると、ProcessManager の __exit__ メソッドが呼び出され
                    fcntl.flock を使用してファイルロックを解放します。

                    呼び出しの引数は、最初が (5, 6) で、2回目が (5, 8) です。
                    5 はファイル記述子
                    6 は fcntl.LOCK_EX | fcntl.LOCK_NB(排他的ロックを試みる)
                    8 は fcntl.LOCK_UN(ロックの解放)
                    を表しています。
        :
2024-01-21 23:28:46 [DEBUG] common_utils - test_processmanager_enter_UT_C0_oserror line 126: 
        - テスト関数: test_mutex_manager_UT_C0_normal_multiprocess, test_processmanager_UT_C0_normal, test_processmanager_enter_UT_C0_exception, test_processmanager_enter_UT_C0_oserror, test_processmanager_exit_UT_C0_delete_file_error_exception, test_processmanager_exit_UT_C0_exception
        - テスト定義:
                - テストカテゴリ: C0
                - テスト区分: 正常系/UT
                - テストシナリオ: ロック作成時にエラー OSErrorが発生する場合
        :
2024-01-21 23:28:46 [ERROR] common_utils - __enter__ line 80: already runnning: test_package:
2024-01-21 23:28:46 [DEBUG] common_utils - test_processmanager_enter_UT_C0_exception line 160: 
        - テスト関数: test_mutex_manager_UT_C0_normal_multiprocess, test_processmanager_UT_C0_normal, test_processmanager_enter_UT_C0_exception, test_processmanager_enter_UT_C0_oserror, test_processmanager_exit_UT_C0_delete_file_error_exception, test_processmanager_exit_UT_C0_exception
        - テスト定義:
                - テストカテゴリ: C0
                - テスト区分: 正常系/UT
                - テストシナリオ: ロック作成時にエラー Exceptionが発生する場合
        :
2024-01-21 23:28:46 [ERROR] common_utils - __enter__ line 83: Failed to multiprocess check: :
2024-01-21 23:28:46 [ERROR] common_utils - __enter__ line 85: Traceback (most recent call last):
  File "/developer/library_dev/project_1/src/lib/common_utils/ibr_multiprocess_lock.py", line 78, in __enter__
    fcntl.flock(self.lock_file.fileno(), fcntl.LOCK_EX | fcntl.LOCK_NB)
  File "/home/satoshi/.pyenv/versions/3.11.6/lib/python3.11/unittest/mock.py", line 1124, in __call__
    return self._mock_call(*args, **kwargs)
           ^^^^^^^^^^^^^^^^^^^^^^^^^^^^^^^^
  File "/home/satoshi/.pyenv/versions/3.11.6/lib/python3.11/unittest/mock.py", line 1128, in _mock_call
    return self._execute_mock_call(*args, **kwargs)
           ^^^^^^^^^^^^^^^^^^^^^^^^^^^^^^^^^^^^^^^^
  File "/home/satoshi/.pyenv/versions/3.11.6/lib/python3.11/unittest/mock.py", line 1187, in _execute_mock_call
    raise result
Exception
:
2024-01-21 23:28:46 [DEBUG] common_utils - test_processmanager_exit_UT_C0_exception line 193: 
        - テスト関数: test_mutex_manager_UT_C0_normal_multiprocess, test_processmanager_UT_C0_normal, test_processmanager_enter_UT_C0_exception, test_processmanager_enter_UT_C0_oserror, test_processmanager_exit_UT_C0_delete_file_error_exception, test_processmanager_exit_UT_C0_exception
        - テスト定義:
                - テストカテゴリ: C0
                - テスト区分: 正常系/UT
                - テストシナリオ: ロック開放時にエラー Exceptionが発生する場合
        :
2024-01-21 23:28:46 [ERROR] common_utils - __exit__ line 94: Failed to release lockfile: :
2024-01-21 23:28:46 [DEBUG] common_utils - test_processmanager_exit_UT_C0_delete_file_error_exception line 227: 
        - テスト関数: test_mutex_manager_UT_C0_normal_multiprocess, test_processmanager_UT_C0_normal, test_processmanager_enter_UT_C0_exception, test_processmanager_enter_UT_C0_oserror, test_processmanager_exit_UT_C0_delete_file_error_exception, test_processmanager_exit_UT_C0_exception
        - テスト定義:
                - テストカテゴリ: C0
                - テスト区分: 正常系/UT
                - テストシナリオ: ロック開放時にエラー Exceptionが発生する場合
        :
2024-01-21 23:28:46 [ERROR] common_utils - __exit__ line 101: Failed to unlink lockfile: :
2024-01-21 23:28:46 [DEBUG] common_utils - test_mutex_manager_UT_C0_normal_multiprocess line 257: 
        - テスト関数: test_mutex_manager_UT_C0_normal_multiprocess, test_processmanager_UT_C0_normal, test_processmanager_enter_UT_C0_exception, test_processmanager_enter_UT_C0_oserror, test_processmanager_exit_UT_C0_delete_file_error_exception, test_processmanager_exit_UT_C0_exception
        - テスト定義:
                - テストカテゴリ: C0
                - テスト区分: 正常系/UT
                - テストシナリオ:
        :
2024-01-21 23:28:46 [ERROR] common_utils - __exit__ line 101: Failed to unlink lockfile: [Errno 2] No such file or directory: '/tmp/test_package.lock':
2024-01-21 23:28:48 [DEBUG] common_utils - <module> line 39: Config(env='local', common_config={'logger_path': {'LOGGER_DEF_FILE': 'tests/def/mfaUtilsLoggingHelper/logging_TimedRotate.json', 'LOGGER_MSG_FILE': 'tests/def/mfaUtilsLoggingHelper/config_MessageList.toml'}, 'input_file_path': {'UPDATE_EXCEL_PATH': 'tests/share/receive'}, 'output_file_path': {'SEND_REFFERENCE_MASTER_PATH': 'tests/share/receive'}}, package_config={'test': {'local_test': 'test'}}, log_message=<bound method LoggerPackage.log_message of <src.lib.common_utils.ibr_logger_package.LoggerPackage object at 0x7f3b86c0cc10>>):
2024-01-21 23:28:48 [DEBUG] common_utils - test_processmanager_UT_C0_normal line 88: 
        - テスト関数: test_mutex_manager_UT_C0_normal_multiprocess, test_processmanager_UT_C0_normal, test_processmanager_enter_UT_C0_exception, test_processmanager_enter_UT_C0_oserror, test_processmanager_exit_UT_C0_delete_file_error_exception, test_processmanager_exit_UT_C0_exception
        - テスト定義:
                - テストカテゴリ: C0
                - テスト区分: 正常系/UT
                - テストシナリオ:
                    with ProcessManager('test_package'): ステートメントを使用すると
                    ProcessManager クラスのインスタンスがコンテキストマネージャとして機能します。
                    Pythonのコンテキストマネージャは、with ステートメントのブロックに入る際に
                    __enter__ メソッドを呼び出し、ブロックを抜ける際に __exit__ メソッドを呼び出します。

                    このテストケースでは、ProcessManager の __enter__ メソッドが呼び出されると
                    fcntl.flock を使用してファイルロックを試みます。
                    これは、プロセスが排他的にリソースを使用することを保証するためです。
                    with ブロックを抜けると、ProcessManager の __exit__ メソッドが呼び出され
                    fcntl.flock を使用してファイルロックを解放します。

                    呼び出しの引数は、最初が (5, 6) で、2回目が (5, 8) です。
                    5 はファイル記述子
                    6 は fcntl.LOCK_EX | fcntl.LOCK_NB(排他的ロックを試みる)
                    8 は fcntl.LOCK_UN(ロックの解放)
                    を表しています。
        :
2024-01-21 23:28:48 [DEBUG] common_utils - test_processmanager_enter_UT_C0_oserror line 126: 
        - テスト関数: test_mutex_manager_UT_C0_normal_multiprocess, test_processmanager_UT_C0_normal, test_processmanager_enter_UT_C0_exception, test_processmanager_enter_UT_C0_oserror, test_processmanager_exit_UT_C0_delete_file_error_exception, test_processmanager_exit_UT_C0_exception
        - テスト定義:
                - テストカテゴリ: C0
                - テスト区分: 正常系/UT
                - テストシナリオ: ロック作成時にエラー OSErrorが発生する場合
        :
2024-01-21 23:28:48 [ERROR] common_utils - __enter__ line 80: already runnning: test_package:
2024-01-21 23:28:48 [DEBUG] common_utils - test_processmanager_enter_UT_C0_exception line 160: 
        - テスト関数: test_mutex_manager_UT_C0_normal_multiprocess, test_processmanager_UT_C0_normal, test_processmanager_enter_UT_C0_exception, test_processmanager_enter_UT_C0_oserror, test_processmanager_exit_UT_C0_delete_file_error_exception, test_processmanager_exit_UT_C0_exception
        - テスト定義:
                - テストカテゴリ: C0
                - テスト区分: 正常系/UT
                - テストシナリオ: ロック作成時にエラー Exceptionが発生する場合
        :
2024-01-21 23:28:48 [ERROR] common_utils - __enter__ line 83: Failed to multiprocess check: :
2024-01-21 23:28:48 [ERROR] common_utils - __enter__ line 85: Traceback (most recent call last):
  File "/developer/library_dev/project_1/src/lib/common_utils/ibr_multiprocess_lock.py", line 78, in __enter__
    fcntl.flock(self.lock_file.fileno(), fcntl.LOCK_EX | fcntl.LOCK_NB)
  File "/home/satoshi/.pyenv/versions/3.11.6/lib/python3.11/unittest/mock.py", line 1124, in __call__
    return self._mock_call(*args, **kwargs)
           ^^^^^^^^^^^^^^^^^^^^^^^^^^^^^^^^
  File "/home/satoshi/.pyenv/versions/3.11.6/lib/python3.11/unittest/mock.py", line 1128, in _mock_call
    return self._execute_mock_call(*args, **kwargs)
           ^^^^^^^^^^^^^^^^^^^^^^^^^^^^^^^^^^^^^^^^
  File "/home/satoshi/.pyenv/versions/3.11.6/lib/python3.11/unittest/mock.py", line 1187, in _execute_mock_call
    raise result
Exception
:
2024-01-21 23:28:48 [DEBUG] common_utils - test_processmanager_exit_UT_C0_exception line 193: 
        - テスト関数: test_mutex_manager_UT_C0_normal_multiprocess, test_processmanager_UT_C0_normal, test_processmanager_enter_UT_C0_exception, test_processmanager_enter_UT_C0_oserror, test_processmanager_exit_UT_C0_delete_file_error_exception, test_processmanager_exit_UT_C0_exception
        - テスト定義:
                - テストカテゴリ: C0
                - テスト区分: 正常系/UT
                - テストシナリオ: ロック開放時にエラー Exceptionが発生する場合
        :
2024-01-21 23:28:48 [ERROR] common_utils - __exit__ line 94: Failed to release lockfile: :
2024-01-21 23:28:48 [DEBUG] common_utils - test_processmanager_exit_UT_C0_delete_file_error_exception line 227: 
        - テスト関数: test_mutex_manager_UT_C0_normal_multiprocess, test_processmanager_UT_C0_normal, test_processmanager_enter_UT_C0_exception, test_processmanager_enter_UT_C0_oserror, test_processmanager_exit_UT_C0_delete_file_error_exception, test_processmanager_exit_UT_C0_exception
        - テスト定義:
                - テストカテゴリ: C0
                - テスト区分: 正常系/UT
                - テストシナリオ: ロック開放時にエラー Exceptionが発生する場合
        :
2024-01-21 23:28:48 [ERROR] common_utils - __exit__ line 101: Failed to unlink lockfile: :
2024-01-21 23:28:48 [DEBUG] common_utils - test_mutex_manager_UT_C0_normal_multiprocess line 257: 
        - テスト関数: test_mutex_manager_UT_C0_normal_multiprocess, test_processmanager_UT_C0_normal, test_processmanager_enter_UT_C0_exception, test_processmanager_enter_UT_C0_oserror, test_processmanager_exit_UT_C0_delete_file_error_exception, test_processmanager_exit_UT_C0_exception
        - テスト定義:
                - テストカテゴリ: C0
                - テスト区分: 正常系/UT
                - テストシナリオ:
        :
2024-01-21 23:28:48 [ERROR] common_utils - __exit__ line 101: Failed to unlink lockfile: [Errno 2] No such file or directory: '/tmp/test_package.lock':
2024-01-22 22:09:46 [DEBUG] common_utils - <module> line 39: Config(env='local', common_config={'logger_path': {'LOGGER_DEF_FILE': 'tests/def/mfaUtilsLoggingHelper/logging_TimedRotate.json', 'LOGGER_MSG_FILE': 'tests/def/mfaUtilsLoggingHelper/config_MessageList.toml'}, 'input_file_path': {'UPDATE_EXCEL_PATH': 'tests/share/receive'}, 'output_file_path': {'SEND_REFFERENCE_MASTER_PATH': 'tests/share/receive'}}, package_config={'test': {'local_test': 'test'}}, log_message=<bound method LoggerPackage.log_message of <src.lib.common_utils.ibr_logger_package.LoggerPackage object at 0x7f1cfcda3b10>>):
2024-01-22 22:09:46 [DEBUG] common_utils - test_processmanager_UT_C0_normal line 91: 
        - テスト関数: test_mutex_manager_UT_C0_normal_multiprocess, test_processmanager_UT_C0_normal, test_processmanager_enter_UT_C0_exception, test_processmanager_enter_UT_C0_oserror, test_processmanager_exit_UT_C0_delete_file_error_exception, test_processmanager_exit_UT_C0_exception
        - テスト定義:
                - テストカテゴリ: C0
                - テスト区分: 正常系/UT
                - テストシナリオ:
                    with ProcessManager('test_package'): ステートメントを使用すると
                    ProcessManager クラスのインスタンスがコンテキストマネージャとして機能します。
                    Pythonのコンテキストマネージャは、with ステートメントのブロックに入る際に
                    __enter__ メソッドを呼び出し、ブロックを抜ける際に __exit__ メソッドを呼び出します。

                    このテストケースでは、ProcessManager の __enter__ メソッドが呼び出されると
                    fcntl.flock を使用してファイルロックを試みます。
                    これは、プロセスが排他的にリソースを使用することを保証するためです。
                    with ブロックを抜けると、ProcessManager の __exit__ メソッドが呼び出され
                    fcntl.flock を使用してファイルロックを解放します。

                    呼び出しの引数は、最初が (5, 6) で、2回目が (5, 8) です。
                    5 はファイル記述子
                    6 は fcntl.LOCK_EX | fcntl.LOCK_NB(排他的ロックを試みる)
                    8 は fcntl.LOCK_UN(ロックの解放)
                    を表しています。
        :
2024-01-22 22:09:46 [DEBUG] common_utils - test_processmanager_enter_UT_C0_oserror line 129: 
        - テスト関数: test_mutex_manager_UT_C0_normal_multiprocess, test_processmanager_UT_C0_normal, test_processmanager_enter_UT_C0_exception, test_processmanager_enter_UT_C0_oserror, test_processmanager_exit_UT_C0_delete_file_error_exception, test_processmanager_exit_UT_C0_exception
        - テスト定義:
                - テストカテゴリ: C0
                - テスト区分: 正常系/UT
                - テストシナリオ: ロック作成時にエラー OSErrorが発生する場合
        :
2024-01-22 22:09:46 [ERROR] common_utils - __enter__ line 80: already runnning: test_package:
2024-01-22 22:09:46 [DEBUG] common_utils - test_processmanager_enter_UT_C0_exception line 163: 
        - テスト関数: test_mutex_manager_UT_C0_normal_multiprocess, test_processmanager_UT_C0_normal, test_processmanager_enter_UT_C0_exception, test_processmanager_enter_UT_C0_oserror, test_processmanager_exit_UT_C0_delete_file_error_exception, test_processmanager_exit_UT_C0_exception
        - テスト定義:
                - テストカテゴリ: C0
                - テスト区分: 正常系/UT
                - テストシナリオ: ロック作成時にエラー Exceptionが発生する場合
        :
2024-01-22 22:09:46 [ERROR] common_utils - __enter__ line 83: Failed to multiprocess check: :
2024-01-22 22:09:46 [ERROR] common_utils - __enter__ line 85: Traceback (most recent call last):
  File "/developer/library_dev/project_1/src/lib/common_utils/ibr_multiprocess_lock.py", line 78, in __enter__
    fcntl.flock(self.lock_file.fileno(), fcntl.LOCK_EX | fcntl.LOCK_NB)
  File "/home/satoshi/.pyenv/versions/3.11.6/lib/python3.11/unittest/mock.py", line 1124, in __call__
    return self._mock_call(*args, **kwargs)
           ^^^^^^^^^^^^^^^^^^^^^^^^^^^^^^^^
  File "/home/satoshi/.pyenv/versions/3.11.6/lib/python3.11/unittest/mock.py", line 1128, in _mock_call
    return self._execute_mock_call(*args, **kwargs)
           ^^^^^^^^^^^^^^^^^^^^^^^^^^^^^^^^^^^^^^^^
  File "/home/satoshi/.pyenv/versions/3.11.6/lib/python3.11/unittest/mock.py", line 1187, in _execute_mock_call
    raise result
Exception
:
2024-01-22 22:09:46 [DEBUG] common_utils - test_processmanager_exit_UT_C0_exception line 196: 
        - テスト関数: test_mutex_manager_UT_C0_normal_multiprocess, test_processmanager_UT_C0_normal, test_processmanager_enter_UT_C0_exception, test_processmanager_enter_UT_C0_oserror, test_processmanager_exit_UT_C0_delete_file_error_exception, test_processmanager_exit_UT_C0_exception
        - テスト定義:
                - テストカテゴリ: C0
                - テスト区分: 正常系/UT
                - テストシナリオ: ロック開放時にエラー Exceptionが発生する場合
        :
2024-01-22 22:09:46 [ERROR] common_utils - __exit__ line 94: Failed to release lockfile: :
2024-01-22 22:09:46 [DEBUG] common_utils - test_processmanager_exit_UT_C0_delete_file_error_exception line 230: 
        - テスト関数: test_mutex_manager_UT_C0_normal_multiprocess, test_processmanager_UT_C0_normal, test_processmanager_enter_UT_C0_exception, test_processmanager_enter_UT_C0_oserror, test_processmanager_exit_UT_C0_delete_file_error_exception, test_processmanager_exit_UT_C0_exception
        - テスト定義:
                - テストカテゴリ: C0
                - テスト区分: 正常系/UT
                - テストシナリオ: ロック開放時にエラー Exceptionが発生する場合
        :
2024-01-22 22:09:46 [ERROR] common_utils - __exit__ line 101: Failed to unlink lockfile: :
2024-01-22 22:09:46 [DEBUG] common_utils - test_mutex_manager_UT_C0_normal_multiprocess line 260: 
        - テスト関数: test_mutex_manager_UT_C0_normal_multiprocess, test_processmanager_UT_C0_normal, test_processmanager_enter_UT_C0_exception, test_processmanager_enter_UT_C0_oserror, test_processmanager_exit_UT_C0_delete_file_error_exception, test_processmanager_exit_UT_C0_exception
        - テスト定義:
                - テストカテゴリ: C0
                - テスト区分: 正常系/UT
                - テストシナリオ:
        :
2024-01-22 22:09:46 [ERROR] common_utils - __exit__ line 101: Failed to unlink lockfile: [Errno 2] No such file or directory: '/tmp/test_package.lock':
2024-01-22 22:10:15 [DEBUG] common_utils - <module> line 39: Config(env='local', common_config={'logger_path': {'LOGGER_DEF_FILE': 'tests/def/mfaUtilsLoggingHelper/logging_TimedRotate.json', 'LOGGER_MSG_FILE': 'tests/def/mfaUtilsLoggingHelper/config_MessageList.toml'}, 'input_file_path': {'UPDATE_EXCEL_PATH': 'tests/share/receive'}, 'output_file_path': {'SEND_REFFERENCE_MASTER_PATH': 'tests/share/receive'}}, package_config={'test': {'local_test': 'test'}}, log_message=<bound method LoggerPackage.log_message of <src.lib.common_utils.ibr_logger_package.LoggerPackage object at 0x7f05e7e686d0>>):
2024-01-22 22:10:15 [DEBUG] common_utils - test_processmanager_UT_C0_normal line 91: 
        - テスト関数: test_mutex_manager_UT_C0_normal_multiprocess, test_processmanager_UT_C0_normal, test_processmanager_enter_UT_C0_exception, test_processmanager_enter_UT_C0_oserror, test_processmanager_exit_UT_C0_delete_file_error_exception, test_processmanager_exit_UT_C0_exception
        - テスト定義:
                - テストカテゴリ: C0
                - テスト区分: 正常系/UT
                - テストシナリオ:
                    with ProcessManager('test_package'): ステートメントを使用すると
                    ProcessManager クラスのインスタンスがコンテキストマネージャとして機能します。
                    Pythonのコンテキストマネージャは、with ステートメントのブロックに入る際に
                    __enter__ メソッドを呼び出し、ブロックを抜ける際に __exit__ メソッドを呼び出します。

                    このテストケースでは、ProcessManager の __enter__ メソッドが呼び出されると
                    fcntl.flock を使用してファイルロックを試みます。
                    これは、プロセスが排他的にリソースを使用することを保証するためです。
                    with ブロックを抜けると、ProcessManager の __exit__ メソッドが呼び出され
                    fcntl.flock を使用してファイルロックを解放します。

                    呼び出しの引数は、最初が (5, 6) で、2回目が (5, 8) です。
                    5 はファイル記述子
                    6 は fcntl.LOCK_EX | fcntl.LOCK_NB(排他的ロックを試みる)
                    8 は fcntl.LOCK_UN(ロックの解放)
                    を表しています。
        :
2024-01-22 22:10:15 [DEBUG] common_utils - test_processmanager_enter_UT_C0_oserror line 129: 
        - テスト関数: test_mutex_manager_UT_C0_normal_multiprocess, test_processmanager_UT_C0_normal, test_processmanager_enter_UT_C0_exception, test_processmanager_enter_UT_C0_oserror, test_processmanager_exit_UT_C0_delete_file_error_exception, test_processmanager_exit_UT_C0_exception
        - テスト定義:
                - テストカテゴリ: C0
                - テスト区分: 正常系/UT
                - テストシナリオ: ロック作成時にエラー OSErrorが発生する場合
        :
2024-01-22 22:10:15 [ERROR] common_utils - __enter__ line 80: already runnning: test_package:
2024-01-22 22:10:15 [DEBUG] common_utils - test_processmanager_enter_UT_C0_exception line 163: 
        - テスト関数: test_mutex_manager_UT_C0_normal_multiprocess, test_processmanager_UT_C0_normal, test_processmanager_enter_UT_C0_exception, test_processmanager_enter_UT_C0_oserror, test_processmanager_exit_UT_C0_delete_file_error_exception, test_processmanager_exit_UT_C0_exception
        - テスト定義:
                - テストカテゴリ: C0
                - テスト区分: 正常系/UT
                - テストシナリオ: ロック作成時にエラー Exceptionが発生する場合
        :
2024-01-22 22:10:15 [ERROR] common_utils - __enter__ line 83: Failed to multiprocess check: :
2024-01-22 22:10:15 [ERROR] common_utils - __enter__ line 85: Traceback (most recent call last):
  File "/developer/library_dev/project_1/src/lib/common_utils/ibr_multiprocess_lock.py", line 78, in __enter__
    fcntl.flock(self.lock_file.fileno(), fcntl.LOCK_EX | fcntl.LOCK_NB)
  File "/home/satoshi/.pyenv/versions/3.11.6/lib/python3.11/unittest/mock.py", line 1124, in __call__
    return self._mock_call(*args, **kwargs)
           ^^^^^^^^^^^^^^^^^^^^^^^^^^^^^^^^
  File "/home/satoshi/.pyenv/versions/3.11.6/lib/python3.11/unittest/mock.py", line 1128, in _mock_call
    return self._execute_mock_call(*args, **kwargs)
           ^^^^^^^^^^^^^^^^^^^^^^^^^^^^^^^^^^^^^^^^
  File "/home/satoshi/.pyenv/versions/3.11.6/lib/python3.11/unittest/mock.py", line 1187, in _execute_mock_call
    raise result
Exception
:
2024-01-22 22:10:15 [DEBUG] common_utils - test_processmanager_exit_UT_C0_exception line 196: 
        - テスト関数: test_mutex_manager_UT_C0_normal_multiprocess, test_processmanager_UT_C0_normal, test_processmanager_enter_UT_C0_exception, test_processmanager_enter_UT_C0_oserror, test_processmanager_exit_UT_C0_delete_file_error_exception, test_processmanager_exit_UT_C0_exception
        - テスト定義:
                - テストカテゴリ: C0
                - テスト区分: 正常系/UT
                - テストシナリオ: ロック開放時にエラー Exceptionが発生する場合
        :
2024-01-22 22:10:15 [ERROR] common_utils - __exit__ line 94: Failed to release lockfile: :
2024-01-22 22:10:15 [DEBUG] common_utils - test_processmanager_exit_UT_C0_delete_file_error_exception line 230: 
        - テスト関数: test_mutex_manager_UT_C0_normal_multiprocess, test_processmanager_UT_C0_normal, test_processmanager_enter_UT_C0_exception, test_processmanager_enter_UT_C0_oserror, test_processmanager_exit_UT_C0_delete_file_error_exception, test_processmanager_exit_UT_C0_exception
        - テスト定義:
                - テストカテゴリ: C0
                - テスト区分: 正常系/UT
                - テストシナリオ: ロック開放時にエラー Exceptionが発生する場合
        :
2024-01-22 22:10:15 [ERROR] common_utils - __exit__ line 101: Failed to unlink lockfile: :
2024-01-22 22:10:15 [DEBUG] common_utils - test_mutex_manager_UT_C0_normal_multiprocess line 260: 
        - テスト関数: test_mutex_manager_UT_C0_normal_multiprocess, test_processmanager_UT_C0_normal, test_processmanager_enter_UT_C0_exception, test_processmanager_enter_UT_C0_oserror, test_processmanager_exit_UT_C0_delete_file_error_exception, test_processmanager_exit_UT_C0_exception
        - テスト定義:
                - テストカテゴリ: C0
                - テスト区分: 正常系/UT
                - テストシナリオ:
        :
2024-01-22 22:10:15 [ERROR] common_utils - __exit__ line 101: Failed to unlink lockfile: [Errno 2] No such file or directory: '/tmp/test_package.lock':
2024-01-22 22:10:26 [DEBUG] common_utils - <module> line 39: Config(env='local', common_config={'logger_path': {'LOGGER_DEF_FILE': 'tests/def/mfaUtilsLoggingHelper/logging_TimedRotate.json', 'LOGGER_MSG_FILE': 'tests/def/mfaUtilsLoggingHelper/config_MessageList.toml'}, 'input_file_path': {'UPDATE_EXCEL_PATH': 'tests/share/receive'}, 'output_file_path': {'SEND_REFFERENCE_MASTER_PATH': 'tests/share/receive'}}, package_config={'test': {'local_test': 'test'}}, log_message=<bound method LoggerPackage.log_message of <src.lib.common_utils.ibr_logger_package.LoggerPackage object at 0x7f47464e5550>>):
2024-01-22 22:10:26 [DEBUG] common_utils - test_mutex_manager_UT_C0_normal_multiprocess line 260: 
        - テスト関数: test_mutex_manager_UT_C0_normal_multiprocess, test_processmanager_UT_C0_normal, test_processmanager_enter_UT_C0_exception, test_processmanager_enter_UT_C0_oserror, test_processmanager_exit_UT_C0_delete_file_error_exception, test_processmanager_exit_UT_C0_exception
        - テスト定義:
                - テストカテゴリ: C0
                - テスト区分: 正常系/UT
                - テストシナリオ:
        :
2024-01-22 22:10:26 [ERROR] common_utils - __exit__ line 101: Failed to unlink lockfile: [Errno 2] No such file or directory: '/tmp/test_package.lock':
2024-01-22 22:10:32 [DEBUG] common_utils - <module> line 39: Config(env='local', common_config={'logger_path': {'LOGGER_DEF_FILE': 'tests/def/mfaUtilsLoggingHelper/logging_TimedRotate.json', 'LOGGER_MSG_FILE': 'tests/def/mfaUtilsLoggingHelper/config_MessageList.toml'}, 'input_file_path': {'UPDATE_EXCEL_PATH': 'tests/share/receive'}, 'output_file_path': {'SEND_REFFERENCE_MASTER_PATH': 'tests/share/receive'}}, package_config={'test': {'local_test': 'test'}}, log_message=<bound method LoggerPackage.log_message of <src.lib.common_utils.ibr_logger_package.LoggerPackage object at 0x7f93098c49d0>>):
2024-01-22 22:10:32 [DEBUG] common_utils - test_mutex_manager_UT_C0_normal_multiprocess line 260: 
        - テスト関数: test_mutex_manager_UT_C0_normal_multiprocess, test_processmanager_UT_C0_normal, test_processmanager_enter_UT_C0_exception, test_processmanager_enter_UT_C0_oserror, test_processmanager_exit_UT_C0_delete_file_error_exception, test_processmanager_exit_UT_C0_exception
        - テスト定義:
                - テストカテゴリ: C0
                - テスト区分: 正常系/UT
                - テストシナリオ:
        :
2024-01-22 22:10:32 [ERROR] common_utils - __exit__ line 101: Failed to unlink lockfile: [Errno 2] No such file or directory: '/tmp/test_package.lock':
2024-01-22 22:11:31 [DEBUG] common_utils - <module> line 39: Config(env='local', common_config={'logger_path': {'LOGGER_DEF_FILE': 'tests/def/mfaUtilsLoggingHelper/logging_TimedRotate.json', 'LOGGER_MSG_FILE': 'tests/def/mfaUtilsLoggingHelper/config_MessageList.toml'}, 'input_file_path': {'UPDATE_EXCEL_PATH': 'tests/share/receive'}, 'output_file_path': {'SEND_REFFERENCE_MASTER_PATH': 'tests/share/receive'}}, package_config={'test': {'local_test': 'test'}}, log_message=<bound method LoggerPackage.log_message of <src.lib.common_utils.ibr_logger_package.LoggerPackage object at 0x7f2d52be09d0>>):
2024-01-22 22:11:31 [DEBUG] common_utils - test_mutex_manager_UT_C0_normal_multiprocess line 260: 
        - テスト関数: test_mutex_manager_UT_C0_normal_multiprocess, test_processmanager_UT_C0_normal, test_processmanager_enter_UT_C0_exception, test_processmanager_enter_UT_C0_oserror, test_processmanager_exit_UT_C0_delete_file_error_exception, test_processmanager_exit_UT_C0_exception
        - テスト定義:
                - テストカテゴリ: C0
                - テスト区分: 正常系/UT
                - テストシナリオ:
        :
2024-01-22 22:11:31 [ERROR] common_utils - __exit__ line 101: Failed to unlink lockfile: [Errno 2] No such file or directory: '/tmp/test_package.lock':
2024-01-22 22:14:31 [DEBUG] common_utils - <module> line 40: Config(env='local', common_config={'logger_path': {'LOGGER_DEF_FILE': 'tests/def/mfaUtilsLoggingHelper/logging_TimedRotate.json', 'LOGGER_MSG_FILE': 'tests/def/mfaUtilsLoggingHelper/config_MessageList.toml'}, 'input_file_path': {'UPDATE_EXCEL_PATH': 'tests/share/receive'}, 'output_file_path': {'SEND_REFFERENCE_MASTER_PATH': 'tests/share/receive'}}, package_config={'test': {'local_test': 'test'}}, log_message=<bound method LoggerPackage.log_message of <src.lib.common_utils.ibr_logger_package.LoggerPackage object at 0x7fecfc634bd0>>):
2024-01-22 22:14:33 [DEBUG] common_utils - <module> line 40: Config(env='local', common_config={'logger_path': {'LOGGER_DEF_FILE': 'tests/def/mfaUtilsLoggingHelper/logging_TimedRotate.json', 'LOGGER_MSG_FILE': 'tests/def/mfaUtilsLoggingHelper/config_MessageList.toml'}, 'input_file_path': {'UPDATE_EXCEL_PATH': 'tests/share/receive'}, 'output_file_path': {'SEND_REFFERENCE_MASTER_PATH': 'tests/share/receive'}}, package_config={'test': {'local_test': 'test'}}, log_message=<bound method LoggerPackage.log_message of <src.lib.common_utils.ibr_logger_package.LoggerPackage object at 0x7f8b2b655410>>):
2024-01-22 22:14:48 [DEBUG] common_utils - <module> line 40: Config(env='local', common_config={'logger_path': {'LOGGER_DEF_FILE': 'tests/def/mfaUtilsLoggingHelper/logging_TimedRotate.json', 'LOGGER_MSG_FILE': 'tests/def/mfaUtilsLoggingHelper/config_MessageList.toml'}, 'input_file_path': {'UPDATE_EXCEL_PATH': 'tests/share/receive'}, 'output_file_path': {'SEND_REFFERENCE_MASTER_PATH': 'tests/share/receive'}}, package_config={'test': {'local_test': 'test'}}, log_message=<bound method LoggerPackage.log_message of <src.lib.common_utils.ibr_logger_package.LoggerPackage object at 0x7fded2674390>>):
2024-01-22 22:14:48 [DEBUG] common_utils - test_processmanager_UT_C0_normal line 92: 
        - テスト関数: test_mutex_manager_UT_C0_normal_multiprocess, test_processmanager_UT_C0_normal, test_processmanager_enter_UT_C0_exception, test_processmanager_enter_UT_C0_oserror, test_processmanager_exit_UT_C0_delete_file_error_exception, test_processmanager_exit_UT_C0_exception
        - テスト定義:
                - テストカテゴリ: C0
                - テスト区分: 正常系/UT
                - テストシナリオ:
                    with ProcessManager('test_package'): ステートメントを使用すると
                    ProcessManager クラスのインスタンスがコンテキストマネージャとして機能します。
                    Pythonのコンテキストマネージャは、with ステートメントのブロックに入る際に
                    __enter__ メソッドを呼び出し、ブロックを抜ける際に __exit__ メソッドを呼び出します。

                    このテストケースでは、ProcessManager の __enter__ メソッドが呼び出されると
                    fcntl.flock を使用してファイルロックを試みます。
                    これは、プロセスが排他的にリソースを使用することを保証するためです。
                    with ブロックを抜けると、ProcessManager の __exit__ メソッドが呼び出され
                    fcntl.flock を使用してファイルロックを解放します。

                    呼び出しの引数は、最初が (5, 6) で、2回目が (5, 8) です。
                    5 はファイル記述子
                    6 は fcntl.LOCK_EX | fcntl.LOCK_NB(排他的ロックを試みる)
                    8 は fcntl.LOCK_UN(ロックの解放)
                    を表しています。
        :
2024-01-22 22:14:48 [DEBUG] common_utils - test_processmanager_enter_UT_C0_oserror line 130: 
        - テスト関数: test_mutex_manager_UT_C0_normal_multiprocess, test_processmanager_UT_C0_normal, test_processmanager_enter_UT_C0_exception, test_processmanager_enter_UT_C0_oserror, test_processmanager_exit_UT_C0_delete_file_error_exception, test_processmanager_exit_UT_C0_exception
        - テスト定義:
                - テストカテゴリ: C0
                - テスト区分: 正常系/UT
                - テストシナリオ: ロック作成時にエラー OSErrorが発生する場合
        :
2024-01-22 22:14:48 [ERROR] common_utils - __enter__ line 80: already runnning: test_package:
2024-01-22 22:14:48 [DEBUG] common_utils - test_processmanager_enter_UT_C0_exception line 164: 
        - テスト関数: test_mutex_manager_UT_C0_normal_multiprocess, test_processmanager_UT_C0_normal, test_processmanager_enter_UT_C0_exception, test_processmanager_enter_UT_C0_oserror, test_processmanager_exit_UT_C0_delete_file_error_exception, test_processmanager_exit_UT_C0_exception
        - テスト定義:
                - テストカテゴリ: C0
                - テスト区分: 正常系/UT
                - テストシナリオ: ロック作成時にエラー Exceptionが発生する場合
        :
2024-01-22 22:14:48 [ERROR] common_utils - __enter__ line 83: Failed to multiprocess check: :
2024-01-22 22:14:48 [ERROR] common_utils - __enter__ line 85: Traceback (most recent call last):
  File "/developer/library_dev/project_1/src/lib/common_utils/ibr_multiprocess_lock.py", line 78, in __enter__
    fcntl.flock(self.lock_file.fileno(), fcntl.LOCK_EX | fcntl.LOCK_NB)
  File "/home/satoshi/.pyenv/versions/3.11.6/lib/python3.11/unittest/mock.py", line 1124, in __call__
    return self._mock_call(*args, **kwargs)
           ^^^^^^^^^^^^^^^^^^^^^^^^^^^^^^^^
  File "/home/satoshi/.pyenv/versions/3.11.6/lib/python3.11/unittest/mock.py", line 1128, in _mock_call
    return self._execute_mock_call(*args, **kwargs)
           ^^^^^^^^^^^^^^^^^^^^^^^^^^^^^^^^^^^^^^^^
  File "/home/satoshi/.pyenv/versions/3.11.6/lib/python3.11/unittest/mock.py", line 1187, in _execute_mock_call
    raise result
Exception
:
2024-01-22 22:14:48 [DEBUG] common_utils - test_processmanager_exit_UT_C0_exception line 197: 
        - テスト関数: test_mutex_manager_UT_C0_normal_multiprocess, test_processmanager_UT_C0_normal, test_processmanager_enter_UT_C0_exception, test_processmanager_enter_UT_C0_oserror, test_processmanager_exit_UT_C0_delete_file_error_exception, test_processmanager_exit_UT_C0_exception
        - テスト定義:
                - テストカテゴリ: C0
                - テスト区分: 正常系/UT
                - テストシナリオ: ロック開放時にエラー Exceptionが発生する場合
        :
2024-01-22 22:14:48 [ERROR] common_utils - __exit__ line 94: Failed to release lockfile: :
2024-01-22 22:14:48 [DEBUG] common_utils - test_processmanager_exit_UT_C0_delete_file_error_exception line 231: 
        - テスト関数: test_mutex_manager_UT_C0_normal_multiprocess, test_processmanager_UT_C0_normal, test_processmanager_enter_UT_C0_exception, test_processmanager_enter_UT_C0_oserror, test_processmanager_exit_UT_C0_delete_file_error_exception, test_processmanager_exit_UT_C0_exception
        - テスト定義:
                - テストカテゴリ: C0
                - テスト区分: 正常系/UT
                - テストシナリオ: ロック開放時にエラー Exceptionが発生する場合
        :
2024-01-22 22:14:48 [ERROR] common_utils - __exit__ line 101: Failed to unlink lockfile: :
2024-01-22 22:14:48 [DEBUG] common_utils - test_mutex_manager_UT_C0_normal_multiprocess line 261: 
        - テスト関数: test_mutex_manager_UT_C0_normal_multiprocess, test_processmanager_UT_C0_normal, test_processmanager_enter_UT_C0_exception, test_processmanager_enter_UT_C0_oserror, test_processmanager_exit_UT_C0_delete_file_error_exception, test_processmanager_exit_UT_C0_exception
        - テスト定義:
                - テストカテゴリ: C0
                - テスト区分: 正常系/UT
                - テストシナリオ:
        :
2024-01-22 22:14:48 [ERROR] common_utils - __enter__ line 80: already runnning: test_package:
2024-01-22 22:21:38 [DEBUG] common_utils - <module> line 40: Config(env='local', common_config={'logger_path': {'LOGGER_DEF_FILE': 'tests/def/mfaUtilsLoggingHelper/logging_TimedRotate.json', 'LOGGER_MSG_FILE': 'tests/def/mfaUtilsLoggingHelper/config_MessageList.toml'}, 'input_file_path': {'UPDATE_EXCEL_PATH': 'tests/share/receive'}, 'output_file_path': {'SEND_REFFERENCE_MASTER_PATH': 'tests/share/receive'}}, package_config={'test': {'local_test': 'test'}}, log_message=<bound method LoggerPackage.log_message of <src.lib.common_utils.ibr_logger_package.LoggerPackage object at 0x7f52eec80250>>):
2024-01-22 22:21:38 [DEBUG] common_utils - test_processmanager_UT_C0_normal line 92: 
        - テスト関数: test_mutex_manager_UT_C0_normal_multiprocess, test_processmanager_UT_C0_normal, test_processmanager_enter_UT_C0_exception, test_processmanager_enter_UT_C0_oserror, test_processmanager_exit_UT_C0_delete_file_error_exception, test_processmanager_exit_UT_C0_exception
        - テスト定義:
                - テストカテゴリ: C0
                - テスト区分: 正常系/UT
                - テストシナリオ:
                    with ProcessManager('test_package'): ステートメントを使用すると
                    ProcessManager クラスのインスタンスがコンテキストマネージャとして機能します。
                    Pythonのコンテキストマネージャは、with ステートメントのブロックに入る際に
                    __enter__ メソッドを呼び出し、ブロックを抜ける際に __exit__ メソッドを呼び出します。

                    このテストケースでは、ProcessManager の __enter__ メソッドが呼び出されると
                    fcntl.flock を使用してファイルロックを試みます。
                    これは、プロセスが排他的にリソースを使用することを保証するためです。
                    with ブロックを抜けると、ProcessManager の __exit__ メソッドが呼び出され
                    fcntl.flock を使用してファイルロックを解放します。

                    呼び出しの引数は、最初が (5, 6) で、2回目が (5, 8) です。
                    5 はファイル記述子
                    6 は fcntl.LOCK_EX | fcntl.LOCK_NB(排他的ロックを試みる)
                    8 は fcntl.LOCK_UN(ロックの解放)
                    を表しています。
        :
2024-01-22 22:21:38 [DEBUG] common_utils - test_processmanager_enter_UT_C0_oserror line 130: 
        - テスト関数: test_mutex_manager_UT_C0_normal_multiprocess, test_processmanager_UT_C0_normal, test_processmanager_enter_UT_C0_exception, test_processmanager_enter_UT_C0_oserror, test_processmanager_exit_UT_C0_delete_file_error_exception, test_processmanager_exit_UT_C0_exception
        - テスト定義:
                - テストカテゴリ: C0
                - テスト区分: 正常系/UT
                - テストシナリオ: ロック作成時にエラー OSErrorが発生する場合
        :
2024-01-22 22:21:38 [ERROR] common_utils - __enter__ line 80: already runnning: test_package:
2024-01-22 22:21:38 [DEBUG] common_utils - test_processmanager_enter_UT_C0_exception line 164: 
        - テスト関数: test_mutex_manager_UT_C0_normal_multiprocess, test_processmanager_UT_C0_normal, test_processmanager_enter_UT_C0_exception, test_processmanager_enter_UT_C0_oserror, test_processmanager_exit_UT_C0_delete_file_error_exception, test_processmanager_exit_UT_C0_exception
        - テスト定義:
                - テストカテゴリ: C0
                - テスト区分: 正常系/UT
                - テストシナリオ: ロック作成時にエラー Exceptionが発生する場合
        :
2024-01-22 22:21:38 [ERROR] common_utils - __enter__ line 83: Failed to multiprocess check: :
2024-01-22 22:21:38 [ERROR] common_utils - __enter__ line 85: Traceback (most recent call last):
  File "/developer/library_dev/project_1/src/lib/common_utils/ibr_multiprocess_lock.py", line 78, in __enter__
    fcntl.flock(self.lock_file.fileno(), fcntl.LOCK_EX | fcntl.LOCK_NB)
  File "/home/satoshi/.pyenv/versions/3.11.6/lib/python3.11/unittest/mock.py", line 1124, in __call__
    return self._mock_call(*args, **kwargs)
           ^^^^^^^^^^^^^^^^^^^^^^^^^^^^^^^^
  File "/home/satoshi/.pyenv/versions/3.11.6/lib/python3.11/unittest/mock.py", line 1128, in _mock_call
    return self._execute_mock_call(*args, **kwargs)
           ^^^^^^^^^^^^^^^^^^^^^^^^^^^^^^^^^^^^^^^^
  File "/home/satoshi/.pyenv/versions/3.11.6/lib/python3.11/unittest/mock.py", line 1187, in _execute_mock_call
    raise result
Exception
:
2024-01-22 22:21:38 [DEBUG] common_utils - test_processmanager_exit_UT_C0_exception line 197: 
        - テスト関数: test_mutex_manager_UT_C0_normal_multiprocess, test_processmanager_UT_C0_normal, test_processmanager_enter_UT_C0_exception, test_processmanager_enter_UT_C0_oserror, test_processmanager_exit_UT_C0_delete_file_error_exception, test_processmanager_exit_UT_C0_exception
        - テスト定義:
                - テストカテゴリ: C0
                - テスト区分: 正常系/UT
                - テストシナリオ: ロック開放時にエラー Exceptionが発生する場合
        :
2024-01-22 22:21:38 [ERROR] common_utils - __exit__ line 94: Failed to release lockfile: :
2024-01-22 22:21:38 [DEBUG] common_utils - test_processmanager_exit_UT_C0_delete_file_error_exception line 231: 
        - テスト関数: test_mutex_manager_UT_C0_normal_multiprocess, test_processmanager_UT_C0_normal, test_processmanager_enter_UT_C0_exception, test_processmanager_enter_UT_C0_oserror, test_processmanager_exit_UT_C0_delete_file_error_exception, test_processmanager_exit_UT_C0_exception
        - テスト定義:
                - テストカテゴリ: C0
                - テスト区分: 正常系/UT
                - テストシナリオ: ロック開放時にエラー Exceptionが発生する場合
        :
2024-01-22 22:21:38 [ERROR] common_utils - __exit__ line 101: Failed to unlink lockfile: :
2024-01-22 22:21:38 [DEBUG] common_utils - test_mutex_manager_UT_C0_normal_multiprocess line 261: 
        - テスト関数: test_mutex_manager_UT_C0_normal_multiprocess, test_processmanager_UT_C0_normal, test_processmanager_enter_UT_C0_exception, test_processmanager_enter_UT_C0_oserror, test_processmanager_exit_UT_C0_delete_file_error_exception, test_processmanager_exit_UT_C0_exception
        - テスト定義:
                - テストカテゴリ: C0
                - テスト区分: 正常系/UT
                - テストシナリオ:
        :
2024-01-22 22:21:38 [ERROR] common_utils - __enter__ line 80: already runnning: test_package:
2024-01-22 22:22:06 [DEBUG] common_utils - <module> line 40: Config(env='local', common_config={'logger_path': {'LOGGER_DEF_FILE': 'tests/def/mfaUtilsLoggingHelper/logging_TimedRotate.json', 'LOGGER_MSG_FILE': 'tests/def/mfaUtilsLoggingHelper/config_MessageList.toml'}, 'input_file_path': {'UPDATE_EXCEL_PATH': 'tests/share/receive'}, 'output_file_path': {'SEND_REFFERENCE_MASTER_PATH': 'tests/share/receive'}}, package_config={'test': {'local_test': 'test'}}, log_message=<bound method LoggerPackage.log_message of <src.lib.common_utils.ibr_logger_package.LoggerPackage object at 0x7fe8bf090c90>>):
2024-01-22 22:22:06 [DEBUG] common_utils - test_processmanager_UT_C0_normal line 92: 
        - テスト関数: test_mutex_manager_UT_C0_normal_multiprocess, test_processmanager_UT_C0_normal, test_processmanager_enter_UT_C0_exception, test_processmanager_enter_UT_C0_oserror, test_processmanager_exit_UT_C0_delete_file_error_exception, test_processmanager_exit_UT_C0_exception
        - テスト定義:
                - テストカテゴリ: C0
                - テスト区分: 正常系/UT
                - テストシナリオ:
                    with ProcessManager('test_package'): ステートメントを使用すると
                    ProcessManager クラスのインスタンスがコンテキストマネージャとして機能します。
                    Pythonのコンテキストマネージャは、with ステートメントのブロックに入る際に
                    __enter__ メソッドを呼び出し、ブロックを抜ける際に __exit__ メソッドを呼び出します。

                    このテストケースでは、ProcessManager の __enter__ メソッドが呼び出されると
                    fcntl.flock を使用してファイルロックを試みます。
                    これは、プロセスが排他的にリソースを使用することを保証するためです。
                    with ブロックを抜けると、ProcessManager の __exit__ メソッドが呼び出され
                    fcntl.flock を使用してファイルロックを解放します。

                    呼び出しの引数は、最初が (5, 6) で、2回目が (5, 8) です。
                    5 はファイル記述子
                    6 は fcntl.LOCK_EX | fcntl.LOCK_NB(排他的ロックを試みる)
                    8 は fcntl.LOCK_UN(ロックの解放)
                    を表しています。
        :
2024-01-22 22:22:06 [DEBUG] common_utils - test_processmanager_enter_UT_C0_oserror line 130: 
        - テスト関数: test_mutex_manager_UT_C0_normal_multiprocess, test_processmanager_UT_C0_normal, test_processmanager_enter_UT_C0_exception, test_processmanager_enter_UT_C0_oserror, test_processmanager_exit_UT_C0_delete_file_error_exception, test_processmanager_exit_UT_C0_exception
        - テスト定義:
                - テストカテゴリ: C0
                - テスト区分: 正常系/UT
                - テストシナリオ: ロック作成時にエラー OSErrorが発生する場合
        :
2024-01-22 22:22:06 [ERROR] common_utils - __enter__ line 80: already runnning: test_package:
2024-01-22 22:22:06 [DEBUG] common_utils - test_processmanager_enter_UT_C0_exception line 164: 
        - テスト関数: test_mutex_manager_UT_C0_normal_multiprocess, test_processmanager_UT_C0_normal, test_processmanager_enter_UT_C0_exception, test_processmanager_enter_UT_C0_oserror, test_processmanager_exit_UT_C0_delete_file_error_exception, test_processmanager_exit_UT_C0_exception
        - テスト定義:
                - テストカテゴリ: C0
                - テスト区分: 正常系/UT
                - テストシナリオ: ロック作成時にエラー Exceptionが発生する場合
        :
2024-01-22 22:22:06 [ERROR] common_utils - __enter__ line 83: Failed to multiprocess check: :
2024-01-22 22:22:06 [ERROR] common_utils - __enter__ line 85: Traceback (most recent call last):
  File "/developer/library_dev/project_1/src/lib/common_utils/ibr_multiprocess_lock.py", line 78, in __enter__
    fcntl.flock(self.lock_file.fileno(), fcntl.LOCK_EX | fcntl.LOCK_NB)
  File "/home/satoshi/.pyenv/versions/3.11.6/lib/python3.11/unittest/mock.py", line 1124, in __call__
    return self._mock_call(*args, **kwargs)
           ^^^^^^^^^^^^^^^^^^^^^^^^^^^^^^^^
  File "/home/satoshi/.pyenv/versions/3.11.6/lib/python3.11/unittest/mock.py", line 1128, in _mock_call
    return self._execute_mock_call(*args, **kwargs)
           ^^^^^^^^^^^^^^^^^^^^^^^^^^^^^^^^^^^^^^^^
  File "/home/satoshi/.pyenv/versions/3.11.6/lib/python3.11/unittest/mock.py", line 1187, in _execute_mock_call
    raise result
Exception
:
2024-01-22 22:22:06 [DEBUG] common_utils - test_processmanager_exit_UT_C0_exception line 197: 
        - テスト関数: test_mutex_manager_UT_C0_normal_multiprocess, test_processmanager_UT_C0_normal, test_processmanager_enter_UT_C0_exception, test_processmanager_enter_UT_C0_oserror, test_processmanager_exit_UT_C0_delete_file_error_exception, test_processmanager_exit_UT_C0_exception
        - テスト定義:
                - テストカテゴリ: C0
                - テスト区分: 正常系/UT
                - テストシナリオ: ロック開放時にエラー Exceptionが発生する場合
        :
2024-01-22 22:22:06 [ERROR] common_utils - __exit__ line 94: Failed to release lockfile: :
2024-01-22 22:22:06 [DEBUG] common_utils - test_processmanager_exit_UT_C0_delete_file_error_exception line 231: 
        - テスト関数: test_mutex_manager_UT_C0_normal_multiprocess, test_processmanager_UT_C0_normal, test_processmanager_enter_UT_C0_exception, test_processmanager_enter_UT_C0_oserror, test_processmanager_exit_UT_C0_delete_file_error_exception, test_processmanager_exit_UT_C0_exception
        - テスト定義:
                - テストカテゴリ: C0
                - テスト区分: 正常系/UT
                - テストシナリオ: ロック開放時にエラー Exceptionが発生する場合
        :
2024-01-22 22:22:06 [ERROR] common_utils - __exit__ line 101: Failed to unlink lockfile: :
2024-01-22 22:22:06 [DEBUG] common_utils - test_mutex_manager_UT_C0_normal_multiprocess line 261: 
        - テスト関数: test_mutex_manager_UT_C0_normal_multiprocess, test_processmanager_UT_C0_normal, test_processmanager_enter_UT_C0_exception, test_processmanager_enter_UT_C0_oserror, test_processmanager_exit_UT_C0_delete_file_error_exception, test_processmanager_exit_UT_C0_exception
        - テスト定義:
                - テストカテゴリ: C0
                - テスト区分: 正常系/UT
                - テストシナリオ:
        :
2024-01-22 22:22:06 [ERROR] common_utils - __enter__ line 80: already runnning: test_package:
2024-01-22 22:22:24 [DEBUG] common_utils - <module> line 40: Config(env='local', common_config={'logger_path': {'LOGGER_DEF_FILE': 'tests/def/mfaUtilsLoggingHelper/logging_TimedRotate.json', 'LOGGER_MSG_FILE': 'tests/def/mfaUtilsLoggingHelper/config_MessageList.toml'}, 'input_file_path': {'UPDATE_EXCEL_PATH': 'tests/share/receive'}, 'output_file_path': {'SEND_REFFERENCE_MASTER_PATH': 'tests/share/receive'}}, package_config={'test': {'local_test': 'test'}}, log_message=<bound method LoggerPackage.log_message of <src.lib.common_utils.ibr_logger_package.LoggerPackage object at 0x7f5f9bfed390>>):
2024-01-22 22:22:24 [DEBUG] common_utils - test_mutex_manager_UT_C0_normal_multiprocess line 261: 
        - テスト関数: test_mutex_manager_UT_C0_normal_multiprocess, test_processmanager_UT_C0_normal, test_processmanager_enter_UT_C0_exception, test_processmanager_enter_UT_C0_oserror, test_processmanager_exit_UT_C0_delete_file_error_exception, test_processmanager_exit_UT_C0_exception
        - テスト定義:
                - テストカテゴリ: C0
                - テスト区分: 正常系/UT
                - テストシナリオ:
        :
2024-01-22 22:22:24 [ERROR] common_utils - __enter__ line 80: already runnning: test_package:
2024-01-22 22:22:40 [DEBUG] common_utils - <module> line 40: Config(env='local', common_config={'logger_path': {'LOGGER_DEF_FILE': 'tests/def/mfaUtilsLoggingHelper/logging_TimedRotate.json', 'LOGGER_MSG_FILE': 'tests/def/mfaUtilsLoggingHelper/config_MessageList.toml'}, 'input_file_path': {'UPDATE_EXCEL_PATH': 'tests/share/receive'}, 'output_file_path': {'SEND_REFFERENCE_MASTER_PATH': 'tests/share/receive'}}, package_config={'test': {'local_test': 'test'}}, log_message=<bound method LoggerPackage.log_message of <src.lib.common_utils.ibr_logger_package.LoggerPackage object at 0x7fd19e8687d0>>):
2024-01-22 22:22:40 [DEBUG] common_utils - test_mutex_manager_UT_C0_normal_multiprocess line 261: 
        - テスト関数: test_mutex_manager_UT_C0_normal_multiprocess, test_processmanager_UT_C0_normal, test_processmanager_enter_UT_C0_exception, test_processmanager_enter_UT_C0_oserror, test_processmanager_exit_UT_C0_delete_file_error_exception, test_processmanager_exit_UT_C0_exception
        - テスト定義:
                - テストカテゴリ: C0
                - テスト区分: 正常系/UT
                - テストシナリオ:
        :
2024-01-22 22:22:40 [ERROR] common_utils - __enter__ line 80: already runnning: test_package:
2024-01-22 22:25:55 [DEBUG] common_utils - <module> line 40: Config(env='local', common_config={'logger_path': {'LOGGER_DEF_FILE': 'tests/def/mfaUtilsLoggingHelper/logging_TimedRotate.json', 'LOGGER_MSG_FILE': 'tests/def/mfaUtilsLoggingHelper/config_MessageList.toml'}, 'input_file_path': {'UPDATE_EXCEL_PATH': 'tests/share/receive'}, 'output_file_path': {'SEND_REFFERENCE_MASTER_PATH': 'tests/share/receive'}}, package_config={'test': {'local_test': 'test'}}, log_message=<bound method LoggerPackage.log_message of <src.lib.common_utils.ibr_logger_package.LoggerPackage object at 0x7fe2a6d32b10>>):
2024-01-22 22:25:55 [DEBUG] common_utils - test_mutex_manager_UT_C0_normal_multiprocess line 266: 
        - テスト関数: test_mutex_manager_UT_C0_normal_multiprocess, test_processmanager_UT_C0_normal, test_processmanager_enter_UT_C0_exception, test_processmanager_enter_UT_C0_oserror, test_processmanager_exit_UT_C0_delete_file_error_exception, test_processmanager_exit_UT_C0_exception
        - テスト定義:
                - テストカテゴリ: C0
                - テスト区分: 正常系/UT
                - テストシナリオ:
        :
2024-01-22 22:25:55 [ERROR] common_utils - __enter__ line 80: already runnning: test_package:
2024-01-22 22:26:31 [DEBUG] common_utils - <module> line 40: Config(env='local', common_config={'logger_path': {'LOGGER_DEF_FILE': 'tests/def/mfaUtilsLoggingHelper/logging_TimedRotate.json', 'LOGGER_MSG_FILE': 'tests/def/mfaUtilsLoggingHelper/config_MessageList.toml'}, 'input_file_path': {'UPDATE_EXCEL_PATH': 'tests/share/receive'}, 'output_file_path': {'SEND_REFFERENCE_MASTER_PATH': 'tests/share/receive'}}, package_config={'test': {'local_test': 'test'}}, log_message=<bound method LoggerPackage.log_message of <src.lib.common_utils.ibr_logger_package.LoggerPackage object at 0x7ff81e55ced0>>):
2024-01-22 22:26:31 [DEBUG] common_utils - test_mutex_manager_UT_C0_normal_multiprocess line 266: 
        - テスト関数: test_mutex_manager_UT_C0_normal_multiprocess, test_processmanager_UT_C0_normal, test_processmanager_enter_UT_C0_exception, test_processmanager_enter_UT_C0_oserror, test_processmanager_exit_UT_C0_delete_file_error_exception, test_processmanager_exit_UT_C0_exception
        - テスト定義:
                - テストカテゴリ: C0
                - テスト区分: 正常系/UT
                - テストシナリオ:
        :
2024-01-22 22:26:31 [ERROR] common_utils - __enter__ line 80: already runnning: test_package:
2024-01-22 22:27:03 [DEBUG] common_utils - <module> line 40: Config(env='local', common_config={'logger_path': {'LOGGER_DEF_FILE': 'tests/def/mfaUtilsLoggingHelper/logging_TimedRotate.json', 'LOGGER_MSG_FILE': 'tests/def/mfaUtilsLoggingHelper/config_MessageList.toml'}, 'input_file_path': {'UPDATE_EXCEL_PATH': 'tests/share/receive'}, 'output_file_path': {'SEND_REFFERENCE_MASTER_PATH': 'tests/share/receive'}}, package_config={'test': {'local_test': 'test'}}, log_message=<bound method LoggerPackage.log_message of <src.lib.common_utils.ibr_logger_package.LoggerPackage object at 0x7efcbd290fd0>>):
2024-01-22 22:27:03 [DEBUG] common_utils - test_mutex_manager_UT_C0_normal_multiprocess line 266: 
        - テスト関数: test_mutex_manager_UT_C0_normal_multiprocess, test_processmanager_UT_C0_normal, test_processmanager_enter_UT_C0_exception, test_processmanager_enter_UT_C0_oserror, test_processmanager_exit_UT_C0_delete_file_error_exception, test_processmanager_exit_UT_C0_exception
        - テスト定義:
                - テストカテゴリ: C0
                - テスト区分: 正常系/UT
                - テストシナリオ:
        :
2024-01-22 22:27:03 [ERROR] common_utils - __enter__ line 80: already runnning: test_package:
2024-01-22 22:27:58 [DEBUG] common_utils - <module> line 40: Config(env='local', common_config={'logger_path': {'LOGGER_DEF_FILE': 'tests/def/mfaUtilsLoggingHelper/logging_TimedRotate.json', 'LOGGER_MSG_FILE': 'tests/def/mfaUtilsLoggingHelper/config_MessageList.toml'}, 'input_file_path': {'UPDATE_EXCEL_PATH': 'tests/share/receive'}, 'output_file_path': {'SEND_REFFERENCE_MASTER_PATH': 'tests/share/receive'}}, package_config={'test': {'local_test': 'test'}}, log_message=<bound method LoggerPackage.log_message of <src.lib.common_utils.ibr_logger_package.LoggerPackage object at 0x7ff2ea3fab10>>):
2024-01-22 22:27:58 [DEBUG] common_utils - test_mutex_manager_UT_C0_normal_multiprocess line 266: 
        - テスト関数: test_mutex_manager_UT_C0_normal_multiprocess, test_processmanager_UT_C0_normal, test_processmanager_enter_UT_C0_exception, test_processmanager_enter_UT_C0_oserror, test_processmanager_exit_UT_C0_delete_file_error_exception, test_processmanager_exit_UT_C0_exception
        - テスト定義:
                - テストカテゴリ: C0
                - テスト区分: 正常系/UT
                - テストシナリオ:
        :
2024-01-22 22:27:58 [ERROR] common_utils - __enter__ line 80: already runnning: test_package:
2024-01-22 22:29:07 [DEBUG] common_utils - <module> line 40: Config(env='local', common_config={'logger_path': {'LOGGER_DEF_FILE': 'tests/def/mfaUtilsLoggingHelper/logging_TimedRotate.json', 'LOGGER_MSG_FILE': 'tests/def/mfaUtilsLoggingHelper/config_MessageList.toml'}, 'input_file_path': {'UPDATE_EXCEL_PATH': 'tests/share/receive'}, 'output_file_path': {'SEND_REFFERENCE_MASTER_PATH': 'tests/share/receive'}}, package_config={'test': {'local_test': 'test'}}, log_message=<bound method LoggerPackage.log_message of <src.lib.common_utils.ibr_logger_package.LoggerPackage object at 0x7fbab0967b10>>):
2024-01-22 22:29:07 [DEBUG] common_utils - test_mutex_manager_UT_C0_normal_multiprocess line 266: 
        - テスト関数: test_mutex_manager_UT_C0_normal_multiprocess, test_processmanager_UT_C0_normal, test_processmanager_enter_UT_C0_exception, test_processmanager_enter_UT_C0_oserror, test_processmanager_exit_UT_C0_delete_file_error_exception, test_processmanager_exit_UT_C0_exception
        - テスト定義:
                - テストカテゴリ: C0
                - テスト区分: 正常系/UT
                - テストシナリオ:
        :
2024-01-22 22:29:07 [ERROR] common_utils - __enter__ line 80: already runnning: test_package:
2024-01-22 22:30:30 [DEBUG] common_utils - <module> line 40: Config(env='local', common_config={'logger_path': {'LOGGER_DEF_FILE': 'tests/def/mfaUtilsLoggingHelper/logging_TimedRotate.json', 'LOGGER_MSG_FILE': 'tests/def/mfaUtilsLoggingHelper/config_MessageList.toml'}, 'input_file_path': {'UPDATE_EXCEL_PATH': 'tests/share/receive'}, 'output_file_path': {'SEND_REFFERENCE_MASTER_PATH': 'tests/share/receive'}}, package_config={'test': {'local_test': 'test'}}, log_message=<bound method LoggerPackage.log_message of <src.lib.common_utils.ibr_logger_package.LoggerPackage object at 0x7f59c7fc8910>>):
2024-01-22 22:30:30 [DEBUG] common_utils - test_mutex_manager_UT_C0_normal_multiprocess line 266: 
        - テスト関数: test_mutex_manager_UT_C0_normal_multiprocess, test_processmanager_UT_C0_normal, test_processmanager_enter_UT_C0_exception, test_processmanager_enter_UT_C0_oserror, test_processmanager_exit_UT_C0_delete_file_error_exception, test_processmanager_exit_UT_C0_exception
        - テスト定義:
                - テストカテゴリ: C0
                - テスト区分: 正常系/UT
                - テストシナリオ:
        :
2024-01-22 22:30:30 [ERROR] common_utils - __enter__ line 80: already runnning: test_package:
2024-01-22 22:33:08 [DEBUG] common_utils - <module> line 40: Config(env='local', common_config={'logger_path': {'LOGGER_DEF_FILE': 'tests/def/mfaUtilsLoggingHelper/logging_TimedRotate.json', 'LOGGER_MSG_FILE': 'tests/def/mfaUtilsLoggingHelper/config_MessageList.toml'}, 'input_file_path': {'UPDATE_EXCEL_PATH': 'tests/share/receive'}, 'output_file_path': {'SEND_REFFERENCE_MASTER_PATH': 'tests/share/receive'}}, package_config={'test': {'local_test': 'test'}}, log_message=<bound method LoggerPackage.log_message of <src.lib.common_utils.ibr_logger_package.LoggerPackage object at 0x7f58daa1d750>>):
2024-01-22 22:33:08 [DEBUG] common_utils - test_mutex_manager_UT_C0_normal_multiprocess line 266: 
        - テスト関数: test_mutex_manager_UT_C0_normal_multiprocess, test_processmanager_UT_C0_normal, test_processmanager_enter_UT_C0_exception, test_processmanager_enter_UT_C0_oserror, test_processmanager_exit_UT_C0_delete_file_error_exception, test_processmanager_exit_UT_C0_exception
        - テスト定義:
                - テストカテゴリ: C0
                - テスト区分: 正常系/UT
                - テストシナリオ:
        :
2024-01-22 22:33:08 [ERROR] common_utils - __enter__ line 81: already runnning: test_package:
2024-01-22 22:38:01 [DEBUG] common_utils - <module> line 40: Config(env='local', common_config={'logger_path': {'LOGGER_DEF_FILE': 'tests/def/mfaUtilsLoggingHelper/logging_TimedRotate.json', 'LOGGER_MSG_FILE': 'tests/def/mfaUtilsLoggingHelper/config_MessageList.toml'}, 'input_file_path': {'UPDATE_EXCEL_PATH': 'tests/share/receive'}, 'output_file_path': {'SEND_REFFERENCE_MASTER_PATH': 'tests/share/receive'}}, package_config={'test': {'local_test': 'test'}}, log_message=<bound method LoggerPackage.log_message of <src.lib.common_utils.ibr_logger_package.LoggerPackage object at 0x7f375c6b4390>>):
2024-01-22 22:38:01 [DEBUG] common_utils - test_mutex_manager_UT_C0_normal_multiprocess line 266: 
        - テスト関数: test_mutex_manager_UT_C0_normal_multiprocess, test_processmanager_UT_C0_normal, test_processmanager_enter_UT_C0_exception, test_processmanager_enter_UT_C0_oserror, test_processmanager_exit_UT_C0_delete_file_error_exception, test_processmanager_exit_UT_C0_exception
        - テスト定義:
                - テストカテゴリ: C0
                - テスト区分: 正常系/UT
                - テストシナリオ:
        :
2024-01-22 22:38:01 [ERROR] common_utils - __enter__ line 80: already runnning: test_package:
2024-01-22 22:42:41 [DEBUG] common_utils - <module> line 40: Config(env='local', common_config={'logger_path': {'LOGGER_DEF_FILE': 'tests/def/mfaUtilsLoggingHelper/logging_TimedRotate.json', 'LOGGER_MSG_FILE': 'tests/def/mfaUtilsLoggingHelper/config_MessageList.toml'}, 'input_file_path': {'UPDATE_EXCEL_PATH': 'tests/share/receive'}, 'output_file_path': {'SEND_REFFERENCE_MASTER_PATH': 'tests/share/receive'}}, package_config={'test': {'local_test': 'test'}}, log_message=<bound method LoggerPackage.log_message of <src.lib.common_utils.ibr_logger_package.LoggerPackage object at 0x7fb02e741dd0>>):
2024-01-22 22:42:41 [DEBUG] common_utils - test_mutex_manager_UT_C0_normal_multiprocess line 266: 
        - テスト関数: test_mutex_manager_UT_C0_normal_multiprocess, test_processmanager_UT_C0_normal, test_processmanager_enter_UT_C0_exception, test_processmanager_enter_UT_C0_oserror, test_processmanager_exit_UT_C0_delete_file_error_exception, test_processmanager_exit_UT_C0_exception
        - テスト定義:
                - テストカテゴリ: C0
                - テスト区分: 正常系/UT
                - テストシナリオ:
        :
2024-01-22 22:42:41 [ERROR] common_utils - __enter__ line 80: already runnning: test_package:
2024-01-22 23:11:26 [INFO] validator_excel_main_class - start line 134: IBRDEV-I-0000001:起動しました
2024-01-22 23:11:26 [DEBUG] common_utils - tabulate_dataframe line 67: 
|    |   NO | あ   | い   |   う | え   | お   |   か | き   |   く |   け |   こ |
|---:|-----:|:-----|:-----|-----:|:-----|:-----|-----:|:-----|-----:|-----:|-----:|
|  0 |    1 | a    | d    |    1 | 4    | あ   |   10 | 1    |   13 |   16 |   19 |
|  1 |    2 | b    | e    |    2 | s    | 8    |   11 | h    |   14 |   17 |   20 |
|  2 |    3 | c    | f    |    3 | 6    | 9    |   12 | I    |   15 |   18 |   21 |:
2024-01-22 23:11:26 [DEBUG] common_utils - read_excel_one_sheet line 99: 
Sheet_name: Sheet1
|    |   NO | あ   | い   |   う | え   | お   |   か | き   |   く |   け |   こ |
|---:|-----:|:-----|:-----|-----:|:-----|:-----|-----:|:-----|-----:|-----:|-----:|
|  0 |    1 | a    | d    |    1 | 4    | あ   |   10 | 1    |   13 |   16 |   19 |
|  1 |    2 | b    | e    |    2 | s    | 8    |   11 | h    |   14 |   17 |   20 |
|  2 |    3 | c    | f    |    3 | 6    | 9    |   12 | I    |   15 |   18 |   21 |:
2024-01-22 23:11:26 [DEBUG] common_utils - tabulate_dataframe line 67: 
|    | Columns   | Type   |
|---:|:----------|:-------|
|  0 | No        | int64  |
|  1 | a         | object |
|  2 | b         | object |
|  3 | c         | int64  |
|  4 | d         | object |
|  5 | e         | object |
|  6 | f         | int64  |
|  7 | g         | object |
|  8 | h         | int64  |
|  9 | i         | int64  |
| 10 | j         | int64  |:
2024-01-22 23:11:26 [INFO] validator_excel_main_class - _excel_to_dataframe line 94: 
|    | Columns   | Type   |
|---:|:----------|:-------|
|  0 | No        | int64  |
|  1 | a         | object |
|  2 | b         | object |
|  3 | c         | int64  |
|  4 | d         | object |
|  5 | e         | object |
|  6 | f         | int64  |
|  7 | g         | object |
|  8 | h         | int64  |
|  9 | i         | int64  |
| 10 | j         | int64  |:
2024-01-22 23:11:26 [INFO] validator_excel_main_class - _valdate line 123: 検証対象ファイル: src/share/receive/input_data_validator.xlsx:
2024-01-22 23:11:26 [INFO] validator_excel_main_class - _valdate line 124: 検証対象Sheet: Sheet1:
2024-01-22 23:11:26 [WARNING] validator_excel_main_class - _valdate line 125: validate error 検出件数: 2:
2024-01-22 23:11:26 [DEBUG] validator_excel_main_class - _valdate line 126: validate error list: [(0, [{'type': 'int_type', 'loc': ('e',), 'msg': 'Input should be a valid integer', 'input': 'あ', 'url': 'https://errors.pydantic.dev/2.5/v/int_type'}, {'type': 'string_type', 'loc': ('g',), 'msg': 'Input should be a valid string', 'input': 1, 'url': 'https://errors.pydantic.dev/2.5/v/string_type'}]), (1, [{'type': 'int_type', 'loc': ('d',), 'msg': 'Input should be a valid integer', 'input': 's', 'url': 'https://errors.pydantic.dev/2.5/v/int_type'}])]:
2024-01-22 23:11:26 [DEBUG] common_utils - logger_validation_errors line 260: errors: [(0, [{'type': 'int_type', 'loc': ('e',), 'msg': 'Input should be a valid integer', 'input': 'あ', 'url': 'https://errors.pydantic.dev/2.5/v/int_type'}, {'type': 'string_type', 'loc': ('g',), 'msg': 'Input should be a valid string', 'input': 1, 'url': 'https://errors.pydantic.dev/2.5/v/string_type'}]), (1, [{'type': 'int_type', 'loc': ('d',), 'msg': 'Input should be a valid integer', 'input': 's', 'url': 'https://errors.pydantic.dev/2.5/v/int_type'}])]:
2024-01-22 23:11:26 [DEBUG] common_utils - logger_validation_errors line 267: error_dict: {'type': 'int_type', 'loc': ('e',), 'msg': 'Input should be a valid integer', 'input': 'あ', 'url': 'https://errors.pydantic.dev/2.5/v/int_type'}:
2024-01-22 23:11:26 [DEBUG] common_utils - logger_validation_errors line 277: values: ['Input should be a valid integer', ('e',), 'あ']:
2024-01-22 23:11:26 [ERROR] common_utils - logger_validation_errors line 287: Validation error at (1, e):  Input should be a valid integer, wrong values: あ:
2024-01-22 23:11:26 [DEBUG] common_utils - logger_validation_errors line 267: error_dict: {'type': 'string_type', 'loc': ('g',), 'msg': 'Input should be a valid string', 'input': 1, 'url': 'https://errors.pydantic.dev/2.5/v/string_type'}:
2024-01-22 23:11:26 [DEBUG] common_utils - logger_validation_errors line 277: values: ['Input should be a valid string', ('g',), 1]:
2024-01-22 23:11:26 [ERROR] common_utils - logger_validation_errors line 287: Validation error at (1, g):  Input should be a valid string, wrong values: 1:
2024-01-22 23:11:26 [DEBUG] common_utils - logger_validation_errors line 267: error_dict: {'type': 'int_type', 'loc': ('d',), 'msg': 'Input should be a valid integer', 'input': 's', 'url': 'https://errors.pydantic.dev/2.5/v/int_type'}:
2024-01-22 23:11:26 [DEBUG] common_utils - logger_validation_errors line 277: values: ['Input should be a valid integer', ('d',), 's']:
2024-01-22 23:11:26 [ERROR] common_utils - logger_validation_errors line 287: Validation error at (2, d):  Input should be a valid integer, wrong values: s:
2024-01-22 23:11:26 [INFO] validator_excel_main_class - start line 150: IBRDEV-I-0000002:終了しました
2024-01-22 23:11:59 [DEBUG] common_utils - <module> line 40: Config(env='local', common_config={'logger_path': {'LOGGER_DEF_FILE': 'tests/def/mfaUtilsLoggingHelper/logging_TimedRotate.json', 'LOGGER_MSG_FILE': 'tests/def/mfaUtilsLoggingHelper/config_MessageList.toml'}, 'input_file_path': {'UPDATE_EXCEL_PATH': 'tests/share/receive'}, 'output_file_path': {'SEND_REFFERENCE_MASTER_PATH': 'tests/share/receive'}}, package_config={'test': {'local_test': 'test'}}, log_message=<bound method LoggerPackage.log_message of <src.lib.common_utils.ibr_logger_package.LoggerPackage object at 0x7f92744a8590>>):
2024-01-22 23:11:59 [DEBUG] common_utils - test_mutex_manager_UT_C0_normal_multiprocess line 266: 
        - テスト関数: test_mutex_manager_UT_C0_normal_multiprocess, test_processmanager_UT_C0_normal, test_processmanager_enter_UT_C0_exception, test_processmanager_enter_UT_C0_oserror, test_processmanager_exit_UT_C0_delete_file_error_exception, test_processmanager_exit_UT_C0_exception
        - テスト定義:
                - テストカテゴリ: C0
                - テスト区分: 正常系/UT
                - テストシナリオ:
        :
2024-01-22 23:11:59 [ERROR] common_utils - __enter__ line 80: already runnning: test_package:
2024-01-22 23:22:13 [DEBUG] common_utils - <module> line 40: Config(env='local', common_config={'logger_path': {'LOGGER_DEF_FILE': 'tests/def/mfaUtilsLoggingHelper/logging_TimedRotate.json', 'LOGGER_MSG_FILE': 'tests/def/mfaUtilsLoggingHelper/config_MessageList.toml'}, 'input_file_path': {'UPDATE_EXCEL_PATH': 'tests/share/receive'}, 'output_file_path': {'SEND_REFFERENCE_MASTER_PATH': 'tests/share/receive'}}, package_config={'test': {'local_test': 'test'}}, log_message=<bound method LoggerPackage.log_message of <src.lib.common_utils.ibr_logger_package.LoggerPackage object at 0x7f2d8324aa90>>):
2024-01-22 23:22:13 [DEBUG] common_utils - test_mutex_manager_UT_C0_normal_multiprocess line 266: 
        - テスト関数: test_mutex_manager_UT_C0_normal_multiprocess, test_processmanager_UT_C0_normal, test_processmanager_enter_UT_C0_exception, test_processmanager_enter_UT_C0_oserror, test_processmanager_exit_UT_C0_delete_file_error_exception, test_processmanager_exit_UT_C0_exception
        - テスト定義:
                - テストカテゴリ: C0
                - テスト区分: 正常系/UT
                - テストシナリオ:
        :
2024-01-22 23:22:35 [DEBUG] common_utils - <module> line 40: Config(env='local', common_config={'logger_path': {'LOGGER_DEF_FILE': 'tests/def/mfaUtilsLoggingHelper/logging_TimedRotate.json', 'LOGGER_MSG_FILE': 'tests/def/mfaUtilsLoggingHelper/config_MessageList.toml'}, 'input_file_path': {'UPDATE_EXCEL_PATH': 'tests/share/receive'}, 'output_file_path': {'SEND_REFFERENCE_MASTER_PATH': 'tests/share/receive'}}, package_config={'test': {'local_test': 'test'}}, log_message=<bound method LoggerPackage.log_message of <src.lib.common_utils.ibr_logger_package.LoggerPackage object at 0x7f8417854c90>>):
2024-01-22 23:22:35 [DEBUG] common_utils - test_mutex_manager_UT_C0_normal_multiprocess line 266: 
        - テスト関数: test_mutex_manager_UT_C0_normal_multiprocess, test_processmanager_UT_C0_normal, test_processmanager_enter_UT_C0_exception, test_processmanager_enter_UT_C0_oserror, test_processmanager_exit_UT_C0_delete_file_error_exception, test_processmanager_exit_UT_C0_exception
        - テスト定義:
                - テストカテゴリ: C0
                - テスト区分: 正常系/UT
                - テストシナリオ:
        :
2024-01-22 23:24:49 [DEBUG] common_utils - <module> line 40: Config(env='local', common_config={'logger_path': {'LOGGER_DEF_FILE': 'tests/def/mfaUtilsLoggingHelper/logging_TimedRotate.json', 'LOGGER_MSG_FILE': 'tests/def/mfaUtilsLoggingHelper/config_MessageList.toml'}, 'input_file_path': {'UPDATE_EXCEL_PATH': 'tests/share/receive'}, 'output_file_path': {'SEND_REFFERENCE_MASTER_PATH': 'tests/share/receive'}}, package_config={'test': {'local_test': 'test'}}, log_message=<bound method LoggerPackage.log_message of <src.lib.common_utils.ibr_logger_package.LoggerPackage object at 0x7fa836664d90>>):
2024-01-22 23:24:49 [DEBUG] common_utils - test_mutex_manager_UT_C0_normal_multiprocess line 266: 
        - テスト関数: test_mutex_manager_UT_C0_normal_multiprocess, test_processmanager_UT_C0_normal, test_processmanager_enter_UT_C0_exception, test_processmanager_enter_UT_C0_oserror, test_processmanager_exit_UT_C0_delete_file_error_exception, test_processmanager_exit_UT_C0_exception
        - テスト定義:
                - テストカテゴリ: C0
                - テスト区分: 正常系/UT
                - テストシナリオ:
        :
2024-01-22 23:24:49 [ERROR] common_utils - __enter__ line 80: already runnning: test_package:
2024-01-22 23:26:13 [DEBUG] common_utils - <module> line 40: Config(env='local', common_config={'logger_path': {'LOGGER_DEF_FILE': 'tests/def/mfaUtilsLoggingHelper/logging_TimedRotate.json', 'LOGGER_MSG_FILE': 'tests/def/mfaUtilsLoggingHelper/config_MessageList.toml'}, 'input_file_path': {'UPDATE_EXCEL_PATH': 'tests/share/receive'}, 'output_file_path': {'SEND_REFFERENCE_MASTER_PATH': 'tests/share/receive'}}, package_config={'test': {'local_test': 'test'}}, log_message=<bound method LoggerPackage.log_message of <src.lib.common_utils.ibr_logger_package.LoggerPackage object at 0x7f62f46157d0>>):
2024-01-22 23:26:13 [DEBUG] common_utils - test_mutex_manager_UT_C0_normal_multiprocess line 266: 
        - テスト関数: test_mutex_manager_UT_C0_normal_multiprocess, test_processmanager_UT_C0_normal, test_processmanager_enter_UT_C0_exception, test_processmanager_enter_UT_C0_oserror, test_processmanager_exit_UT_C0_delete_file_error_exception, test_processmanager_exit_UT_C0_exception
        - テスト定義:
                - テストカテゴリ: C0
                - テスト区分: 正常系/UT
                - テストシナリオ:
        :
2024-01-22 23:26:13 [ERROR] common_utils - __enter__ line 80: already runnning: test_package:
2024-01-22 23:28:49 [DEBUG] common_utils - <module> line 40: Config(env='local', common_config={'logger_path': {'LOGGER_DEF_FILE': 'tests/def/mfaUtilsLoggingHelper/logging_TimedRotate.json', 'LOGGER_MSG_FILE': 'tests/def/mfaUtilsLoggingHelper/config_MessageList.toml'}, 'input_file_path': {'UPDATE_EXCEL_PATH': 'tests/share/receive'}, 'output_file_path': {'SEND_REFFERENCE_MASTER_PATH': 'tests/share/receive'}}, package_config={'test': {'local_test': 'test'}}, log_message=<bound method LoggerPackage.log_message of <src.lib.common_utils.ibr_logger_package.LoggerPackage object at 0x7f26588cd590>>):
2024-01-22 23:28:49 [DEBUG] common_utils - test_mutex_manager_UT_C0_normal_multiprocess line 266: 
        - テスト関数: test_mutex_manager_UT_C0_normal_multiprocess, test_processmanager_UT_C0_normal, test_processmanager_enter_UT_C0_exception, test_processmanager_enter_UT_C0_oserror, test_processmanager_exit_UT_C0_delete_file_error_exception, test_processmanager_exit_UT_C0_exception
        - テスト定義:
                - テストカテゴリ: C0
                - テスト区分: 正常系/UT
                - テストシナリオ:
        :
2024-01-22 23:28:49 [ERROR] common_utils - __enter__ line 80: already runnning: test_package:
2024-01-22 23:29:32 [DEBUG] common_utils - <module> line 40: Config(env='local', common_config={'logger_path': {'LOGGER_DEF_FILE': 'tests/def/mfaUtilsLoggingHelper/logging_TimedRotate.json', 'LOGGER_MSG_FILE': 'tests/def/mfaUtilsLoggingHelper/config_MessageList.toml'}, 'input_file_path': {'UPDATE_EXCEL_PATH': 'tests/share/receive'}, 'output_file_path': {'SEND_REFFERENCE_MASTER_PATH': 'tests/share/receive'}}, package_config={'test': {'local_test': 'test'}}, log_message=<bound method LoggerPackage.log_message of <src.lib.common_utils.ibr_logger_package.LoggerPackage object at 0x7f4e001b5550>>):
2024-01-22 23:29:32 [DEBUG] common_utils - test_mutex_manager_UT_C0_normal_multiprocess line 266: 
        - テスト関数: test_mutex_manager_UT_C0_normal_multiprocess, test_processmanager_UT_C0_normal, test_processmanager_enter_UT_C0_exception, test_processmanager_enter_UT_C0_oserror, test_processmanager_exit_UT_C0_delete_file_error_exception, test_processmanager_exit_UT_C0_exception
        - テスト定義:
                - テストカテゴリ: C0
                - テスト区分: 正常系/UT
                - テストシナリオ:
        :
2024-01-22 23:29:32 [ERROR] common_utils - __enter__ line 80: already runnning: test_package:
2024-01-22 23:32:05 [DEBUG] common_utils - <module> line 40: Config(env='local', common_config={'logger_path': {'LOGGER_DEF_FILE': 'tests/def/mfaUtilsLoggingHelper/logging_TimedRotate.json', 'LOGGER_MSG_FILE': 'tests/def/mfaUtilsLoggingHelper/config_MessageList.toml'}, 'input_file_path': {'UPDATE_EXCEL_PATH': 'tests/share/receive'}, 'output_file_path': {'SEND_REFFERENCE_MASTER_PATH': 'tests/share/receive'}}, package_config={'test': {'local_test': 'test'}}, log_message=<bound method LoggerPackage.log_message of <src.lib.common_utils.ibr_logger_package.LoggerPackage object at 0x7f0e8379a150>>):
2024-01-22 23:32:05 [DEBUG] common_utils - test_mutex_manager_UT_C0_normal_multiprocess line 272: 
        - テスト関数: test_mutex_manager_UT_C0_normal_multiprocess, test_processmanager_UT_C0_normal, test_processmanager_enter_UT_C0_exception, test_processmanager_enter_UT_C0_oserror, test_processmanager_exit_UT_C0_delete_file_error_exception, test_processmanager_exit_UT_C0_exception
        - テスト定義:
                - テストカテゴリ: C0
                - テスト区分: 正常系/UT
                - テストシナリオ: 複数起動してalready runningの検出を確認する
                    multiprocessing と caplog を直接組み合わせて使用することはできません。
                    なぜなら、multiprocessing は新しいプロセスを作成しそれぞれのプロセスは
                    独自のメモリ空間を持つためメインプロセスの caplog フィクスチャに
                    アクセスできないからです。
                    この問題を解決するためには、multiprocessing の代わりに
                    threading モジュールを使用しています。
        :
2024-01-22 23:32:05 [ERROR] common_utils - __enter__ line 80: already runnning: test_package:
