2024-09-11 21:47:06 [INFO] validator_excel_main_class-2 - start line 136: IBRDEV-I-0000001:起動しました
2024-09-11 21:47:06 [DEBUG] common_utils - tabulate_dataframe line 67: 
|    |   NO | あ   | い   |   う | え   | お   |   か | き   |   く |   け |   こ |
|---:|-----:|:-----|:-----|-----:|:-----|:-----|-----:|:-----|-----:|-----:|-----:|
|  0 |    1 | a    | d    |    1 | 4    | あ   |   10 | 1    |   13 |   16 |   19 |
|  1 |    2 | b    | e    |    2 | s    | 8    |   11 | h    |   14 |   17 |   20 |
|  2 |    3 | c    | f    |    3 | 6    | 9    |   12 | I    |   15 |   18 |   21 |:
2024-09-11 21:47:06 [DEBUG] common_utils - read_excel_one_sheet line 99: 
Sheet_name: Sheet1
|    |   NO | あ   | い   |   う | え   | お   |   か | き   |   く |   け |   こ |
|---:|-----:|:-----|:-----|-----:|:-----|:-----|-----:|:-----|-----:|-----:|-----:|
|  0 |    1 | a    | d    |    1 | 4    | あ   |   10 | 1    |   13 |   16 |   19 |
|  1 |    2 | b    | e    |    2 | s    | 8    |   11 | h    |   14 |   17 |   20 |
|  2 |    3 | c    | f    |    3 | 6    | 9    |   12 | I    |   15 |   18 |   21 |:
2024-09-11 21:47:06 [DEBUG] common_utils - tabulate_dataframe line 67: 
|    | Columns   | Type   |
|---:|:----------|:-------|
|  0 | NO        | int64  |
|  1 | あ        | object |
|  2 | い        | object |
|  3 | う        | int64  |
|  4 | え        | object |
|  5 | お        | object |
|  6 | か        | int64  |
|  7 | き        | object |
|  8 | く        | int64  |
|  9 | け        | int64  |
| 10 | こ        | int64  |:
2024-09-11 21:47:06 [INFO] validator_excel_main_class-2 - _log_dataframe_info line 66: DataFrame info:
|    | Columns   | Type   |
|---:|:----------|:-------|
|  0 | NO        | int64  |
|  1 | あ        | object |
|  2 | い        | object |
|  3 | う        | int64  |
|  4 | え        | object |
|  5 | お        | object |
|  6 | か        | int64  |
|  7 | き        | object |
|  8 | く        | int64  |
|  9 | け        | int64  |
| 10 | こ        | int64  |:
2024-09-11 21:47:06 [WARNING] validator_utils - log_errors line 31: Validation error at row 0: {'type': 'int_type', 'loc': ('お',), 'msg': 'Input should be a valid integer', 'input': 'あ', 'url': 'https://errors.pydantic.dev/2.5/v/int_type'}:
2024-09-11 21:47:06 [WARNING] validator_utils - log_errors line 31: Validation error at row 0: {'type': 'string_type', 'loc': ('き',), 'msg': 'Input should be a valid string', 'input': 1, 'url': 'https://errors.pydantic.dev/2.5/v/string_type'}:
2024-09-11 21:47:06 [WARNING] validator_utils - log_errors line 31: Validation error at row 1: {'type': 'int_type', 'loc': ('え',), 'msg': 'Input should be a valid integer', 'input': 's', 'url': 'https://errors.pydantic.dev/2.5/v/int_type'}:
2024-09-11 21:47:06 [WARNING] validator_excel_main_class-2 - start line 142: Process completed with 2 validation errors:
2024-09-11 21:47:06 [INFO] validator_excel_main_class-2 - start line 152: IBRDEV-I-0000002:正常終了しました
2024-09-11 22:01:12 [INFO] validator_excel_main_class-2 - start line 145: IBRDEV-I-0000001:起動しました
2024-09-11 22:01:12 [DEBUG] common_utils - tabulate_dataframe line 67: 
|    |   NO | あ   | い   |   う | え   | お   |   か | き   |   く |   け |   こ |
|---:|-----:|:-----|:-----|-----:|:-----|:-----|-----:|:-----|-----:|-----:|-----:|
|  0 |    1 | a    | d    |    1 | 4    | あ   |   10 | 1    |   13 |   16 |   19 |
|  1 |    2 | b    | e    |    2 | s    | 8    |   11 | h    |   14 |   17 |   20 |
|  2 |    3 | c    | f    |    3 | 6    | 9    |   12 | I    |   15 |   18 |   21 |:
2024-09-11 22:01:12 [DEBUG] common_utils - read_excel_one_sheet line 99: 
Sheet_name: Sheet1
|    |   NO | あ   | い   |   う | え   | お   |   か | き   |   く |   け |   こ |
|---:|-----:|:-----|:-----|-----:|:-----|:-----|-----:|:-----|-----:|-----:|-----:|
|  0 |    1 | a    | d    |    1 | 4    | あ   |   10 | 1    |   13 |   16 |   19 |
|  1 |    2 | b    | e    |    2 | s    | 8    |   11 | h    |   14 |   17 |   20 |
|  2 |    3 | c    | f    |    3 | 6    | 9    |   12 | I    |   15 |   18 |   21 |:
2024-09-11 22:01:12 [DEBUG] common_utils - tabulate_dataframe line 67: 
|    | Columns   | Type   |
|---:|:----------|:-------|
|  0 | NO        | int64  |
|  1 | あ        | object |
|  2 | い        | object |
|  3 | う        | int64  |
|  4 | え        | object |
|  5 | お        | object |
|  6 | か        | int64  |
|  7 | き        | object |
|  8 | く        | int64  |
|  9 | け        | int64  |
| 10 | こ        | int64  |:
2024-09-11 22:01:12 [INFO] validator_excel_main_class-2 - _log_dataframe_info line 68: DataFrame info:
|    | Columns   | Type   |
|---:|:----------|:-------|
|  0 | NO        | int64  |
|  1 | あ        | object |
|  2 | い        | object |
|  3 | う        | int64  |
|  4 | え        | object |
|  5 | お        | object |
|  6 | か        | int64  |
|  7 | き        | object |
|  8 | く        | int64  |
|  9 | け        | int64  |
| 10 | こ        | int64  |:
2024-09-11 22:01:12 [WARNING] validator_utils - log_errors line 31: Validation error at row 0: {'type': 'int_type', 'loc': ('お',), 'msg': 'Input should be a valid integer', 'input': 'あ', 'url': 'https://errors.pydantic.dev/2.5/v/int_type'}:
2024-09-11 22:01:12 [WARNING] validator_utils - log_errors line 31: Validation error at row 0: {'type': 'string_type', 'loc': ('き',), 'msg': 'Input should be a valid string', 'input': 1, 'url': 'https://errors.pydantic.dev/2.5/v/string_type'}:
2024-09-11 22:01:12 [WARNING] validator_utils - log_errors line 31: Validation error at row 1: {'type': 'int_type', 'loc': ('え',), 'msg': 'Input should be a valid integer', 'input': 's', 'url': 'https://errors.pydantic.dev/2.5/v/int_type'}:
2024-09-11 22:01:12 [WARNING] validator_excel_main_class-2 - start line 151: Process completed with 2 validation errors:
2024-09-11 22:01:12 [INFO] validator_excel_main_class-2 - start line 161: IBRDEV-I-0000002:正常終了しました
2024-09-11 22:04:49 [ERROR] common_utils - parse_toml_file line 55: can not get target files [Errno 2] No such file or directory: 'package_config.toml':
2024-09-11 22:04:49 [ERROR] common_utils - load line 138: package_config取得に失敗しました: [Errno 2] No such file or directory: 'package_config.toml':
2024-09-11 22:04:49 [ERROR] common_utils - load line 140: Traceback (most recent call last):
  File "/developer/library_dev3/library-develop/library-dev/project_1/src/lib/common_utils/ibr_get_config.py", line 136, in load
    package_config = TomlParser.parse_toml_file(package_toml_path)
                     ^^^^^^^^^^^^^^^^^^^^^^^^^^^^^^^^^^^^^^^^^^^^^
  File "/developer/library_dev3/library-develop/library-dev/project_1/src/lib/common_utils/ibr_toml_loader.py", line 52, in parse_toml_file
    with toml_path.open(mode='r', encoding='utf8') as f:
         ^^^^^^^^^^^^^^^^^^^^^^^^^^^^^^^^^^^^^^^^^
  File "/home/satoshi/.pyenv/versions/3.11.6/lib/python3.11/pathlib.py", line 1044, in open
    return io.open(self, mode, buffering, encoding, errors, newline)
           ^^^^^^^^^^^^^^^^^^^^^^^^^^^^^^^^^^^^^^^^^^^^^^^^^^^^^^^^^
FileNotFoundError: [Errno 2] No such file or directory: 'package_config.toml'
:
2024-09-11 22:05:35 [ERROR] common_utils - parse_toml_file line 55: can not get target files [Errno 2] No such file or directory: 'package_config.toml':
2024-09-11 22:05:35 [ERROR] common_utils - load line 138: package_config取得に失敗しました: [Errno 2] No such file or directory: 'package_config.toml':
2024-09-11 22:05:35 [ERROR] common_utils - load line 140: Traceback (most recent call last):
  File "/developer/library_dev3/library-develop/library-dev/project_1/src/lib/common_utils/ibr_get_config.py", line 136, in load
    package_config = TomlParser.parse_toml_file(package_toml_path)
                     ^^^^^^^^^^^^^^^^^^^^^^^^^^^^^^^^^^^^^^^^^^^^^
  File "/developer/library_dev3/library-develop/library-dev/project_1/src/lib/common_utils/ibr_toml_loader.py", line 52, in parse_toml_file
    with toml_path.open(mode='r', encoding='utf8') as f:
         ^^^^^^^^^^^^^^^^^^^^^^^^^^^^^^^^^^^^^^^^^
  File "/home/satoshi/.pyenv/versions/3.11.6/lib/python3.11/pathlib.py", line 1044, in open
    return io.open(self, mode, buffering, encoding, errors, newline)
           ^^^^^^^^^^^^^^^^^^^^^^^^^^^^^^^^^^^^^^^^^^^^^^^^^^^^^^^^^
FileNotFoundError: [Errno 2] No such file or directory: 'package_config.toml'
:
2024-09-11 22:07:31 [ERROR] common_utils - parse_toml_file line 55: can not get target files [Errno 2] No such file or directory: 'package_config.toml':
2024-09-11 22:07:31 [ERROR] common_utils - load line 138: package_config取得に失敗しました: [Errno 2] No such file or directory: 'package_config.toml':
2024-09-11 22:07:31 [ERROR] common_utils - load line 140: Traceback (most recent call last):
  File "/developer/library_dev3/library-develop/library-dev/project_1/src/lib/common_utils/ibr_get_config.py", line 136, in load
    package_config = TomlParser.parse_toml_file(package_toml_path)
                     ^^^^^^^^^^^^^^^^^^^^^^^^^^^^^^^^^^^^^^^^^^^^^
  File "/developer/library_dev3/library-develop/library-dev/project_1/src/lib/common_utils/ibr_toml_loader.py", line 52, in parse_toml_file
    with toml_path.open(mode='r', encoding='utf8') as f:
         ^^^^^^^^^^^^^^^^^^^^^^^^^^^^^^^^^^^^^^^^^
  File "/home/satoshi/.pyenv/versions/3.11.6/lib/python3.11/pathlib.py", line 1044, in open
    return io.open(self, mode, buffering, encoding, errors, newline)
           ^^^^^^^^^^^^^^^^^^^^^^^^^^^^^^^^^^^^^^^^^^^^^^^^^^^^^^^^^
FileNotFoundError: [Errno 2] No such file or directory: 'package_config.toml'
:
2024-09-11 22:13:50 [ERROR] common_utils - parse_toml_file line 55: can not get target files [Errno 2] No such file or directory: '/developer/library_dev3/library-develop/library-dev/project_1/src/lib/common_utils/package_config.toml':
2024-09-11 22:13:50 [ERROR] common_utils - load line 138: package_config取得に失敗しました: [Errno 2] No such file or directory: '/developer/library_dev3/library-develop/library-dev/project_1/src/lib/common_utils/package_config.toml':
2024-09-11 22:13:50 [ERROR] common_utils - load line 140: Traceback (most recent call last):
  File "/developer/library_dev3/library-develop/library-dev/project_1/src/lib/common_utils/ibr_get_config.py", line 136, in load
    package_config = TomlParser.parse_toml_file(package_toml_path)
                     ^^^^^^^^^^^^^^^^^^^^^^^^^^^^^^^^^^^^^^^^^^^^^
  File "/developer/library_dev3/library-develop/library-dev/project_1/src/lib/common_utils/ibr_toml_loader.py", line 52, in parse_toml_file
    with toml_path.open(mode='r', encoding='utf8') as f:
         ^^^^^^^^^^^^^^^^^^^^^^^^^^^^^^^^^^^^^^^^^
  File "/home/satoshi/.pyenv/versions/3.11.6/lib/python3.11/pathlib.py", line 1044, in open
    return io.open(self, mode, buffering, encoding, errors, newline)
           ^^^^^^^^^^^^^^^^^^^^^^^^^^^^^^^^^^^^^^^^^^^^^^^^^^^^^^^^^
FileNotFoundError: [Errno 2] No such file or directory: '/developer/library_dev3/library-develop/library-dev/project_1/src/lib/common_utils/package_config.toml'
:
2024-09-11 22:19:23 [INFO] validator_excel_main_class-2 - start line 144: IBRDEV-I-0000001:起動しました
2024-09-11 22:19:23 [DEBUG] common_utils - tabulate_dataframe line 67: 
|    |   NO | あ   | い   |   う | え   | お   |   か | き   |   く |   け |   こ |
|---:|-----:|:-----|:-----|-----:|:-----|:-----|-----:|:-----|-----:|-----:|-----:|
|  0 |    1 | a    | d    |    1 | 4    | あ   |   10 | 1    |   13 |   16 |   19 |
|  1 |    2 | b    | e    |    2 | s    | 8    |   11 | h    |   14 |   17 |   20 |
|  2 |    3 | c    | f    |    3 | 6    | 9    |   12 | I    |   15 |   18 |   21 |:
2024-09-11 22:19:23 [DEBUG] common_utils - read_excel_one_sheet line 99: 
Sheet_name: Sheet1
|    |   NO | あ   | い   |   う | え   | お   |   か | き   |   く |   け |   こ |
|---:|-----:|:-----|:-----|-----:|:-----|:-----|-----:|:-----|-----:|-----:|-----:|
|  0 |    1 | a    | d    |    1 | 4    | あ   |   10 | 1    |   13 |   16 |   19 |
|  1 |    2 | b    | e    |    2 | s    | 8    |   11 | h    |   14 |   17 |   20 |
|  2 |    3 | c    | f    |    3 | 6    | 9    |   12 | I    |   15 |   18 |   21 |:
2024-09-11 22:19:23 [DEBUG] common_utils - tabulate_dataframe line 67: 
|    | Columns   | Type   |
|---:|:----------|:-------|
|  0 | NO        | int64  |
|  1 | あ        | object |
|  2 | い        | object |
|  3 | う        | int64  |
|  4 | え        | object |
|  5 | お        | object |
|  6 | か        | int64  |
|  7 | き        | object |
|  8 | く        | int64  |
|  9 | け        | int64  |
| 10 | こ        | int64  |:
2024-09-11 22:19:23 [INFO] validator_excel_main_class-2 - _log_dataframe_info line 68: DataFrame info:
|    | Columns   | Type   |
|---:|:----------|:-------|
|  0 | NO        | int64  |
|  1 | あ        | object |
|  2 | い        | object |
|  3 | う        | int64  |
|  4 | え        | object |
|  5 | お        | object |
|  6 | か        | int64  |
|  7 | き        | object |
|  8 | く        | int64  |
|  9 | け        | int64  |
| 10 | こ        | int64  |:
2024-09-11 22:19:23 [WARNING] validator_utils - log_errors line 31: Validation error at row 0: {'type': 'int_type', 'loc': ('お',), 'msg': 'Input should be a valid integer', 'input': 'あ', 'url': 'https://errors.pydantic.dev/2.5/v/int_type'}:
2024-09-11 22:19:23 [WARNING] validator_utils - log_errors line 31: Validation error at row 0: {'type': 'string_type', 'loc': ('き',), 'msg': 'Input should be a valid string', 'input': 1, 'url': 'https://errors.pydantic.dev/2.5/v/string_type'}:
2024-09-11 22:19:23 [WARNING] validator_utils - log_errors line 31: Validation error at row 1: {'type': 'int_type', 'loc': ('え',), 'msg': 'Input should be a valid integer', 'input': 's', 'url': 'https://errors.pydantic.dev/2.5/v/int_type'}:
2024-09-11 22:19:23 [WARNING] validator_excel_main_class-2 - start line 150: Process completed with 2 validation errors:
2024-09-11 22:19:23 [INFO] validator_excel_main_class-2 - start line 160: IBRDEV-I-0000002:正常終了しました
2024-09-11 22:33:15 [INFO] validator_excel_main_class-2 - start line 151: IBRDEV-I-0000001:起動しました
2024-09-11 22:33:15 [DEBUG] common_utils - tabulate_dataframe line 67: 
|    |   NO | あ   | い   |   う | え   | お   |   か | き   |   く |   け |   こ |
|---:|-----:|:-----|:-----|-----:|:-----|:-----|-----:|:-----|-----:|-----:|-----:|
|  0 |    1 | a    | d    |    1 | 4    | あ   |   10 | 1    |   13 |   16 |   19 |
|  1 |    2 | b    | e    |    2 | s    | 8    |   11 | h    |   14 |   17 |   20 |
|  2 |    3 | c    | f    |    3 | 6    | 9    |   12 | I    |   15 |   18 |   21 |:
2024-09-11 22:33:15 [DEBUG] common_utils - read_excel_one_sheet line 99: 
Sheet_name: Sheet1
|    |   NO | あ   | い   |   う | え   | お   |   か | き   |   く |   け |   こ |
|---:|-----:|:-----|:-----|-----:|:-----|:-----|-----:|:-----|-----:|-----:|-----:|
|  0 |    1 | a    | d    |    1 | 4    | あ   |   10 | 1    |   13 |   16 |   19 |
|  1 |    2 | b    | e    |    2 | s    | 8    |   11 | h    |   14 |   17 |   20 |
|  2 |    3 | c    | f    |    3 | 6    | 9    |   12 | I    |   15 |   18 |   21 |:
2024-09-11 22:33:15 [DEBUG] common_utils - tabulate_dataframe line 67: 
|    | Columns   | Type   |
|---:|:----------|:-------|
|  0 | NO        | int64  |
|  1 | あ        | object |
|  2 | い        | object |
|  3 | う        | int64  |
|  4 | え        | object |
|  5 | お        | object |
|  6 | か        | int64  |
|  7 | き        | object |
|  8 | く        | int64  |
|  9 | け        | int64  |
| 10 | こ        | int64  |:
2024-09-11 22:33:15 [INFO] validator_excel_main_class-2 - _log_dataframe_info line 71: DataFrame info:
|    | Columns   | Type   |
|---:|:----------|:-------|
|  0 | NO        | int64  |
|  1 | あ        | object |
|  2 | い        | object |
|  3 | う        | int64  |
|  4 | え        | object |
|  5 | お        | object |
|  6 | か        | int64  |
|  7 | き        | object |
|  8 | く        | int64  |
|  9 | け        | int64  |
| 10 | こ        | int64  |:
2024-09-11 22:33:15 [WARNING] validator_utils - log_errors line 31: Validation error at row 0: {'type': 'int_type', 'loc': ('お',), 'msg': 'Input should be a valid integer', 'input': 'あ', 'url': 'https://errors.pydantic.dev/2.5/v/int_type'}:
2024-09-11 22:33:15 [WARNING] validator_utils - log_errors line 31: Validation error at row 0: {'type': 'string_type', 'loc': ('き',), 'msg': 'Input should be a valid string', 'input': 1, 'url': 'https://errors.pydantic.dev/2.5/v/string_type'}:
2024-09-11 22:33:15 [WARNING] validator_utils - log_errors line 31: Validation error at row 1: {'type': 'int_type', 'loc': ('え',), 'msg': 'Input should be a valid integer', 'input': 's', 'url': 'https://errors.pydantic.dev/2.5/v/int_type'}:
2024-09-11 22:33:15 [WARNING] validator_excel_main_class-2 - start line 157: Process completed with 2 validation errors:
2024-09-11 22:33:15 [INFO] validator_excel_main_class-2 - start line 167: IBRDEV-I-0000002:正常終了しました
2024-09-11 22:50:20 [INFO] validator_excel_main_class-2 - start line 153: IBRDEV-I-0000001:起動しました
2024-09-11 22:50:21 [DEBUG] common_utils - tabulate_dataframe line 67: 
|    |   NO | あ   | い   |   う | え   | お   |   か | き   |   く |   け |   こ |
|---:|-----:|:-----|:-----|-----:|:-----|:-----|-----:|:-----|-----:|-----:|-----:|
|  0 |    1 | a    | d    |    1 | 4    | あ   |   10 | 1    |   13 |   16 |   19 |
|  1 |    2 | b    | e    |    2 | s    | 8    |   11 | h    |   14 |   17 |   20 |
|  2 |    3 | c    | f    |    3 | 6    | 9    |   12 | I    |   15 |   18 |   21 |:
2024-09-11 22:50:21 [DEBUG] common_utils - read_excel_one_sheet line 99: 
Sheet_name: Sheet1
|    |   NO | あ   | い   |   う | え   | お   |   か | き   |   く |   け |   こ |
|---:|-----:|:-----|:-----|-----:|:-----|:-----|-----:|:-----|-----:|-----:|-----:|
|  0 |    1 | a    | d    |    1 | 4    | あ   |   10 | 1    |   13 |   16 |   19 |
|  1 |    2 | b    | e    |    2 | s    | 8    |   11 | h    |   14 |   17 |   20 |
|  2 |    3 | c    | f    |    3 | 6    | 9    |   12 | I    |   15 |   18 |   21 |:
2024-09-11 22:50:21 [DEBUG] common_utils - tabulate_dataframe line 67: 
|    | Columns   | Type   |
|---:|:----------|:-------|
|  0 | NO        | int64  |
|  1 | あ        | object |
|  2 | い        | object |
|  3 | う        | int64  |
|  4 | え        | object |
|  5 | お        | object |
|  6 | か        | int64  |
|  7 | き        | object |
|  8 | く        | int64  |
|  9 | け        | int64  |
| 10 | こ        | int64  |:
2024-09-11 22:50:21 [INFO] validator_excel_main_class-2 - _log_dataframe_info line 71: DataFrame info:
|    | Columns   | Type   |
|---:|:----------|:-------|
|  0 | NO        | int64  |
|  1 | あ        | object |
|  2 | い        | object |
|  3 | う        | int64  |
|  4 | え        | object |
|  5 | お        | object |
|  6 | か        | int64  |
|  7 | き        | object |
|  8 | く        | int64  |
|  9 | け        | int64  |
| 10 | こ        | int64  |:
2024-09-11 22:50:21 [WARNING] validator_utils - log_errors line 31: Validation error at row 0: {'type': 'int_type', 'loc': ('お',), 'msg': 'Input should be a valid integer', 'input': 'あ', 'url': 'https://errors.pydantic.dev/2.5/v/int_type'}:
2024-09-11 22:50:21 [WARNING] validator_utils - log_errors line 31: Validation error at row 0: {'type': 'string_type', 'loc': ('き',), 'msg': 'Input should be a valid string', 'input': 1, 'url': 'https://errors.pydantic.dev/2.5/v/string_type'}:
2024-09-11 22:50:21 [WARNING] validator_utils - log_errors line 31: Validation error at row 1: {'type': 'int_type', 'loc': ('え',), 'msg': 'Input should be a valid integer', 'input': 's', 'url': 'https://errors.pydantic.dev/2.5/v/int_type'}:
2024-09-11 22:50:21 [WARNING] validator_excel_main_class-2 - start line 159: Process completed with 2 validation errors:
2024-09-11 22:50:21 [INFO] validator_excel_main_class-2 - start line 169: IBRDEV-I-0000002:正常終了しました
2024-09-11 22:51:40 [INFO] validator_excel_main_class-2 - start line 153: IBRDEV-I-0000001:起動しました
2024-09-11 22:51:40 [DEBUG] common_utils - tabulate_dataframe line 67: 
|    |   NO | あ   | い   |   う | え   | お   |   か | き   |   く |   け |   こ |
|---:|-----:|:-----|:-----|-----:|:-----|:-----|-----:|:-----|-----:|-----:|-----:|
|  0 |    1 | a    | d    |    1 | 4    | あ   |   10 | 1    |   13 |   16 |   19 |
|  1 |    2 | b    | e    |    2 | s    | 8    |   11 | h    |   14 |   17 |   20 |
|  2 |    3 | c    | f    |    3 | 6    | 9    |   12 | I    |   15 |   18 |   21 |:
2024-09-11 22:51:40 [DEBUG] common_utils - read_excel_one_sheet line 99: 
Sheet_name: Sheet1
|    |   NO | あ   | い   |   う | え   | お   |   か | き   |   く |   け |   こ |
|---:|-----:|:-----|:-----|-----:|:-----|:-----|-----:|:-----|-----:|-----:|-----:|
|  0 |    1 | a    | d    |    1 | 4    | あ   |   10 | 1    |   13 |   16 |   19 |
|  1 |    2 | b    | e    |    2 | s    | 8    |   11 | h    |   14 |   17 |   20 |
|  2 |    3 | c    | f    |    3 | 6    | 9    |   12 | I    |   15 |   18 |   21 |:
2024-09-11 22:51:40 [DEBUG] common_utils - tabulate_dataframe line 67: 
|    | Columns   | Type   |
|---:|:----------|:-------|
|  0 | NO        | int64  |
|  1 | あ        | object |
|  2 | い        | object |
|  3 | う        | int64  |
|  4 | え        | object |
|  5 | お        | object |
|  6 | か        | int64  |
|  7 | き        | object |
|  8 | く        | int64  |
|  9 | け        | int64  |
| 10 | こ        | int64  |:
2024-09-11 22:51:40 [INFO] validator_excel_main_class-2 - _log_dataframe_info line 71: DataFrame info:
|    | Columns   | Type   |
|---:|:----------|:-------|
|  0 | NO        | int64  |
|  1 | あ        | object |
|  2 | い        | object |
|  3 | う        | int64  |
|  4 | え        | object |
|  5 | お        | object |
|  6 | か        | int64  |
|  7 | き        | object |
|  8 | く        | int64  |
|  9 | け        | int64  |
| 10 | こ        | int64  |:
2024-09-11 22:51:40 [WARNING] validator_utils - log_errors line 31: Validation error at row 0: {'type': 'int_type', 'loc': ('お',), 'msg': 'Input should be a valid integer', 'input': 'あ', 'url': 'https://errors.pydantic.dev/2.5/v/int_type'}:
2024-09-11 22:51:40 [WARNING] validator_utils - log_errors line 31: Validation error at row 0: {'type': 'string_type', 'loc': ('き',), 'msg': 'Input should be a valid string', 'input': 1, 'url': 'https://errors.pydantic.dev/2.5/v/string_type'}:
2024-09-11 22:51:40 [WARNING] validator_utils - log_errors line 31: Validation error at row 1: {'type': 'int_type', 'loc': ('え',), 'msg': 'Input should be a valid integer', 'input': 's', 'url': 'https://errors.pydantic.dev/2.5/v/int_type'}:
2024-09-11 22:51:40 [WARNING] validator_excel_main_class-2 - start line 159: Process completed with 2 validation errors:
2024-09-11 22:51:40 [INFO] validator_excel_main_class-2 - start line 169: IBRDEV-I-0000002:正常終了しました
2024-09-11 22:52:18 [INFO] validator_excel_main_class-2 - start line 154: IBRDEV-I-0000001:起動しました
2024-09-11 22:52:18 [DEBUG] common_utils - tabulate_dataframe line 67: 
|    |   NO | あ   | い   |   う | え   | お   |   か | き   |   く |   け |   こ |
|---:|-----:|:-----|:-----|-----:|:-----|:-----|-----:|:-----|-----:|-----:|-----:|
|  0 |    1 | a    | d    |    1 | 4    | あ   |   10 | 1    |   13 |   16 |   19 |
|  1 |    2 | b    | e    |    2 | s    | 8    |   11 | h    |   14 |   17 |   20 |
|  2 |    3 | c    | f    |    3 | 6    | 9    |   12 | I    |   15 |   18 |   21 |:
2024-09-11 22:52:18 [DEBUG] common_utils - read_excel_one_sheet line 99: 
Sheet_name: Sheet1
|    |   NO | あ   | い   |   う | え   | お   |   か | き   |   く |   け |   こ |
|---:|-----:|:-----|:-----|-----:|:-----|:-----|-----:|:-----|-----:|-----:|-----:|
|  0 |    1 | a    | d    |    1 | 4    | あ   |   10 | 1    |   13 |   16 |   19 |
|  1 |    2 | b    | e    |    2 | s    | 8    |   11 | h    |   14 |   17 |   20 |
|  2 |    3 | c    | f    |    3 | 6    | 9    |   12 | I    |   15 |   18 |   21 |:
2024-09-11 22:52:18 [DEBUG] common_utils - tabulate_dataframe line 67: 
|    | Columns   | Type   |
|---:|:----------|:-------|
|  0 | NO        | int64  |
|  1 | あ        | object |
|  2 | い        | object |
|  3 | う        | int64  |
|  4 | え        | object |
|  5 | お        | object |
|  6 | か        | int64  |
|  7 | き        | object |
|  8 | く        | int64  |
|  9 | け        | int64  |
| 10 | こ        | int64  |:
2024-09-11 22:52:18 [INFO] validator_excel_main_class-2 - _log_dataframe_info line 71: DataFrame info:
|    | Columns   | Type   |
|---:|:----------|:-------|
|  0 | NO        | int64  |
|  1 | あ        | object |
|  2 | い        | object |
|  3 | う        | int64  |
|  4 | え        | object |
|  5 | お        | object |
|  6 | か        | int64  |
|  7 | き        | object |
|  8 | く        | int64  |
|  9 | け        | int64  |
| 10 | こ        | int64  |:
2024-09-11 22:52:18 [WARNING] validator_utils - log_errors line 31: Validation error at row 0: {'type': 'int_type', 'loc': ('お',), 'msg': 'Input should be a valid integer', 'input': 'あ', 'url': 'https://errors.pydantic.dev/2.5/v/int_type'}:
2024-09-11 22:52:18 [WARNING] validator_utils - log_errors line 31: Validation error at row 0: {'type': 'string_type', 'loc': ('き',), 'msg': 'Input should be a valid string', 'input': 1, 'url': 'https://errors.pydantic.dev/2.5/v/string_type'}:
2024-09-11 22:52:18 [WARNING] validator_utils - log_errors line 31: Validation error at row 1: {'type': 'int_type', 'loc': ('え',), 'msg': 'Input should be a valid integer', 'input': 's', 'url': 'https://errors.pydantic.dev/2.5/v/int_type'}:
2024-09-11 22:52:18 [WARNING] validator_excel_main_class-2 - start line 160: Process completed with 2 validation errors:
2024-09-11 22:52:18 [INFO] validator_excel_main_class-2 - start line 170: IBRDEV-I-0000002:正常終了しました
2024-09-11 22:52:47 [INFO] validator_excel_main_class-2 - start line 153: IBRDEV-I-0000001:起動しました
2024-09-11 22:52:47 [DEBUG] common_utils - tabulate_dataframe line 67: 
|    |   NO | あ   | い   |   う | え   | お   |   か | き   |   く |   け |   こ |
|---:|-----:|:-----|:-----|-----:|:-----|:-----|-----:|:-----|-----:|-----:|-----:|
|  0 |    1 | a    | d    |    1 | 4    | あ   |   10 | 1    |   13 |   16 |   19 |
|  1 |    2 | b    | e    |    2 | s    | 8    |   11 | h    |   14 |   17 |   20 |
|  2 |    3 | c    | f    |    3 | 6    | 9    |   12 | I    |   15 |   18 |   21 |:
2024-09-11 22:52:47 [DEBUG] common_utils - read_excel_one_sheet line 99: 
Sheet_name: Sheet1
|    |   NO | あ   | い   |   う | え   | お   |   か | き   |   く |   け |   こ |
|---:|-----:|:-----|:-----|-----:|:-----|:-----|-----:|:-----|-----:|-----:|-----:|
|  0 |    1 | a    | d    |    1 | 4    | あ   |   10 | 1    |   13 |   16 |   19 |
|  1 |    2 | b    | e    |    2 | s    | 8    |   11 | h    |   14 |   17 |   20 |
|  2 |    3 | c    | f    |    3 | 6    | 9    |   12 | I    |   15 |   18 |   21 |:
2024-09-11 22:52:47 [DEBUG] common_utils - tabulate_dataframe line 67: 
|    | Columns   | Type   |
|---:|:----------|:-------|
|  0 | NO        | int64  |
|  1 | あ        | object |
|  2 | い        | object |
|  3 | う        | int64  |
|  4 | え        | object |
|  5 | お        | object |
|  6 | か        | int64  |
|  7 | き        | object |
|  8 | く        | int64  |
|  9 | け        | int64  |
| 10 | こ        | int64  |:
2024-09-11 22:52:47 [INFO] validator_excel_main_class-2 - _log_dataframe_info line 71: DataFrame info:
|    | Columns   | Type   |
|---:|:----------|:-------|
|  0 | NO        | int64  |
|  1 | あ        | object |
|  2 | い        | object |
|  3 | う        | int64  |
|  4 | え        | object |
|  5 | お        | object |
|  6 | か        | int64  |
|  7 | き        | object |
|  8 | く        | int64  |
|  9 | け        | int64  |
| 10 | こ        | int64  |:
2024-09-11 22:52:47 [WARNING] validator_utils - log_errors line 31: Validation error at row 0: {'type': 'int_type', 'loc': ('お',), 'msg': 'Input should be a valid integer', 'input': 'あ', 'url': 'https://errors.pydantic.dev/2.5/v/int_type'}:
2024-09-11 22:52:47 [WARNING] validator_utils - log_errors line 31: Validation error at row 0: {'type': 'string_type', 'loc': ('き',), 'msg': 'Input should be a valid string', 'input': 1, 'url': 'https://errors.pydantic.dev/2.5/v/string_type'}:
2024-09-11 22:52:47 [WARNING] validator_utils - log_errors line 31: Validation error at row 1: {'type': 'int_type', 'loc': ('え',), 'msg': 'Input should be a valid integer', 'input': 's', 'url': 'https://errors.pydantic.dev/2.5/v/int_type'}:
2024-09-11 22:52:47 [WARNING] validator_excel_main_class-2 - start line 159: Process completed with 2 validation errors:
2024-09-11 22:52:47 [INFO] validator_excel_main_class-2 - start line 169: IBRDEV-I-0000002:正常終了しました
2024-09-11 23:21:16 [INFO] validator_excel_main_class-2 - start line 153: IBRDEV-I-0000001:起動しました
2024-09-11 23:21:16 [DEBUG] common_utils - tabulate_dataframe line 67: 
|    |   NO | あ   | い   |   う | え   | お   |   か | き   |   く |   け |   こ |
|---:|-----:|:-----|:-----|-----:|:-----|:-----|-----:|:-----|-----:|-----:|-----:|
|  0 |    1 | a    | d    |    1 | 4    | あ   |   10 | 1    |   13 |   16 |   19 |
|  1 |    2 | b    | e    |    2 | s    | 8    |   11 | h    |   14 |   17 |   20 |
|  2 |    3 | c    | f    |    3 | 6    | 9    |   12 | I    |   15 |   18 |   21 |:
2024-09-11 23:21:16 [DEBUG] common_utils - read_excel_one_sheet line 99: 
Sheet_name: Sheet1
|    |   NO | あ   | い   |   う | え   | お   |   か | き   |   く |   け |   こ |
|---:|-----:|:-----|:-----|-----:|:-----|:-----|-----:|:-----|-----:|-----:|-----:|
|  0 |    1 | a    | d    |    1 | 4    | あ   |   10 | 1    |   13 |   16 |   19 |
|  1 |    2 | b    | e    |    2 | s    | 8    |   11 | h    |   14 |   17 |   20 |
|  2 |    3 | c    | f    |    3 | 6    | 9    |   12 | I    |   15 |   18 |   21 |:
2024-09-11 23:21:16 [DEBUG] common_utils - tabulate_dataframe line 67: 
|    | Columns   | Type   |
|---:|:----------|:-------|
|  0 | NO        | int64  |
|  1 | あ        | object |
|  2 | い        | object |
|  3 | う        | int64  |
|  4 | え        | object |
|  5 | お        | object |
|  6 | か        | int64  |
|  7 | き        | object |
|  8 | く        | int64  |
|  9 | け        | int64  |
| 10 | こ        | int64  |:
2024-09-11 23:21:16 [INFO] validator_excel_main_class-2 - _log_dataframe_info line 71: DataFrame info:
|    | Columns   | Type   |
|---:|:----------|:-------|
|  0 | NO        | int64  |
|  1 | あ        | object |
|  2 | い        | object |
|  3 | う        | int64  |
|  4 | え        | object |
|  5 | お        | object |
|  6 | か        | int64  |
|  7 | き        | object |
|  8 | く        | int64  |
|  9 | け        | int64  |
| 10 | こ        | int64  |:
2024-09-11 23:21:16 [WARNING] validator_utils - log_errors line 31: Validation error at row 0: {'type': 'int_type', 'loc': ('お',), 'msg': 'Input should be a valid integer', 'input': 'あ', 'url': 'https://errors.pydantic.dev/2.5/v/int_type'}:
2024-09-11 23:21:16 [WARNING] validator_utils - log_errors line 31: Validation error at row 0: {'type': 'string_type', 'loc': ('き',), 'msg': 'Input should be a valid string', 'input': 1, 'url': 'https://errors.pydantic.dev/2.5/v/string_type'}:
2024-09-11 23:21:16 [WARNING] validator_utils - log_errors line 31: Validation error at row 1: {'type': 'int_type', 'loc': ('え',), 'msg': 'Input should be a valid integer', 'input': 's', 'url': 'https://errors.pydantic.dev/2.5/v/int_type'}:
2024-09-11 23:21:16 [WARNING] validator_excel_main_class-2 - start line 159: Process completed with 2 validation errors:
2024-09-11 23:21:16 [INFO] validator_excel_main_class-2 - start line 169: IBRDEV-I-0000002:正常終了しました
